Workbook
Name \0: #N/A
Name \1: #REF!
Name \2: #REF!
Name \3: #REF!
Name \4: #REF!
Name \5: #REF!
Name \a: #N/A
Name \b: #N/A
Name \c: #N/A
Name \d: #N/A
Name \DSUM: #REF!
Name \e: #N/A
Name \EXP: #REF!
Name \f: #N/A
Name \g: #N/A
Name \GL: #REF!
Name \h: #REF!
Name \I: #REF!
Name \k: #REF!
Name \l: #REF!
Name \m: #N/A
Name \MPR2: #REF!
Name \n: #REF!
Name \o: #REF!
Name \p: #N/A
Name \q: #REF!
Name \R: #REF!
Name \s: #N/A
Name \t: #REF!
Name \u: #N/A
Name \w: #REF!
Name \x: #REF!
Name \y: #REF!
Name \z: #REF!
Name _: #REF!
Name __?Business___Market_Spr: #REF!
Name __?End_Use_Analysis___Sectoral_Gro: #REF!
Name __?INDUSTRY_MATERIAL_BALA: #REF!
Name __?INDUSTRY_MATERIAL_BALANCE___PROJECTI: #REF!
Name __?PE___Q1_REV: #REF!
Name __?PE_1996: #REF!
Name __?PE_BUSINESS___PAST___FUT: #REF!
Name __?PE_REV: #REF!
Name __?PRICE_FORECAST___1995: #REF!
Name __?PROFITABILITY__Q3_1996__: #REF!
Name __?Q3___SUMM: #REF!
Name __?Quarterwise_Collection_P: #REF!
Name __?Quarterwise_Export_P: #REF!
Name __?QUARTERWISE_PERFORMA: #REF!
Name __?RE: #REF!
Name _______________________________DAT5: #REF!
Name _______________________________DAT7: #REF!
Name ______________________________DAT1: #REF!
Name ______________________________DAT10: #REF!
Name _____________________________DAT5: #REF!
Name _____________________________DAT7: #REF!
Name ____________________________DAT1: #REF!
Name ____________________________DAT10: #REF!
Name ____________________________DAT5: #REF!
Name ____________________________DAT7: #REF!

Sheet AR - slide BoD
B1: Amounts in 000
B2: Total receivables | I2: =I22/1000 -> 61380.633 | J2: =J22/1000 -> 99724.765
B4: Receivables as on 28th Feb 25 | D4: BU | E4: Overdue | F4: Not Due | G4: Not Due | I4: Provision | J4: Provision | L4: Provision risks - overdue receivables | P4: Remark
L5: Probable | M5: Possible | N5: Rare
B6: Central do Adubo | D6: Fertilizer | E6: =E26/1000 -> 7560.7278 | F6: =F26/1000 -> 0 | G6: =G26/1000 -> 7560.7278 | I6: =I26/1000 -> 0 | J6: =J26/1000 -> 0 | L6: =L26/1000 -> 0 | M6: =M26/1000 -> 7560.7278 | N6: =N26/1000 -> 0 | P6: Creditor´s assembly Judicial recovery plan has not yet been approved by Creditors. Adfert advisors believe that the AS-IS plan will not be approved and new financial conditions will need to be presented.
B7: SM Agro / Fazenda Baturi | D7: Fertilizer | E7: =E27/1000 -> 3088.5311 | F7: =F27/1000 -> 0 | G7: =G27/1000 -> 3088.5311 | I7: =I27/1000 -> 3088.5311 | J7: =J27/1000 -> 0 | L7: =L27/1000 -> 3088.5311 | M7: =M27/1000 -> 0 | N7: =N27/1000 -> 0 | P7: Judicial collection lawsuit is ongoing.
B8: CBM Fertilizantes | D8: Fertilizer | E8: =E28/1000 -> 3044.8509 | F8: =F28/1000 -> 0 | G8: =G28/1000 -> 3044.8509 | I8: =I28/1000 -> 3044.8509 | J8: =J28/1000 -> 0 | L8: =L28/1000 -> 3044.8509 | M8: =M28/1000 -> 0 | N8: =N28/1000 -> 0 | P8: Adfert has taken legal action and collection recovery lawsuit has been filed. Payment plan was not succesful.
B9: Mogiana Tecno Agro | D9: Fertilizer | E9: =E29/1000 -> 2492.8421 | F9: =F29/1000 -> 0 | G9: =G29/1000 -> 2492.8421 | I9: =I29/1000 -> 0 | J9: =J29/1000 -> 0 | L9: =L29/1000 -> 0 | M9: =M29/1000 -> 2492.8421 | N9: =N29/1000 -> 0 | P9: AFT received a renewalled payment proposal. Monthly payments along 2 yrs, with Machineary as guarantee and worth 25% of Open Exposure. Formal proposal still pending full disclosre on documents and valuation on Machinery.
B10: Casa das Sementes | D10: Fertilizer | E10: =E30/1000 -> 1863.2009 | F10: =F30/1000 -> 0 | G10: =G30/1000 -> 1863.2009 | I10: =I30/1000 -> 1863.2009 | J10: =J30/1000 -> 0 | L10: =L30/1000 -> 1863.2009 | M10: =M30/1000 -> 0 | N10: =N30/1000 -> 0 | P10: Legal process ongoing and 100% of the invoices we provisioned.
B11: Terra Fértil | D11: Fertilizer | E11: =E31/1000 -> 1702.8487 | F11: =F31/1000 -> 0 | G11: =G31/1000 -> 1702.8487 | I11: =I31/1000 -> 1702.8487 | J11: =J31/1000 -> 0 | L11: =L31/1000 -> 1702.8487 | M11: =M31/1000 -> 0 | N11: =N31/1000 -> 0 | P11: AFT has reached a payment agreement: 15% paid by Oct 25 and 3 yearly installments (Oct 26-27-28). No discount on principal and price inflation indexed
B12: Agro Beraldo | D12: Fertilizer | E12: =E32/1000 -> 876.01175 | F12: =F32/1000 -> 0 | G12: =G32/1000 -> 876.01175 | I12: =I32/1000 -> 0 | J12: =J32/1000 -> 0 | L12: =L32/1000 -> 0 | M12: =M32/1000 -> 876.01175 | N12: =N32/1000 -> 0 | P12: Judicial collection lawsuit is ongoing.
B14: Total Over Due in Litigation (TOP 7) | E14: =E39/1000 -> 22315.752 | F14: 0 | G14: 0 | I14: =I39/1000 -> 10427.32 | J14: =J39/1000 -> 0 | L14: =L39/1000 -> 10427.32 | M14: =M39/1000 -> 11888.433 | N14: 0
B15: Total Over Due with Possible Loss | E15: =E45/1000 -> 6.07632 | F15: 0 | G15: 0 | I15: =I45/1000 -> 6.07632 | J15: =J45/1000 -> 0 | L15: =L45/1000 -> 6.07632 | M15: =M45/1000 -> 0 | N15: 0
B16: Low Risk - Expect to Receive soon | E16: =E46/1000 -> 714.67217 | F16: =F46/1000 -> 0 | G16: =G46/1000 -> 714.67217 | I16: =I46/1000 -> 177.26661 | J16: =J46/1000 -> 0 | L16: =L46/1000 -> 0 | M16: =M46/1000 -> 0 | N16: =N46/1000 -> 714.67217 | P16: Provision as per corporate policy
B17: Total | E17: =E16+E15+E14 -> 23036.501 | F17: =F16+F15+F14 -> 0 | G17: =G16+G15+G14 -> 714.67217 | I17: =I16+I15+I14 -> 10610.662 | J17: =J16+J15+J14 -> 0 | L17: =L14+L15 -> 10433.396 | M17: =M16+M14 -> 11888.433 | N17: =N16+N14 -> 714.67217
B19: in BRl
B22: Total receivables | I22: =SUM(E132:F132) -> 61380633 | J22: =SUM(F132:G132) -> 99724765
B24: Receivables as on 31th Mar 26 | D24: BU | E24: Overdue | F24: Not Due | G24: Total | I24: Provision | J24: Write Off | L24: Collection Risk | P24: Remark
L25: Probable | M25: Possible | N25: Rare
B26: CENTRAL DO ADUBO COM E REPRESENTACAO LTD | D26: Fertilizers | E26: 7560727.8 | F26: 0 | G26: =SUM(E26:F26) -> 7560727.8 | I26: 0 | L26: =I26 -> 0 | M26: =E26-I26 -> 7560727.8 | P26: Current Status: Creditor´s Assembly has been approved. All suppliers to receive 35% (65% haircut) of total Outstanding in 10 years (2x per year installments) after a 18-months grace period, corrected by TR inflation index. Prefered suppliers, such as AFT, are eligible to full Overdue recovery based on future sales. 3% of all new CAD Sales to offset Old Overdues and 4% for sales with tenor (credit). This condition is non-binding and the client is to grant AFT a real estate guarantee of BRL 1MM. Upcoming Actions: Decision will now need to undergo approval and pass the entire appeal period. This step may still take a couple months to be completed.
B27: GRUPO LEANDRO SARTI | D27: Fertilizers | E27: 3088531.1 | F27: 0 | G27: =SUM(E27:F27) -> 3088531.1 | I27: 3088531.1 | L27: =I27 -> 3088531.1 | M27: =E27-I27 -> 0 | P27: Current Status: In Litigation via Collection enforcement claim. The judicial process is still in the initial phase, and we are in the period of notifying the parties involved. Upcoming Actions: We will await the procedures set forth by the court.
B28: AGRO BERALDO | D28: Fertilizers | E28: 3044850.9 | F28: 0 | G28: =SUM(E28:F28) -> 3044850.9 | I28: 3044850.9 | L28: =I28 -> 3044850.9 | M28: =E28-I28 -> 0 | P28: Current Status: The Litigation Collection enforcement claim process is ongoing. Upcoming Actions: AFT awaiting for further updates by the court.
B29: TERRA FERTIL - MACHADO | D29: Fertilizers | E29: 2492842.1 | F29: 0 | G29: =SUM(E29:F29) -> 2492842.1 | I29: 0 | L29: =I29 -> 0 | M29: =E29-I29 -> 2492842.1 | P29: Current Status: In Litigation via Collection enforcement claim. An agreement has been reached between parties, under the following terms: (i) Total settlement amount: R$ 3,192,985.64; (ii) Down payment: R$ 478,947.84, to be paid by October 30, 2025; (iii) Remaining balance: R$ 2,714,037.80, to be paid in three annual installments of R$ 904,679.26 each (2026 / 2027 / 2028), to be duly adjusted by inflation/court index. Upcoming Actions: AFT awaiting for the downpayment from the debtor to fulfill the agreement (Oct 20th 2025).
B30: MOGIANA TECNO AGRO | D30: Fertilizers | E30: 1863200.9 | F30: 0 | G30: =SUM(E30:F30) -> 1863200.9 | I30: 1863200.9 | L30: =I30 -> 1863200.9 | M30: =E30-I30 -> 0 | P30: Current Status: In Litigation via Collection enforcement claim. AFT received a proposal agreement, consisting of 12 initial installments of R$ 50,000.00, beginning March 28, which we had previously agreed after trying to negotiate a higher amount. From the 13th month, the proposal would be to rise monthly installments to R$ 100,000.00. This payment agreement would include both principal (R$ 2,502,567.34) and Interest (R$ 204,693.57). We have, via the enforcement collection claim received BRL 29k from the clients account via judicial decison. Upcoming Actions: we´ve not received feedback and are still assessing the viability of an agreed payment plan proposal. AFT is continuing to follow up on a payment schedule definition. AFT continues to follow on enforcement of any assets available from the client.
B31: CASA DAS SEMENTES | D31: Fertilizers | E31: 1702848.7 | F31: 0 | G31: =SUM(E31:F31) -> 1702848.7 | I31: 1702848.7 | L31: =I31 -> 1702848.7 | M31: =E31-I31 -> 0 | P31: Current Status: In Litigation via Collection enforcement claim. The process is ongoing, and we have successfully notified the debtor via judicial court. Upcoming Actions: AFT is seeking to seize assets from the debtor via the judicial claim which is ongoing.
B32: CBM FERTILIZANTES | D32: Fertilizers | E32: 876011.75 | F32: 0 | G32: =SUM(E32:F32) -> 876011.75 | I32: 0 | L32: =I32 -> 0 | M32: =E32-I32 -> 876011.75 | P32: Judicial settlement has been signed, under the following terms: (i) Total settlement amount: R$ 1,179,964.76, to be paid under the following conditions; (ii) Agreed payment in Two installments of R$ 100,000.00 each, due on April 24, 2025, and September 30th, 2025; Client has paid BRL 100k of the 1st installment and 2nd to be paid on the 30th of Sept. (iii) Three annual installments of R$ 326,654.92 , due on September 30, 2026, September 30, 2027, and September 30, 2028; Upcoming Actions: AFT awaiting for the payment plan agreed ofr September (another BRL 100k payment).
B33: GRUPO TRIANGULO AGRO | D33: Fertilizers | E33: 237309.12 | F33: 0 | G33: =SUM(E33:F33) -> 237309.12 | I33: 237309.12 | L33: =I33 -> 237309.12 | M33: =E33-I33 -> 0 | P33: Current Status: Client has issue a Judicial Recovery claim. The judicial process is still in the initial phase, and AFT has been notified. Upcoming Actions: AFT awaiting for the next steps to be set by court.
B34: TERRA FERTILIZANTES LTDA - ARAXÁ | D34: Additives | E34: 226233.6 | F34: 0 | G34: =SUM(E34:F34) -> 226233.6 | I34: 226233.6 | L34: =I34 -> 226233.6 | M34: =E34-I34 -> 0 | P34: May - 2024. In Litigation via collection enforcement. We don´t expect to have the collection. Client has been operation with a different Tax Id and we´re investigating how to link both companies to this claim.
B35: FAZENDA ARCOS SÃO JOÃO | D35: Fertilizers | E35: 988506.24 | F35: 0 | G35: =SUM(E35:F35) -> 988506.24 | I35: 29655.187 | L35: =I35 -> 29655.187 | M35: =E35-I35 -> 958851.05 | P35: Aug- 2025 Payment plan negotiation ongoing.
B36: ITERUM - RONDONOPOLIS | D36: Additives | E36: 213750 | F36: 0 | G36: =SUM(E36:F36) -> 213750 | I36: 213750 | L36: =I36 -> 213750 | M36: =E36-I36 -> 0 | P36: Dec- 2024 - Client facing fanancial difficulties and offered to return non-used final products. AFT is validating samples collected for quality assurance.
B37: GLINFERTIL - SAO FRANCISCO DO SUL | D37: Additives | E37: 20940 | F37: 0 | G37: =SUM(E37:F37) -> 20940 | I37: 20940 | L37: =I37 -> 20940 | M37: =E37-I37 -> 0 | P37: Nov 2023 Overdue. We don´t expect to receive collection from this client. The current status is that the client awaits for a court decision to accept the Judicial recovery process.
B39: Total Over Due in Litigation (TOP 12) | E39: =SUM(E26:E37) -> 22315752 | F39: =SUM(F26:F37) -> 0 | G39: =SUM(G26:G37) -> 22315752 | I39: =SUM(I26:I37) -> 10427320 | J39: =SUM(J26:J37) -> 0 | L39: =SUM(L26:L37) -> 10427320 | M39: =SUM(M26:M37) -> 11888433 | N39: =SUM(N26:N37) -> 0
B40: KLEYTON DUARTE SOARES | D40: Additives | E40: 100 | F40: 0 | G40: =SUM(E40:F40) -> 100 | I40: 100 | L40: =I40 -> 100 | M40: =E40-L40 -> 0 | P40: Jul - 2024 - Sale of old fixed assets to employees (chairs, desks etc) and it was not duly debited in employees payroll. Employee has left the company.
B41: MARIA JOSE DA SILVA | D41: Additives | E41: 50 | F41: 0 | G41: =SUM(E41:F41) -> 50 | I41: 50 | L41: =I41 -> 50 | M41: =E41-L41 -> 0 | P41: Aug - 2024 - Sale of old fixed assets to employees (chairs, desks etc) and it was not duly debited in employees payroll. Employee has left the company.
B42: GRUPO YARA | D42: Additives | E42: 5626.32 | F42: 0 | G42: =SUM(E42:F42) -> 5626.32 | I42: 5626.32 | L42: =I42 -> 5626.32 | M42: =E42-L42 -> 0 | P42: June 2024 - invoice underpayment due client claim of weight divergence
B43: SEU LIXO | D43: Additives | E43: 300 | F43: 0 | G43: =SUM(E43:F43) -> 300 | I43: 300 | L43: =I43 -> 300 | M43: =E43-L43 -> 0 | P43: Nov 2024 - sale of scrap materials.
B45: Total Over Due with Probable Loss | E45: =SUM(E40:E44) -> 6076.32 | F45: =SUM(F40:F44) -> 0 | G45: =SUM(G40:G44) -> 6076.32 | I45: =SUM(I40:I44) -> 6076.32 | J45: =SUM(J40:J44) -> 0 | L45: =SUM(L40:L44) -> 6076.32 | M45: =SUM(M40:M44) -> 0 | N45: =SUM(N40:N44) -> 0
B46: Low Risk - Expect to Receive soon | E46: =SUM(E47:E56) -> 714672.17 | F46: =F57+F58+F59 -> 0 | G46: =SUM(G47:G56) -> 714672.17 | I46: =SUM(I47:I56) -> 177266.61 | J46: =SUM(J47:J56) -> 0 | L46: =SUM(L47:L56) -> 0 | M46: =SUM(M47:M56) -> 0 | N46: =SUM(N47:N56) -> 714672.17 | P46: Provision as per corporate policy
B47: AGROBROKERS - COLÔMBIA | D47: Additive Intl. | E47: 449507.69 | F47: 0 | G47: 449507.69 | I47: 13485.231 | N47: =E47 -> 449507.69 | P47: Cargo cleared at Colombia port customs. AFT is in contact with the customer for validation of the payment plan.
B48: FERTIBAL - EQUADOR | D48: Additive Intl. | E48: 14548.35 | G48: =SUM(E48:F48) -> 14548.35 | I48: 0 | N48: =E48 -> 14548.35 | P48: Jan - 2026 The client paid 50% of the amount in January 2026; the remainder will be paid in March.
...

Sheet AR - slide
B1: in BRl
B2: Receivables as on 31st March 25 | D2: BU | E2: Overdue | F2: Not Due | G2: Provision | I2: Risk Provisions | M2: Remark
I3: Probable | J3: Possible | K3: Rare
B4: Central do Adubo | D4: Fertilizer | E4: 7560727.8 | G4: 3780363.9 | I4: 3780363.9 | J4: 3780363.9 | M4: Creditor´s assembly has been schedulled for May 2025. Central has reached out to Adfert for preferred suppliers status and conditions are in negotiation along April early May to be presented in the Assembly.
B5: SM Agro / Fazenda Baturi | D5: Fertilizer | E5: 3088531.1 | F5: 0 | G5: 3088531.1 | I5: 3088531.1 | M5: Judicial collection lawsuit is ongoing.
B6: CBM Fertilizantes | D6: Fertilizer | E6: 1076345 | F6: 0 | G6: 1076345 | I6: 1076345 | M6: Payment plan in negotiation: 10% payment in 2025 + 3 bullet yearly payments for the remaining debt.
B7: Mogiana Tecno Agro | D7: Fertilizer | E7: 1892360 | F7: 0 | G7: 0 | I7: 0 | J7: 1892360 | M7: AFT received a renewalled payment proposal. Monthly payments along 2 yrs, with Machineary as guarantee and worth 25% of Open Exposure. Formal proposal still pending full disclosre on documents and valuation on Machinery.
B8: Casa das Sementes | D8: Fertilizer | E8: 1716645.3 | G8: 1716645.3 | I8: 1716645.3 | M8: Legal process ongoing and 100% of the invoices we provisioned.
B9: Terra Fértil | D9: Fertilizer | E9: 2971789.9 | G9: 89153.697 | J9: 2971789.9 | M9: AFT has reached a payment agreement: 15% paid by Oct 25 and 3 yearly installments (Oct 26-27-28). No discount on principal and price inflation indexed
B10: Agro Beraldo | D10: Fertilizer | E10: 3044850.9 | F10: 0 | G10: 91345.528 | J10: 3044850.9 | M10: Judicial collection lawsuit is ongoing.
B12: Total Over Due in Litigation (TOP 7) | E12: =SUM(E4:E10) -> 21351250 | F12: =SUM(F4:F10) -> 0 | G12: =SUM(G4:G10) -> 9842384.5 | I12: =SUM(I4:I10) -> 9661885.3 | J12: =SUM(J4:J10) -> 11689365 | K12: =SUM(K4:K10) -> 0
B13: Planta Rica Agronegócios Ltda | D13: Fertilizers | E13: 110528 | F13: 0 | G13: 110528 | I13: 110528 | M13: old overdue
B14: Equilíbrio - Mogi Mirim | D14: Fertilizers | E14: 22222.25 | F14: 0 | G14: 22222.25 | I14: 22222.25 | M14: old overdue due to Quality issues
B15: Terra Fertilizantes Ltda | D15: Additives | E15: 226233.6 | F15: 0 | G15: 6787.008 | I15: 226233.6 | M15: Judicial recovery started
B16: Plant Bem - Paranagua | D16: Additives | E16: 140872.6 | F16: 0 | G16: 140872.6 | I16: 140872.6 | M16: old overdue
B17: Fertisanta Fertilizantes | D17: Additives | E17: 41379 | F17: 0 | G17: 41379 | I17: 41379 | M17: old overdue
B18: GLINFERTIL - SAO FRANCISCO DO SUL | D18: Additives | E18: 20940 | G18: 20940 | I18: 20940
B19: Superbac | D19: Additives | E19: 102008.2 | G19: 3060.25 | I19: 102008.2 | M19: No agreenment on payment. Judicial recovery process to begin
B20: Delcorp S.A | D20: Additives | E20: 84291.45 | F20: 0 | G20: 84291.45 | I20: 84291.45 | M20: old overdue
B21: Total Over Due with Possible Loss | E21: =SUM(E13:E20) -> 748475.1 | F21: =SUM(F13:F20) -> 0 | G21: =SUM(G13:G20) -> 430080.56 | I21: =SUM(I13:I20) -> 748475.1 | J21: =SUM(J13:J20) -> 0 | K21: =SUM(K13:K20) -> 0
B22: Low Risk - Expect to Receive soon | E22: =SUM(E23:E43) -> 7425775.8 | F22: =F44+F45+F46 -> 35847180 | G22: =SUM(G23:G43) -> 526944.99 | M22: Provision as per corporate policy
B23: Grupo Fert Tocantins | D23: Additives | E23: =1991399-67239 -> 1924160 | G23: 67314 | K23: =E23 -> 1924160 | M23: Overdue received in the beginning of March
B24: GRUPO MOSAIC FERTILIZANTES DO BRASIL | D24: Additives | E24: =765704.79-80843.12 -> 684861.67 | G24: 66674.04 | K24: =E24 -> 684861.67
B25: ITERUM - RONDONOPOLIS | D25: Additives | E25: 213750 | G25: 1475.1
B26: GRUPO AMAGGI | D26: Additives | E26: 56400
B27: GRUPO HERINGER | D27: Additives | E27: 397800
B28: GRUPO MOSAIC FERTILIZANTES P K LTDA | D28: Additives | E28: =123685.2-16500 -> 107185.2
B29: GRUPO CIBRA | D29: Additives | E29: =414240-1200 -> 413040
B30: GRUPO YARA | D30: Additives | E30: =63226.32-57600 -> 5626.32
B31: LYCSA Argentina | D31: Int'll | E31: 256935.85 | G31: 256935.85 | J31: 256935.85
B32: FERTYMEND - EQUADOR | D32: Int'll | E32: 69886.47
B33: AGRO MIL AGROS SAS - COLOMBIA | D33: Int'll | E33: 136847.67
B34: FERTIBAL - EQUADOR | D34: Int'll | E34: 82123.57
B35: ASOCIACION DE COOPERATIVAS ARGENTINAS CL | D35: Int'll | E35: 703377.76
B36: TECNOMYL S.A. - PARAGUAY | D36: Int'll | E36: 201503.56
B37: ABOPAR - PARAGUAY | D37: Int'll | E37: 150938.02
B38: C I ACEPALMA SA - COLOMBIA | D38: Int'll | E38: 317041.26 | K38: =E38 -> 317041.26
B39: Indorama Senegal | D39: Int'll | E39: 381748.49 | G39: 0 | K39: =E39 -> 381748.49
B40: GRUPO TRIANGULO AGRO | D40: Fertilizers | E40: 237309.12 | G40: 0 | K40: 117330.4
B41: GRUPO R3 | D41: Fertilizers | E41: 659074 | G41: 0 | J41: 659074
...

Sheet AR
J3: Credit Analysis | N3: Guarantee | S3: Remark
C4: CUSTOMER | D4: BU | E4: Total AR | F4: Overdue | G4: Not Due | H4: Provision | J4: Value | K4: Type | L4: Period days | N4: Value | O4: Type | P4: Due date | Q4: Tenor
C5: CENTRAL DO ADUBO | D5: Fertilizer | E5: =F5+G5 -> 7560727.8 | F5: ='Painel Fertilizers'!O4 -> 7560727.8 | G5: ='Painel Fertilizers'!P4 -> 0 | H5: ='Painel Fertilizers'!X4 -> 0 | J5: 0 | K5: 0 | L5: 0 | N5: 0 | O5: 0 | P5: 0 | Q5: 0 | S5: Judicial recovery plan presented but yet to be approved by Creditors Asembly: a meeting was held with AFT and a proposal of 65% discount on face value presented with a 18-month grace period and repayment over 10 years (in 20 installments). Adfert has not received further details on the restructuring plan as previously agreed in the end of Oct. Creditors assembly yet to be marked and a vote will occur for the Debtors recovery plan approval. Adfert advisors have a strong believe that the plan as AS-IS will not be approved and new financial conditions will be needed by the debtors
C6: SM AGRO / FAZ. BATURI | D6: Fertilizer | E6: =F6+G6 -> #REF! | F6: ='Painel Fertilizers'!#REF! -> #REF! | G6: ='Painel Fertilizers'!#REF! -> #REF! | H6: ='Painel Fertilizers'!#REF! -> #REF! | J6: 300000 | K6: Clean | L6: 0 | N6: 740000 | O6: CPR | P6: 45566 | Q6: 10 months | S6: Client has phisycally closed its reseller shop. Current overdue invoices were dully protested at the registry office and legal action has been filed. Awaiting court´s decision ordering the defendants to be served for payment
C7: CBM FERTILIZANTES | D7: Fertilizer | E7: =F7+G7 -> 0 | F7: ='Painel Fertilizers'!O20 -> 0 | G7: 0 | H7: 0 | N7: 4000000 | O7: CPR-G | P7: 45505 | Q7: 1 year | S7: Adfert has taken legal action and collection recovery lawsuit to be filed within November. An agreement for a payment plan was not successfull
C8: MOGIANA TECNO AGRO | D8: Fertilizer | E8: =F8+G8 -> 2026078 | F8: 1892360 | G8: ='Painel Fertilizers'!P20 -> 133718 | H8: ='Painel Fertilizers'!X5 -> 3088531.1 | J8: 1000000 | K8: Surety Bond | L8: 360 | N8: 1892360 | O8: Surety Bond | P8: 45597 | Q8: 1 year | S8: The judicial collection lawsuit plan was signed and filed. Court decision has approved the settement agreement establishing a 24 months payment plan (montlhy payment). 1st installment not paid and the judicial collection is ongoing
C9: CASA DAS SEMENTES | D9: Fertilizer | E9: =F9+G9 -> 3044850.9 | F9: ='Painel Fertilizers'!O6 -> 3044850.9 | G9: ='Painel Fertilizers'!P6 -> 0 | H9: ='Painel Fertilizers'!X6 -> 3044850.9 | J9: 2000000 | K9: Surety Bond | L9: 120 | S9: Provision 100%. Client’s overdues were protested at the registry office. Legal process ongoing
C10: TERRA FERTIL - MACHADO | D10: Fertilizer | E10: =F10+G10 -> 876011.75 | F10: ='Painel Fertilizers'!O10 -> 876011.75 | G10: ='Painel Fertilizers'!P10 -> 0 | H10: ='Painel Fertilizers'!X10 -> 0 | N10: 5517407.7 | O10: Surety Bond | P10: 45606 | Q10: 1 year | S10: Guarantee sent to the legal department so that they begin legal proceedings to collect the amount due
C11: AGROBERALDO | D11: Fertilizer | E11: =F11+G11 -> 0 | F11: ='Painel Fertilizers'!O22 -> 0 | G11: ='Painel Fertilizers'!P22 -> 0 | H11: ='Painel Fertilizers'!X22 -> 0 | N11: 3000000 | O11: Surety Bond | P11: 45627 | Q11: 1 year | S11: Guarantee sent to the legal department so that they begin legal proceedings to collect the amount due
C12: Total Over Due in Litigation | E12: =SUM(E5:E11) -> #REF! | F12: =SUM(F5:F11) -> #REF! | G12: =SUM(G5:G11) -> #REF! | H12: =SUM(H5:H11) -> #REF!
C13: PLANTA RICA AGRONEGÓCIOS LTDA | D13: Fertilizers | E13: =F13+G13 -> 110528 | F13: 110528 | G13: 0 | H13: 110528 | S13: old overdue
C14: FAZENDA BRAVINHOS | D14: Fertilizers | E14: =F14+G14 -> 34132.18 | F14: 34132.18 | G14: 0 | H14: 1023.9654 | S14: Judicial recovery started
C15: EQUILIBRIO - MOGI MIRIM | D15: Fertilizers | E15: =F15+G15 -> 22222.25 | F15: 22222.25 | G15: 0 | H15: 22222.25 | S15: old overdue
C16: TERRA FERTILIZANTES LTDA | D16: Aditives | E16: =F16+G16 -> 226233.6 | F16: 226233.6 | G16: 0 | H16: ='Painel Additive'!X6 -> 63226.32 | S16: Judicial recovery started
C17: PLANT BEM - PARANAGUÁ | D17: Aditives | E17: =F17+G17 -> 140872.6 | F17: 140872.6 | G17: 0 | H17: 140872.6 | S17: old overdue
C18: FERTISANTA FERTILIZANTES | D18: Aditives | E18: =F18+G18 -> 41379 | F18: 41379 | G18: 0 | H18: 41379 | S18: old overdue
C19: DELCORP S.A | D19: Aditives | E19: =F19+G19 -> 84291.45 | F19: 84291.45 | G19: 0 | H19: 84291.45 | S19: old overdue
C20: Total Over Due with Possible Loss | E20: =SUM(E13:E19) -> 659659.08 | F20: =SUM(F13:F19) -> 659659.08 | G20: =SUM(G13:G19) -> 0 | H20: =SUM(H13:H19) -> 463543.59
C21: Low Risk - Expect to Receive soon | E21: =F21+G21 -> #REF! | F21: =-(F20+F12)+'Painel Additive'!O1+'Painel Fertilizers'!O1+'Painel International'!O1 -> #REF! | G21: 0 | H21: ='Bad Debt Provision'!#REF! - (H12+H20) -> #REF! | S21: Provision as per corporate policy
C22: Not Due | E22: =F22+G22 -> 37270137 | F22: 0 | G22: ='Painel Additive'!P1+'Painel Fertilizers'!P1+'Painel International'!P1 -> 37270137 | H22: 0
C23: Total | E23: =SUM(E20:E22)+E12 -> #REF! | F23: =SUM(F20:F22)+F12 -> #REF! | G23: =SUM(G20:G22)+G12 -> #REF! | H23: =SUM(H20:H22)+H12 -> #REF!

Sheet freight debit notes
D1: =SUBTOTAL(9,D3:D999) -> 176583.12 | Q1: 46136
A2: CODPARC | B2: NOMEPARC | C2: CNPJ | D2: Valor | E2: NUFIN | F2: DTVENC | G2: DHBAIXA | H2: AD_BU | I2: NOME_BU | J2: NUMNOTA | K2: DTENTSAI | L2: CODNAT | M2: DESCRNAT | N2: CODTIPOPER | O2: OPERACAO | P2: Grupo | Q2: Dias vencidos
A3: 1787 | B3: MOSAIC - UBERABA (CIU1) | C3: 33.931.486/0014-55 | D3: 3600 | E3: 1246031589 | F3: 44784 | H3: 1 | I3: Adtives | J3: 1246031589 | K3: 44769 | L3: 3041000 | M3: FRETES DIVERSOS | N3: 46 | O3: FINANCEIRO GERAL | P3: GRUPO MOSAIC FERTILIZANTES P K LTDA | Q3: =$Q$1-F3 -> 1352
A4: 1787 | B4: MOSAIC - UBERABA (CIU1) | C4: 33.931.486/0014-55 | D4: 2700 | E4: 1246055596 | F4: 44889 | H4: 1 | I4: Adtives | J4: 1246055596 | K4: 44889 | L4: 3041000 | M4: FRETES DIVERSOS | N4: 46 | O4: FINANCEIRO GERAL | P4: GRUPO MOSAIC FERTILIZANTES P K LTDA | Q4: =$Q$1-F4 -> 1247
A5: 1788 | B5: MOSAIC - UBERABA (CIU2) | C5: 33.931.486/0021-84 | D5: 5400 | E5: 1246055599 | F5: 44889 | H5: 1 | I5: Adtives | J5: 1246055599 | K5: 44889 | L5: 3041000 | M5: FRETES DIVERSOS | N5: 46 | O5: FINANCEIRO GERAL | P5: GRUPO MOSAIC FERTILIZANTES P K LTDA | Q5: =$Q$1-F5 -> 1247
A6: 1788 | B6: MOSAIC - UBERABA (CIU2) | C6: 33.931.486/0021-84 | D6: 1200 | E6: 1246190701 | F6: 45674 | H6: 1 | I6: Adtives | J6: 1246190701 | K6: 45659 | L6: 3041000 | M6: FRETES DIVERSOS | N6: 46 | O6: FINANCEIRO GERAL | P6: GRUPO MOSAIC FERTILIZANTES P K LTDA | Q6: =$Q$1-F6 -> 462
A7: 1789 | B7: MOSAIC - ARAXA (CMA) | C7: 33.931.486/0019-60 | D7: 2700 | E7: 1246120461 | F7: 45294 | H7: 1 | I7: Adtives | J7: 191223 | K7: 45279 | L7: 3041000 | M7: FRETES DIVERSOS | N7: 46 | O7: FINANCEIRO GERAL | P7: GRUPO MOSAIC FERTILIZANTES P K LTDA | Q7: =$Q$1-F7 -> 842
A8: 1789 | B8: MOSAIC - ARAXA (CMA) | C8: 33.931.486/0019-60 | D8: 900 | E8: 1246146095 | F8: 45428 | H8: 1 | I8: Adtives | J8: 1246120461 | K8: 45428 | L8: 3041000 | M8: FRETES DIVERSOS | N8: 46 | O8: FINANCEIRO GERAL | P8: GRUPO MOSAIC FERTILIZANTES P K LTDA | Q8: =$Q$1-F8 -> 708
A9: 43 | B9: CIBRA - CAMACARI | C9: 00.117.842/0001-28 | D9: 3600 | E9: 1246271938 | F9: 46147 | H9: 1 | I9: Adtives | J9: 1246271938 | K9: 46132 | L9: 3042200 | M9: DIÁRIAS E ESTADIA DE MOTORISTAS | N9: 46 | O9: FINANCEIRO GERAL | P9: GRUPO CIBRA | Q9: =$Q$1-F9 -> -11
A10: 43 | B10: CIBRA - CAMACARI | C10: 00.117.842/0001-28 | D10: 3600 | E10: 1246271937 | F10: 46147 | H10: 1 | I10: Adtives | J10: 1246271937 | K10: 46132 | L10: 3042200 | M10: DIÁRIAS E ESTADIA DE MOTORISTAS | N10: 46 | O10: FINANCEIRO GERAL | P10: GRUPO CIBRA | Q10: =$Q$1-F10 -> -11
A11: 43 | B11: CIBRA - CAMACARI | C11: 00.117.842/0001-28 | D11: 3600 | E11: 1246271931 | F11: 46147 | H11: 1 | I11: Adtives | J11: 1246271931 | K11: 46132 | L11: 3042200 | M11: DIÁRIAS E ESTADIA DE MOTORISTAS | N11: 46 | O11: FINANCEIRO GERAL | P11: GRUPO CIBRA | Q11: =$Q$1-F11 -> -11
A12: 43 | B12: CIBRA - CAMACARI | C12: 00.117.842/0001-28 | D12: 6000 | E12: 1246271936 | F12: 46147 | H12: 1 | I12: Adtives | J12: 1246271936 | K12: 46132 | L12: 3042200 | M12: DIÁRIAS E ESTADIA DE MOTORISTAS | N12: 46 | O12: FINANCEIRO GERAL | P12: GRUPO CIBRA | Q12: =$Q$1-F12 -> -11
A13: 43 | B13: CIBRA - CAMACARI | C13: 00.117.842/0001-28 | D13: 2400 | E13: 1246271921 | F13: 46147 | H13: 1 | I13: Adtives | J13: 1246271921 | K13: 46132 | L13: 3042200 | M13: DIÁRIAS E ESTADIA DE MOTORISTAS | N13: 46 | O13: FINANCEIRO GERAL | P13: GRUPO CIBRA | Q13: =$Q$1-F13 -> -11
A14: 1159 | B14: YARA - RIO GRANDE | C14: 92.660.604/0013-16 | D14: 1800 | E14: 1246087936 | F14: 45112 | H14: 1 | I14: Adtives | J14: 1246087936 | K14: 45097 | L14: 3041000 | M14: FRETES DIVERSOS | N14: 46 | O14: FINANCEIRO GERAL | P14: GRUPO YARA | Q14: =$Q$1-F14 -> 1024
... A54: 7022 | B54: STRATOS/MOSAIC - ROSARIO DO CATETE | C54: 31.009.644/0001-74 | D54: 1800 | E54: 1246054442 | F54: 44897 | H54: 1 | I54: Adtives | J54: 1246054442 | K54: 44882 | L54: 3041000 | M54: FRETES DIVERSOS | N54: 46 | O54: FINANCEIRO GERAL | P54: STRATOS/MOSAIC - ROSARIO DO CATETE | Q54: =$Q$1-F54 -> 1239

Sheet Data total
D1: =SUBTOTAL(9,D3:D1088) -> 62360285 | E1: ='Data Additive'!D1+'Data Fertilizers'!D1+'Data International'!D1 -> 62183701 | F1: ='Data Additive'!D1+'Data Fertilizers'!D1+'Data International'!D1+'freight debit notes'!D1 -> 62360285 | G1: =D1-F1 -> 0 | R1: 46136
A2: CODPARC | B2: NOMEPARC | C2: CNPJ | D2: Valor | E2: NUFIN | F2: DTVENC | G2: DHBAIXA | H2: AD_BU | I2: NOME_BU | J2: NUMNOTA | K2: DTENTSAI | L2: CODNAT | M2: DESCRNAT | N2: CODTIPOPER | O2: OPERACAO | P2: Grupo | Q2: Dias vencidos
A3: 205 | B3: FERTIPAR - RONDONÓPOLIS | C3: 09.384.948/0002-43 | D3: 80589.6 | E3: 1246271690 | F3: 46157 | H3: 1 | I3: Adtives | J3: 11158 | K3: 46129 | L3: 1010100 | M3: VENDAS MERCADO INTERNO | N3: 161 | O3: VENDA PROD. INDUSTRIALIZADO - NFE | P3: GRUPO FERTIPAR FERTILIZANTES MATO GROSSO | Q3: =$R$1-F3 -> -21 | R3: =_xlfn.XLOOKUP(E3,'Data Additive'!E:E,'Data Additive'!E:E,0) -> 1246271690
A4: 205 | B4: FERTIPAR - RONDONÓPOLIS | C4: 09.384.948/0002-43 | D4: 75474 | E4: 1246269597 | F4: 46139 | H4: 1 | I4: Adtives | J4: 11003 | K4: 46111 | L4: 1010100 | M4: VENDAS MERCADO INTERNO | N4: 161 | O4: VENDA PROD. INDUSTRIALIZADO - NFE | P4: GRUPO FERTIPAR FERTILIZANTES MATO GROSSO | Q4: =$R$1-F4 -> -3 | R4: =_xlfn.XLOOKUP(E4,'Data Additive'!E:E,'Data Additive'!E:E,0) -> 1246269597
A5: 1257 | B5: MOSAIC - CAMPO GRANDE | C5: 61.156.501/0081-30 | D5: 1980.8 | E5: 1246032946 | F5: 44774 | H5: 1 | I5: Adtives | J5: 17935 | K5: 44714 | L5: 1010100 | M5: VENDAS MERCADO INTERNO | N5: 56 | O5: VENDA A ORDEM | P5: GRUPO MOSAIC FERTILIZANTES DO BRASIL | Q5: =$R$1-F5 -> 1362 | R5: =_xlfn.XLOOKUP(E5,'Data Additive'!E:E,'Data Additive'!E:E,0) -> 1246032946
A6: 1953 | B6: AMAGGI - COMODORO | C6: 77.294.254/0075-20 | D6: 58917.8 | E6: 1246267986 | F6: 46158 | H6: 1 | I6: Adtives | J6: 10907 | K6: 46098 | L6: 1010100 | M6: VENDAS MERCADO INTERNO | N6: 161 | O6: VENDA PROD. INDUSTRIALIZADO - NFE | P6: GRUPO AMAGGI | Q6: =$R$1-F6 -> -22 | R6: =_xlfn.XLOOKUP(E6,'Data Additive'!E:E,'Data Additive'!E:E,0) -> 1246267986
A7: 1787 | B7: MOSAIC - UBERABA (CIU1) | C7: 33.931.486/0014-55 | D7: 3600 | E7: 1246031589 | F7: 44784 | H7: 1 | I7: Adtives | J7: 1246031589 | K7: 44769 | L7: 3041000 | M7: FRETES DIVERSOS | N7: 46 | O7: FINANCEIRO GERAL | P7: GRUPO MOSAIC FERTILIZANTES P K LTDA | Q7: =$R$1-F7 -> 1352 | R7: =_xlfn.XLOOKUP(E7,'Data Additive'!E:E,'Data Additive'!E:E,0) -> 0
A8: 1787 | B8: MOSAIC - UBERABA (CIU1) | C8: 33.931.486/0014-55 | D8: 2700 | E8: 1246055596 | F8: 44889 | H8: 1 | I8: Adtives | J8: 1246055596 | K8: 44889 | L8: 3041000 | M8: FRETES DIVERSOS | N8: 46 | O8: FINANCEIRO GERAL | P8: GRUPO MOSAIC FERTILIZANTES P K LTDA | Q8: =$R$1-F8 -> 1247 | R8: =_xlfn.XLOOKUP(E8,'Data Additive'!E:E,'Data Additive'!E:E,0) -> 0
A9: 1787 | B9: MOSAIC - UBERABA (CIU1) | C9: 33.931.486/0014-55 | D9: 109862.4 | E9: 1246271310 | F9: 46216 | H9: 1 | I9: Adtives | J9: 11116 | K9: 46126 | L9: 1010100 | M9: VENDAS MERCADO INTERNO | N9: 161 | O9: VENDA PROD. INDUSTRIALIZADO - NFE | P9: GRUPO MOSAIC FERTILIZANTES P K LTDA | Q9: =$R$1-F9 -> -80 | R9: =_xlfn.XLOOKUP(E9,'Data Additive'!E:E,'Data Additive'!E:E,0) -> 1246271310
A10: 1787 | B10: MOSAIC - UBERABA (CIU1) | C10: 33.931.486/0014-55 | D10: 116928 | E10: 1246267948 | F10: 46187 | H10: 1 | I10: Adtives | J10: 10899 | K10: 46097 | L10: 1010100 | M10: VENDAS MERCADO INTERNO | N10: 161 | O10: VENDA PROD. INDUSTRIALIZADO - NFE | P10: GRUPO MOSAIC FERTILIZANTES P K LTDA | Q10: =$R$1-F10 -> -51 | R10: =_xlfn.XLOOKUP(E10,'Data Additive'!E:E,'Data Additive'!E:E,0) -> 1246267948
A11: 1787 | B11: MOSAIC - UBERABA (CIU1) | C11: 33.931.486/0014-55 | D11: 115891.2 | E11: 1246262540 | F11: 46149 | H11: 1 | I11: Adtives | J11: 10652 | K11: 46059 | L11: 1010100 | M11: VENDAS MERCADO INTERNO | N11: 161 | O11: VENDA PROD. INDUSTRIALIZADO - NFE | P11: GRUPO MOSAIC FERTILIZANTES P K LTDA | Q11: =$R$1-F11 -> -13 | R11: =_xlfn.XLOOKUP(E11,'Data Additive'!E:E,'Data Additive'!E:E,0) -> 1246262540
A12: 1787 | B12: MOSAIC - UBERABA (CIU1) | C12: 33.931.486/0014-55 | D12: 103795.2 | E12: 1246268633 | F12: 46194 | H12: 1 | I12: Adtives | J12: 10957 | K12: 46104 | L12: 1010100 | M12: VENDAS MERCADO INTERNO | N12: 161 | O12: VENDA PROD. INDUSTRIALIZADO - NFE | P12: GRUPO MOSAIC FERTILIZANTES P K LTDA | Q12: =$R$1-F12 -> -58 | R12: =_xlfn.XLOOKUP(E12,'Data Additive'!E:E,'Data Additive'!E:E,0) -> 1246268633
A13: 1787 | B13: MOSAIC - UBERABA (CIU1) | C13: 33.931.486/0014-55 | D13: 111360 | E13: 1246268748 | F13: 46195 | H13: 1 | I13: Adtives | J13: 10965 | K13: 46105 | L13: 1010100 | M13: VENDAS MERCADO INTERNO | N13: 161 | O13: VENDA PROD. INDUSTRIALIZADO - NFE | P13: GRUPO MOSAIC FERTILIZANTES P K LTDA | Q13: =$R$1-F13 -> -59 | R13: =_xlfn.XLOOKUP(E13,'Data Additive'!E:E,'Data Additive'!E:E,0) -> 1246268748
A14: 1787 | B14: MOSAIC - UBERABA (CIU1) | C14: 33.931.486/0014-55 | D14: 114662.4 | E14: 1246268585 | F14: 46161 | H14: 1 | I14: Adtives | J14: 10953 | K14: 46101 | L14: 1010100 | M14: VENDAS MERCADO INTERNO | N14: 161 | O14: VENDA PROD. INDUSTRIALIZADO - NFE | P14: GRUPO MOSAIC FERTILIZANTES P K LTDA | Q14: =$R$1-F14 -> -25 | R14: =_xlfn.XLOOKUP(E14,'Data Additive'!E:E,'Data Additive'!E:E,0) -> 1246268585
... A444: 6370 | B444: YTL S.A. - PARAGUAI | C444: 00.000.000/0000-00 | D444: 172806.77 | E444: 1246272162 | F444: 46164 | H444: 1 | I444: Adtives | J444: 11193 | K444: 46134 | L444: 1010200 | M444: VENDAS MERCADO EXTERNO | N444: 40 | O444: VENDA - NFE (EXPORTAÇÃO) | P444: YTL S.A. - PARAGUAI | Q444: =$R$1-F444 -> -28 | R444: =_xlfn.XLOOKUP(E444,'Data Additive'!E:E,'Data Additive'!E:E,0) -> 0
A445: 9708 | B445: CARGILL ARGENTINA | C445: ..- | D445: 687688.91 | E445: 1246271322 | F445: 46186 | I445: Não encontrado | J445: 11122 | K445: 46126 | L445: 1010200 | M445: VENDAS MERCADO EXTERNO | N445: 40 | O445: VENDA - NFE (EXPORTAÇÃO) | P445: CARGILL ARGENTINA | Q445: =$R$1-F445 -> -50 | R445: =_xlfn.XLOOKUP(E445,'Data Additive'!E:E,'Data Additive'!E:E,0) -> 0
A446: 8187 | B446: AGROREP. REPRESENTACOES AGRICOLAS | C446: 29.668.745/0001-05 | D446: 299642.08 | E446: 1246270723 | F446: 46357 | H446: 2 | I446: Fertilizers | J446: 11075 | K446: 46120 | L446: 1010100 | M446: VENDAS MERCADO INTERNO | N446: 161 | O446: VENDA PROD. INDUSTRIALIZADO - NFE | P446: AGROREP. REPRESENTACOES AGRICOLAS | Q446: =$R$1-F446 -> -221 | R446: =_xlfn.XLOOKUP(E446,'Data Additive'!E:E,'Data Additive'!E:E,0) -> 0
A447: 9295 | B447: TECNOMYL S.A. - PARAGUAY | C447: 99.999.999/9999-99 | D447: 130127.06 | E447: 1246270982 | F447: 46152 | H447: 1 | I447: Adtives | J447: 11090 | K447: 46122 | L447: 1010200 | M447: VENDAS MERCADO EXTERNO | N447: 40 | O447: VENDA - NFE (EXPORTAÇÃO) | P447: TECNOMYL S.A. - PARAGUAY | Q447: =$R$1-F447 -> -16 | R447: =_xlfn.XLOOKUP(E447,'Data Additive'!E:E,'Data Additive'!E:E,0) -> 0
A448: 9295 | B448: TECNOMYL S.A. - PARAGUAY | C448: 99.999.999/9999-99 | D448: 132185.95 | E448: 1246270621 | F448: 46150 | H448: 1 | I448: Adtives | J448: 11071 | K448: 46120 | L448: 1010200 | M448: VENDAS MERCADO EXTERNO | N448: 40 | O448: VENDA - NFE (EXPORTAÇÃO) | P448: TECNOMYL S.A. - PARAGUAY | Q448: =$R$1-F448 -> -14 | R448: =_xlfn.XLOOKUP(E448,'Data Additive'!E:E,'Data Additive'!E:E,0) -> 0
A449: 9298 | B449: TERRA FERTIL - MACHADO | C449: 15.003.086/0001-83 | D449: 111799 | E449: 1246070436 | F449: 45555 | H449: 2 | I449: Fertilizers | J449: 20815 | K449: 44991 | L449: 1010100 | M449: VENDAS MERCADO INTERNO | N449: 161 | O449: VENDA PROD. INDUSTRIALIZADO - NFE | P449: TERRA FERTIL - MACHADO | Q449: =$R$1-F449 -> 581 | R449: =_xlfn.XLOOKUP(E449,'Data Additive'!E:E,'Data Additive'!E:E,0) -> 0
A450: 9298 | B450: TERRA FERTIL - MACHADO | C450: 15.003.086/0001-83 | D450: 65548 | E450: 1246070905 | F450: 45555 | H450: 2 | I450: Fertilizers | J450: 20839 | K450: 44994 | L450: 1010100 | M450: VENDAS MERCADO INTERNO | N450: 161 | O450: VENDA PROD. INDUSTRIALIZADO - NFE | P450: TERRA FERTIL - MACHADO | Q450: =$R$1-F450 -> 581 | R450: =_xlfn.XLOOKUP(E450,'Data Additive'!E:E,'Data Additive'!E:E,0) -> 0
A451: 9298 | B451: TERRA FERTIL - MACHADO | C451: 15.003.086/0001-83 | D451: 112475 | E451: 1246068948 | F451: 45555 | H451: 2 | I451: Fertilizers | J451: 20763 | K451: 44984 | L451: 1010100 | M451: VENDAS MERCADO INTERNO | N451: 161 | O451: VENDA PROD. INDUSTRIALIZADO - NFE | P451: TERRA FERTIL - MACHADO | Q451: =$R$1-F451 -> 581 | R451: =_xlfn.XLOOKUP(E451,'Data Additive'!E:E,'Data Additive'!E:E,0) -> 0
A452: 9298 | B452: TERRA FERTIL - MACHADO | C452: 15.003.086/0001-83 | D452: 149824 | E452: 1246068778 | F452: 45555 | H452: 2 | I452: Fertilizers | J452: 20750 | K452: 44981 | L452: 1010100 | M452: VENDAS MERCADO INTERNO | N452: 161 | O452: VENDA PROD. INDUSTRIALIZADO - NFE | P452: TERRA FERTIL - MACHADO | Q452: =$R$1-F452 -> 581 | R452: =_xlfn.XLOOKUP(E452,'Data Additive'!E:E,'Data Additive'!E:E,0) -> 0
A453: 9298 | B453: TERRA FERTIL - MACHADO | C453: 15.003.086/0001-83 | D453: 131203 | E453: 1246070820 | F453: 45555 | H453: 2 | I453: Fertilizers | J453: 20836 | K453: 44993 | L453: 1010100 | M453: VENDAS MERCADO INTERNO | N453: 161 | O453: VENDA PROD. INDUSTRIALIZADO - NFE | P453: TERRA FERTIL - MACHADO | Q453: =$R$1-F453 -> 581 | R453: =_xlfn.XLOOKUP(E453,'Data Additive'!E:E,'Data Additive'!E:E,0) -> 0
A454: 9298 | B454: TERRA FERTIL - MACHADO | C454: 15.003.086/0001-83 | D454: 119356.2 | E454: 1246068614 | F454: 45555 | H454: 2 | I454: Fertilizers | J454: 20734 | K454: 44980 | L454: 1010100 | M454: VENDAS MERCADO INTERNO | N454: 161 | O454: VENDA PROD. INDUSTRIALIZADO - NFE | P454: TERRA FERTIL - MACHADO | Q454: =$R$1-F454 -> 581 | R454: =_xlfn.XLOOKUP(E454,'Data Additive'!E:E,'Data Additive'!E:E,0) -> 0
A455: 9298 | B455: TERRA FERTIL - MACHADO | C455: 15.003.086/0001-83 | D455: 122521 | E455: 1246068997 | F455: 45555 | H455: 2 | I455: Fertilizers | J455: 20767 | K455: 44984 | L455: 1010100 | M455: VENDAS MERCADO INTERNO | N455: 161 | O455: VENDA PROD. INDUSTRIALIZADO - NFE | P455: TERRA FERTIL - MACHADO | Q455: =$R$1-F455 -> 581 | R455: =_xlfn.XLOOKUP(E455,'Data Additive'!E:E,'Data Additive'!E:E,0) -> 0
A456: 9298 | B456: TERRA FERTIL - MACHADO | C456: 15.003.086/0001-83 | D456: 118731.49 | E456: 1246083500 | F456: 45555 | H456: 2 | I456: Fertilizers | J456: 21456 | K456: 45070 | L456: 1010100 | M456: VENDAS MERCADO INTERNO | N456: 161 | O456: VENDA PROD. INDUSTRIALIZADO - NFE | P456: TERRA FERTIL - MACHADO | Q456: =$R$1-F456 -> 581 | R456: =_xlfn.XLOOKUP(E456,'Data Additive'!E:E,'Data Additive'!E:E,0) -> 0
A457: 9298 | B457: TERRA FERTIL - MACHADO | C457: 15.003.086/0001-83 | D457: 52557.4 | E457: 1246083593 | F457: 45555 | H457: 2 | I457: Fertilizers | J457: 21460 | K457: 45070 | L457: 1010100 | M457: VENDAS MERCADO INTERNO | N457: 161 | O457: VENDA PROD. INDUSTRIALIZADO - NFE | P457: TERRA FERTIL - MACHADO | Q457: =$R$1-F457 -> 581 | R457: =_xlfn.XLOOKUP(E457,'Data Additive'!E:E,'Data Additive'!E:E,0) -> 0
... A479: 9355 | B479: NITROFERT SAS - COLOMBIA | C479: ..- | D479: 1191855.3 | E479: 1246265200 | F479: 46177 | H479: 1 | I479: Adtives | J479: 2778 | K479: 46078 | L479: 1010200 | M479: VENDAS MERCADO EXTERNO | N479: 40 | O479: VENDA - NFE (EXPORTAÇÃO) | P479: NITROFERT SAS - COLOMBIA | Q479: =$R$1-F479 -> -41 | R479: =_xlfn.XLOOKUP(E479,'Data Additive'!E:E,'Data Additive'!E:E,0) -> 0
A480: 9830 | B480: ELYMAR JOSE DA SILVA FERREIRA | C480: 053.438.381-54 | D480: 331 | E480: 1246266367 | F480: 46145 | I480: Não encontrado | J480: 10813 | K480: 46085 | L480: 4011600 | M480: APARELHOS DE INFORMÁTICA | N480: 244 | O480: VENDA DE IMOBILIZADO SEM ICMS | P480: ELYMAR JOSE DA SILVA FERREIRA | Q480: =$R$1-F480 -> -9 | R480: =_xlfn.XLOOKUP(E480,'Data Additive'!E:E,'Data Additive'!E:E,0) -> 1246266367
A481: 9830 | B481: ELYMAR JOSE DA SILVA FERREIRA | C481: 053.438.381-54 | D481: 331 | E481: 1246266368 | F481: 46175 | I481: Não encontrado | J481: 10813 | K481: 46085 | L481: 4011600 | M481: APARELHOS DE INFORMÁTICA | N481: 244 | O481: VENDA DE IMOBILIZADO SEM ICMS | P481: ELYMAR JOSE DA SILVA FERREIRA | Q481: =$R$1-F481 -> -39 | R481: =_xlfn.XLOOKUP(E481,'Data Additive'!E:E,'Data Additive'!E:E,0) -> 1246266368
A482: 11768 | B482: CERES PERU S.A | C482: ..- | D482: 86689.1 | E482: 1246264534 | F482: 46136 | H482: 1 | I482: Adtives | J482: 10744 | K482: 46076 | L482: 1010200 | M482: VENDAS MERCADO EXTERNO | N482: 40 | O482: VENDA - NFE (EXPORTAÇÃO) | P482: CERES PERU S.A | Q482: =$R$1-F482 -> 0 | R482: =_xlfn.XLOOKUP(E482,'Data Additive'!E:E,'Data Additive'!E:E,0) -> 0
A483: 11770 | B483: FERTIBAL - EQUADOR | C483: ..- | D483: 14548.35 | E483: 1246263524 | F483: 46039 | H483: 1 | I483: Adtives | J483: 9853 | K483: 45959 | L483: 1010200 | M483: VENDAS MERCADO EXTERNO | N483: 40 | O483: VENDA - NFE (EXPORTAÇÃO) | P483: FERTIBAL - EQUADOR | Q483: =$R$1-F483 -> 97 | R483: =_xlfn.XLOOKUP(E483,'Data Additive'!E:E,'Data Additive'!E:E,0) -> 0
A484: 10454 | B484: MOGIANA TECNO AGRO | C484: 33.030.913/0001-00 | D484: 144418.2 | E484: 1246051128 | F484: 45229 | H484: 2 | I484: Fertilizers | J484: 19700 | K484: 44860 | L484: 1010100 | M484: VENDAS MERCADO INTERNO | N484: 161 | O484: VENDA PROD. INDUSTRIALIZADO - NFE | P484: MOGIANA TECNO AGRO | Q484: =$R$1-F484 -> 907 | R484: =_xlfn.XLOOKUP(E484,'Data Additive'!E:E,'Data Additive'!E:E,0) -> 0
A485: 10454 | B485: MOGIANA TECNO AGRO | C485: 33.030.913/0001-00 | D485: 144418.2 | E485: 1246049220 | F485: 45229 | H485: 2 | I485: Fertilizers | J485: 19589 | K485: 44852 | L485: 1010100 | M485: VENDAS MERCADO INTERNO | N485: 161 | O485: VENDA PROD. INDUSTRIALIZADO - NFE | P485: MOGIANA TECNO AGRO | Q485: =$R$1-F485 -> 907 | R485: =_xlfn.XLOOKUP(E485,'Data Additive'!E:E,'Data Additive'!E:E,0) -> 0
A486: 10454 | B486: MOGIANA TECNO AGRO | C486: 33.030.913/0001-00 | D486: 149099.08 | E486: 1246058414 | F486: 45229 | H486: 2 | I486: Fertilizers | J486: 20191 | K486: 44909 | L486: 1010100 | M486: VENDAS MERCADO INTERNO | N486: 161 | O486: VENDA PROD. INDUSTRIALIZADO - NFE | P486: MOGIANA TECNO AGRO | Q486: =$R$1-F486 -> 907 | R486: =_xlfn.XLOOKUP(E486,'Data Additive'!E:E,'Data Additive'!E:E,0) -> 0
A487: 10454 | B487: MOGIANA TECNO AGRO | C487: 33.030.913/0001-00 | D487: 151022.08 | E487: 1246066481 | F487: 45229 | H487: 2 | I487: Fertilizers | J487: 20644 | K487: 44965 | L487: 1010100 | M487: VENDAS MERCADO INTERNO | N487: 161 | O487: VENDA PROD. INDUSTRIALIZADO - NFE | P487: MOGIANA TECNO AGRO | Q487: =$R$1-F487 -> 907 | R487: =_xlfn.XLOOKUP(E487,'Data Additive'!E:E,'Data Additive'!E:E,0) -> 0
A488: 10454 | B488: MOGIANA TECNO AGRO | C488: 33.030.913/0001-00 | D488: 248498.47 | E488: 1246058556 | F488: 45229 | H488: 2 | I488: Fertilizers | J488: 20197 | K488: 44909 | L488: 1010100 | M488: VENDAS MERCADO INTERNO | N488: 161 | O488: VENDA PROD. INDUSTRIALIZADO - NFE | P488: MOGIANA TECNO AGRO | Q488: =$R$1-F488 -> 907 | R488: =_xlfn.XLOOKUP(E488,'Data Additive'!E:E,'Data Additive'!E:E,0) -> 0
A489: 10454 | B489: MOGIANA TECNO AGRO | C489: 33.030.913/0001-00 | D489: 122816.13 | E489: 1246065495 | F489: 45229 | H489: 2 | I489: Fertilizers | J489: 20599 | K489: 44958 | L489: 1010100 | M489: VENDAS MERCADO INTERNO | N489: 161 | O489: VENDA PROD. INDUSTRIALIZADO - NFE | P489: MOGIANA TECNO AGRO | Q489: =$R$1-F489 -> 907 | R489: =_xlfn.XLOOKUP(E489,'Data Additive'!E:E,'Data Additive'!E:E,0) -> 0
A490: 10454 | B490: MOGIANA TECNO AGRO | C490: 33.030.913/0001-00 | D490: 97567.15 | E490: 1246059110 | F490: 45229 | H490: 2 | I490: Fertilizers | J490: 20229 | K490: 44911 | L490: 1010100 | M490: VENDAS MERCADO INTERNO | N490: 161 | O490: VENDA PROD. INDUSTRIALIZADO - NFE | P490: MOGIANA TECNO AGRO | Q490: =$R$1-F490 -> 907 | R490: =_xlfn.XLOOKUP(E490,'Data Additive'!E:E,'Data Additive'!E:E,0) -> 0
...

Sheet Data Additive
D1: =SUBTOTAL(9,$D$3:$D$868) -> 27655916 | R1: 46136
A2: CODPARC | B2: NOMEPARC | C2: CNPJ | D2: Valor | E2: NUFIN | F2: DTVENC | G2: DHBAIXA | H2: AD_BU | I2: NOME_BU | J2: NUMNOTA | K2: DTENTSAI | L2: CODNAT | M2: DESCRNAT | N2: CODTIPOPER | O2: OPERACAO | P2: Grupo | Q2: Dias vencidos
A3: 205 | B3: FERTIPAR - RONDONÓPOLIS | C3: 09.384.948/0002-43 | D3: 80589.6 | E3: 1246271690 | F3: 46157 | H3: 1 | I3: Adtives | J3: 11158 | K3: 46129 | L3: 1010100 | M3: VENDAS MERCADO INTERNO | N3: 161 | O3: VENDA PROD. INDUSTRIALIZADO - NFE | P3: GRUPO FERTIPAR FERTILIZANTES MATO GROSSO | Q3: =$R$1-F3 -> -21 | R3: =_xlfn.XLOOKUP(P3,'Painel Additive'!$B:$B,'Painel Additive'!$B:$B,0) -> GRUPO FERTIPAR FERTILIZANTES MATO GROSSO | S3: =F3-K3 -> 28
A4: 205 | B4: FERTIPAR - RONDONÓPOLIS | C4: 09.384.948/0002-43 | D4: 75474 | E4: 1246269597 | F4: 46139 | H4: 1 | I4: Adtives | J4: 11003 | K4: 46111 | L4: 1010100 | M4: VENDAS MERCADO INTERNO | N4: 161 | O4: VENDA PROD. INDUSTRIALIZADO - NFE | P4: GRUPO FERTIPAR FERTILIZANTES MATO GROSSO | Q4: =$R$1-F4 -> -3 | R4: =_xlfn.XLOOKUP(P4,'Painel Additive'!$B:$B,'Painel Additive'!$B:$B,0) -> GRUPO FERTIPAR FERTILIZANTES MATO GROSSO | S4: =F4-K4 -> 28
A5: 1257 | B5: MOSAIC - CAMPO GRANDE | C5: 61.156.501/0081-30 | D5: 1980.8 | E5: 1246032946 | F5: 44774 | H5: 1 | I5: Adtives | J5: 17935 | K5: 44714 | L5: 1010100 | M5: VENDAS MERCADO INTERNO | N5: 56 | O5: VENDA A ORDEM | P5: GRUPO MOSAIC FERTILIZANTES DO BRASIL | Q5: =$R$1-F5 -> 1362 | R5: =_xlfn.XLOOKUP(P5,'Painel Additive'!$B:$B,'Painel Additive'!$B:$B,0) -> GRUPO MOSAIC FERTILIZANTES DO BRASIL | S5: =F5-K5 -> 60
A6: 1953 | B6: AMAGGI - COMODORO | C6: 77.294.254/0075-20 | D6: 58917.8 | E6: 1246267986 | F6: 46158 | H6: 1 | I6: Adtives | J6: 10907 | K6: 46098 | L6: 1010100 | M6: VENDAS MERCADO INTERNO | N6: 161 | O6: VENDA PROD. INDUSTRIALIZADO - NFE | P6: GRUPO AMAGGI | Q6: =$R$1-F6 -> -22 | R6: =_xlfn.XLOOKUP(P6,'Painel Additive'!$B:$B,'Painel Additive'!$B:$B,0) -> GRUPO AMAGGI | S6: =F6-K6 -> 60
A7: 1787 | B7: MOSAIC - UBERABA (CIU1) | C7: 33.931.486/0014-55 | D7: 109862.4 | E7: 1246271310 | F7: 46216 | H7: 1 | I7: Adtives | J7: 11116 | K7: 46126 | L7: 1010100 | M7: VENDAS MERCADO INTERNO | N7: 161 | O7: VENDA PROD. INDUSTRIALIZADO - NFE | P7: GRUPO MOSAIC FERTILIZANTES P K LTDA | Q7: =$R$1-F7 -> -80 | R7: =_xlfn.XLOOKUP(P7,'Painel Additive'!$B:$B,'Painel Additive'!$B:$B,0) -> GRUPO MOSAIC FERTILIZANTES P K LTDA | S7: =F7-K7 -> 90
A8: 1787 | B8: MOSAIC - UBERABA (CIU1) | C8: 33.931.486/0014-55 | D8: 116928 | E8: 1246267948 | F8: 46187 | H8: 1 | I8: Adtives | J8: 10899 | K8: 46097 | L8: 1010100 | M8: VENDAS MERCADO INTERNO | N8: 161 | O8: VENDA PROD. INDUSTRIALIZADO - NFE | P8: GRUPO MOSAIC FERTILIZANTES P K LTDA | Q8: =$R$1-F8 -> -51 | R8: =_xlfn.XLOOKUP(P8,'Painel Additive'!$B:$B,'Painel Additive'!$B:$B,0) -> GRUPO MOSAIC FERTILIZANTES P K LTDA | S8: =F8-K8 -> 90
A9: 1787 | B9: MOSAIC - UBERABA (CIU1) | C9: 33.931.486/0014-55 | D9: 115891.2 | E9: 1246262540 | F9: 46149 | H9: 1 | I9: Adtives | J9: 10652 | K9: 46059 | L9: 1010100 | M9: VENDAS MERCADO INTERNO | N9: 161 | O9: VENDA PROD. INDUSTRIALIZADO - NFE | P9: GRUPO MOSAIC FERTILIZANTES P K LTDA | Q9: =$R$1-F9 -> -13 | R9: =_xlfn.XLOOKUP(P9,'Painel Additive'!$B:$B,'Painel Additive'!$B:$B,0) -> GRUPO MOSAIC FERTILIZANTES P K LTDA | S9: =F9-K9 -> 90
A10: 1787 | B10: MOSAIC - UBERABA (CIU1) | C10: 33.931.486/0014-55 | D10: 103795.2 | E10: 1246268633 | F10: 46194 | H10: 1 | I10: Adtives | J10: 10957 | K10: 46104 | L10: 1010100 | M10: VENDAS MERCADO INTERNO | N10: 161 | O10: VENDA PROD. INDUSTRIALIZADO - NFE | P10: GRUPO MOSAIC FERTILIZANTES P K LTDA | Q10: =$R$1-F10 -> -58 | R10: =_xlfn.XLOOKUP(P10,'Painel Additive'!$B:$B,'Painel Additive'!$B:$B,0) -> GRUPO MOSAIC FERTILIZANTES P K LTDA | S10: =F10-K10 -> 90
A11: 1787 | B11: MOSAIC - UBERABA (CIU1) | C11: 33.931.486/0014-55 | D11: 111360 | E11: 1246268748 | F11: 46195 | H11: 1 | I11: Adtives | J11: 10965 | K11: 46105 | L11: 1010100 | M11: VENDAS MERCADO INTERNO | N11: 161 | O11: VENDA PROD. INDUSTRIALIZADO - NFE | P11: GRUPO MOSAIC FERTILIZANTES P K LTDA | Q11: =$R$1-F11 -> -59 | R11: =_xlfn.XLOOKUP(P11,'Painel Additive'!$B:$B,'Painel Additive'!$B:$B,0) -> GRUPO MOSAIC FERTILIZANTES P K LTDA | S11: =F11-K11 -> 90
A12: 1787 | B12: MOSAIC - UBERABA (CIU1) | C12: 33.931.486/0014-55 | D12: 114662.4 | E12: 1246268585 | F12: 46161 | H12: 1 | I12: Adtives | J12: 10953 | K12: 46101 | L12: 1010100 | M12: VENDAS MERCADO INTERNO | N12: 161 | O12: VENDA PROD. INDUSTRIALIZADO - NFE | P12: GRUPO MOSAIC FERTILIZANTES P K LTDA | Q12: =$R$1-F12 -> -25 | R12: =_xlfn.XLOOKUP(P12,'Painel Additive'!$B:$B,'Painel Additive'!$B:$B,0) -> GRUPO MOSAIC FERTILIZANTES P K LTDA | S12: =F12-K12 -> 60
A13: 1787 | B13: MOSAIC - UBERABA (CIU1) | C13: 33.931.486/0014-55 | D13: 115852.8 | E13: 1246270635 | F13: 46210 | H13: 1 | I13: Adtives | J13: 11072 | K13: 46120 | L13: 1010100 | M13: VENDAS MERCADO INTERNO | N13: 161 | O13: VENDA PROD. INDUSTRIALIZADO - NFE | P13: GRUPO MOSAIC FERTILIZANTES P K LTDA | Q13: =$R$1-F13 -> -74 | R13: =_xlfn.XLOOKUP(P13,'Painel Additive'!$B:$B,'Painel Additive'!$B:$B,0) -> GRUPO MOSAIC FERTILIZANTES P K LTDA | S13: =F13-K13 -> 90
A14: 1787 | B14: MOSAIC - UBERABA (CIU1) | C14: 33.931.486/0014-55 | D14: 114739.2 | E14: 1246271165 | F14: 46215 | H14: 1 | I14: Adtives | J14: 11105 | K14: 46125 | L14: 1010100 | M14: VENDAS MERCADO INTERNO | N14: 161 | O14: VENDA PROD. INDUSTRIALIZADO - NFE | P14: GRUPO MOSAIC FERTILIZANTES P K LTDA | Q14: =$R$1-F14 -> -79 | R14: =_xlfn.XLOOKUP(P14,'Painel Additive'!$B:$B,'Painel Additive'!$B:$B,0) -> GRUPO MOSAIC FERTILIZANTES P K LTDA | S14: =F14-K14 -> 90
... A190: 707 | B190: TERRA FERTILIZANTES LTDA - ARAXÁ | C190: 10.482.668/0001-76 | D190: 40353.6 | E190: 1246143397 | F190: 45443 | H190: 1 | I190: Adtives | J190: 3448 | K190: 45415 | L190: 1010100 | M190: VENDAS MERCADO INTERNO | N190: 161 | O190: VENDA PROD. INDUSTRIALIZADO - NFE | P190: TERRA FERTILIZANTES LTDA - ARAXÁ | Q190: =$R$1-F190 -> 693 | R190: =_xlfn.XLOOKUP(P190,'Painel Additive'!$B:$B,'Painel Additive'!$B:$B,0) -> TERRA FERTILIZANTES LTDA - ARAXÁ | S190: =F190-K190 -> 28
A191: 1462 | B191: AURORA MINERAÇÃO LTDA | C191: 02.964.101/0001-08 | D191: 37608.4 | E191: 1246266894 | F191: 46147 | H191: 1 | I191: Adtives | J191: 10834 | K191: 46087 | L191: 1010100 | M191: VENDAS MERCADO INTERNO | N191: 161 | O191: VENDA PROD. INDUSTRIALIZADO - NFE | P191: AURORA MINERAÇÃO LTDA | Q191: =$R$1-F191 -> -11 | R191: =_xlfn.XLOOKUP(P191,'Painel Additive'!$B:$B,'Painel Additive'!$B:$B,0) -> AURORA MINERAÇÃO LTDA | S191: =F191-K191 -> 60 | T191: =F191-$R$1 -> 11
A192: 1462 | B192: AURORA MINERAÇÃO LTDA | C192: 02.964.101/0001-08 | D192: 37608.4 | E192: 1246266895 | F192: 46157 | H192: 1 | I192: Adtives | J192: 10834 | K192: 46087 | L192: 1010100 | M192: VENDAS MERCADO INTERNO | N192: 161 | O192: VENDA PROD. INDUSTRIALIZADO - NFE | P192: AURORA MINERAÇÃO LTDA | Q192: =$R$1-F192 -> -21 | R192: =_xlfn.XLOOKUP(P192,'Painel Additive'!$B:$B,'Painel Additive'!$B:$B,0) -> AURORA MINERAÇÃO LTDA | S192: =F192-K192 -> 70 | T192: =F192-$R$1 -> 21
A193: 1462 | B193: AURORA MINERAÇÃO LTDA | C193: 02.964.101/0001-08 | D193: 38160.2 | E193: 1246270126 | F193: 46174 | H193: 1 | I193: Adtives | J193: 11041 | K193: 46114 | L193: 1010100 | M193: VENDAS MERCADO INTERNO | N193: 161 | O193: VENDA PROD. INDUSTRIALIZADO - NFE | P193: AURORA MINERAÇÃO LTDA | Q193: =$R$1-F193 -> -38 | R193: =_xlfn.XLOOKUP(P193,'Painel Additive'!$B:$B,'Painel Additive'!$B:$B,0) -> AURORA MINERAÇÃO LTDA | S193: =F193-K193 -> 60 | T193: =F193-$R$1 -> 38
A194: 1462 | B194: AURORA MINERAÇÃO LTDA | C194: 02.964.101/0001-08 | D194: 38160.2 | E194: 1246270127 | F194: 46184 | H194: 1 | I194: Adtives | J194: 11041 | K194: 46114 | L194: 1010100 | M194: VENDAS MERCADO INTERNO | N194: 161 | O194: VENDA PROD. INDUSTRIALIZADO - NFE | P194: AURORA MINERAÇÃO LTDA | Q194: =$R$1-F194 -> -48 | R194: =_xlfn.XLOOKUP(P194,'Painel Additive'!$B:$B,'Painel Additive'!$B:$B,0) -> AURORA MINERAÇÃO LTDA | S194: =F194-K194 -> 70
A195: 1462 | B195: AURORA MINERAÇÃO LTDA | C195: 02.964.101/0001-08 | D195: 37491.5 | E195: 1246262009 | F195: 46125 | H195: 1 | I195: Adtives | J195: 10624 | K195: 46055 | L195: 1010100 | M195: VENDAS MERCADO INTERNO | N195: 161 | O195: VENDA PROD. INDUSTRIALIZADO - NFE | P195: AURORA MINERAÇÃO LTDA | Q195: =$R$1-F195 -> 11 | R195: =_xlfn.XLOOKUP(P195,'Painel Additive'!$B:$B,'Painel Additive'!$B:$B,0) -> AURORA MINERAÇÃO LTDA | S195: =F195-K195 -> 70
A196: 2011 | B196: FERTGROW S.A | C196: 14.267.717/0001-09 | D196: 106570.7 | E196: 1246270108 | F196: 46142 | H196: 1 | I196: Adtives | J196: 11036 | K196: 46114 | L196: 1010100 | M196: VENDAS MERCADO INTERNO | N196: 161 | O196: VENDA PROD. INDUSTRIALIZADO - NFE | P196: FERTGROW S.A | Q196: =$R$1-F196 -> -6 | R196: =_xlfn.XLOOKUP(P196,'Painel Additive'!$B:$B,'Painel Additive'!$B:$B,0) -> FERTGROW S.A | S196: =F196-K196 -> 28
A197: 2011 | B197: FERTGROW S.A | C197: 14.267.717/0001-09 | D197: 105829.4 | E197: 1246271331 | F197: 46154 | H197: 1 | I197: Adtives | J197: 11121 | K197: 46126 | L197: 1010100 | M197: VENDAS MERCADO INTERNO | N197: 161 | O197: VENDA PROD. INDUSTRIALIZADO - NFE | P197: FERTGROW S.A | Q197: =$R$1-F197 -> -18 | R197: =_xlfn.XLOOKUP(P197,'Painel Additive'!$B:$B,'Painel Additive'!$B:$B,0) -> FERTGROW S.A | S197: =F197-K197 -> 28
A198: 31 | B198: SUL GOIANA - GOIATUBA | C198: 37.309.283/0001-68 | D198: 120000 | E198: 1246269899 | F198: 46141 | H198: 1 | I198: Adtives | J198: 2861 | K198: 46113 | L198: 1010100 | M198: VENDAS MERCADO INTERNO | N198: 161 | O198: VENDA PROD. INDUSTRIALIZADO - NFE | P198: SUL GOIANA - GOIATUBA | Q198: =$R$1-F198 -> -5 | R198: =_xlfn.XLOOKUP(P198,'Painel Additive'!$B:$B,'Painel Additive'!$B:$B,0) -> SUL GOIANA - GOIATUBA | S198: =F198-K198 -> 28
A199: 2247 | B199: ADUBOS LEAO - LARANJEIRAS | C199: 27.360.944/0001-26 | D199: 12189 | E199: 1246272759 | F199: 46167 | H199: 1 | I199: Adtives | J199: 2896 | K199: 46139 | L199: 1010100 | M199: VENDAS MERCADO INTERNO | N199: 161 | O199: VENDA PROD. INDUSTRIALIZADO - NFE | P199: ADUBOS LEAO - LARANJEIRAS | Q199: =$R$1-F199 -> -31 | R199: =_xlfn.XLOOKUP(P199,'Painel Additive'!$B:$B,'Painel Additive'!$B:$B,0) -> ADUBOS LEAO - LARANJEIRAS | S199: =F199-K199 -> 28
A200: 2247 | B200: ADUBOS LEAO - LARANJEIRAS | C200: 27.360.944/0001-26 | D200: 12189 | E200: 1246272760 | F200: 46195 | H200: 1 | I200: Adtives | J200: 2896 | K200: 46139 | L200: 1010100 | M200: VENDAS MERCADO INTERNO | N200: 161 | O200: VENDA PROD. INDUSTRIALIZADO - NFE | P200: ADUBOS LEAO - LARANJEIRAS | Q200: =$R$1-F200 -> -59 | R200: =_xlfn.XLOOKUP(P200,'Painel Additive'!$B:$B,'Painel Additive'!$B:$B,0) -> ADUBOS LEAO - LARANJEIRAS | S200: =F200-K200 -> 56
A201: 2247 | B201: ADUBOS LEAO - LARANJEIRAS | C201: 27.360.944/0001-26 | D201: 956 | E201: 1246272577 | F201: 46164 | H201: 1 | I201: Adtives | J201: 2892 | K201: 46136 | L201: 1010100 | M201: VENDAS MERCADO INTERNO | N201: 161 | O201: VENDA PROD. INDUSTRIALIZADO - NFE | P201: ADUBOS LEAO - LARANJEIRAS | Q201: =$R$1-F201 -> -28 | R201: =_xlfn.XLOOKUP(P201,'Painel Additive'!$B:$B,'Painel Additive'!$B:$B,0) -> ADUBOS LEAO - LARANJEIRAS | S201: =F201-K201 -> 28
A202: 2247 | B202: ADUBOS LEAO - LARANJEIRAS | C202: 27.360.944/0001-26 | D202: 956 | E202: 1246272578 | F202: 46192 | H202: 1 | I202: Adtives | J202: 2892 | K202: 46136 | L202: 1010100 | M202: VENDAS MERCADO INTERNO | N202: 161 | O202: VENDA PROD. INDUSTRIALIZADO - NFE | P202: ADUBOS LEAO - LARANJEIRAS | Q202: =$R$1-F202 -> -56 | R202: =_xlfn.XLOOKUP(P202,'Painel Additive'!$B:$B,'Painel Additive'!$B:$B,0) -> ADUBOS LEAO - LARANJEIRAS | S202: =F202-K202 -> 56
A203: 3142 | B203: INTERFERTIL - SAO FRANCISCO DO SUL | C203: 01.094.764/0002-37 | D203: 44919 | E203: 1246272504 | F203: 46164 | H203: 1 | I203: Adtives | J203: 11215 | K203: 46136 | L203: 1010100 | M203: VENDAS MERCADO INTERNO | N203: 161 | O203: VENDA PROD. INDUSTRIALIZADO - NFE | P203: INTERFERTIL - SAO FRANCISCO DO SUL | Q203: =$R$1-F203 -> -28 | R203: =_xlfn.XLOOKUP(P203,'Painel Additive'!$B:$B,'Painel Additive'!$B:$B,0) -> INTERFERTIL - SAO FRANCISCO DO SUL | S203: =F203-K203 -> 28
A204: 2900 | B204: BIOSAFRA - MARUIM | C204: 04.251.044/0001-45 | D204: 17017.16 | E204: 1246267967 | F204: 46157 | H204: 1 | I204: Adtives | J204: 10901 | K204: 46097 | L204: 1010100 | M204: VENDAS MERCADO INTERNO | N204: 161 | O204: VENDA PROD. INDUSTRIALIZADO - NFE | P204: BIOSAFRA - MARUIM | Q204: =$R$1-F204 -> -21 | R204: =_xlfn.XLOOKUP(P204,'Painel Additive'!$B:$B,'Painel Additive'!$B:$B,0) -> BIOSAFRA - MARUIM | S204: =F204-K204 -> 60
A205: 2900 | B205: BIOSAFRA - MARUIM | C205: 04.251.044/0001-45 | D205: 17017.16 | E205: 1246267968 | F205: 46187 | H205: 1 | I205: Adtives | J205: 10901 | K205: 46097 | L205: 1010100 | M205: VENDAS MERCADO INTERNO | N205: 161 | O205: VENDA PROD. INDUSTRIALIZADO - NFE | P205: BIOSAFRA - MARUIM | Q205: =$R$1-F205 -> -51 | R205: =_xlfn.XLOOKUP(P205,'Painel Additive'!$B:$B,'Painel Additive'!$B:$B,0) -> BIOSAFRA - MARUIM | S205: =F205-K205 -> 90
... A234: 7022 | B234: STRATOS/MOSAIC - ROSARIO DO CATETE | C234: 31.009.644/0001-74 | D234: 70752.8 | E234: 1246265339 | F234: 46139 | H234: 1 | I234: Adtives | J234: 10774 | K234: 46079 | L234: 1010100 | M234: VENDAS MERCADO INTERNO | N234: 161 | O234: VENDA PROD. INDUSTRIALIZADO - NFE | P234: STRATOS/MOSAIC - ROSARIO DO CATETE | Q234: =$R$1-F234 -> -3 | R234: =_xlfn.XLOOKUP(P234,'Painel Additive'!$B:$B,'Painel Additive'!$B:$B,0) -> STRATOS/MOSAIC - ROSARIO DO CATETE | S234: =F234-K234 -> 60
A235: 9830 | B235: ELYMAR JOSE DA SILVA FERREIRA | C235: 053.438.381-54 | D235: 331 | E235: 1246266367 | F235: 46145 | I235: Não encontrado | J235: 10813 | K235: 46085 | L235: 4011600 | M235: APARELHOS DE INFORMÁTICA | N235: 244 | O235: VENDA DE IMOBILIZADO SEM ICMS | P235: ELYMAR JOSE DA SILVA FERREIRA | Q235: =$R$1-F235 -> -9 | R235: =_xlfn.XLOOKUP(P235,'Painel Additive'!$B:$B,'Painel Additive'!$B:$B,0) -> ELYMAR JOSE DA SILVA FERREIRA | S235: =F235-K235 -> 60
A236: 9830 | B236: ELYMAR JOSE DA SILVA FERREIRA | C236: 053.438.381-54 | D236: 331 | E236: 1246266368 | F236: 46175 | I236: Não encontrado | J236: 10813 | K236: 46085 | L236: 4011600 | M236: APARELHOS DE INFORMÁTICA | N236: 244 | O236: VENDA DE IMOBILIZADO SEM ICMS | P236: ELYMAR JOSE DA SILVA FERREIRA | Q236: =$R$1-F236 -> -39 | R236: =_xlfn.XLOOKUP(P236,'Painel Additive'!$B:$B,'Painel Additive'!$B:$B,0) -> ELYMAR JOSE DA SILVA FERREIRA | S236: =F236-K236 -> 90
A237: 11637 | B237: AGROPECUARIA MARATA LTDA - MARUIM | C237: 32.821.183/0004-45 | D237: 290220 | E237: 1246272018 | F237: 46162 | H237: 1 | I237: Adtives | J237: 2884 | K237: 46134 | L237: 1010100 | M237: VENDAS MERCADO INTERNO | N237: 161 | O237: VENDA PROD. INDUSTRIALIZADO - NFE | P237: AGROPECUARIA MARATA LTDA - MARUIM | Q237: =$R$1-F237 -> -26 | R237: =_xlfn.XLOOKUP(P237,'Painel Additive'!$B:$B,'Painel Additive'!$B:$B,0) -> AGROPECUARIA MARATA LTDA - MARUIM | S237: =F237-K237 -> 28
A238: 12943 | B238: ITERUM - RONDONOPOLIS | C238: 07.571.116/0015-25 | D238: 82290 | E238: 1246187828 | F238: 45667 | H238: 1 | I238: Adtives | J238: 1585 | K238: 45639 | L238: 1010100 | M238: VENDAS MERCADO INTERNO | N238: 161 | O238: VENDA PROD. INDUSTRIALIZADO - NFE | P238: ITERUM - RONDONOPOLIS | Q238: =$R$1-F238 -> 469 | R238: =_xlfn.XLOOKUP(P238,'Painel Additive'!$B:$B,'Painel Additive'!$B:$B,0) -> ITERUM - RONDONOPOLIS | S238: =F238-K238 -> 28
A239: 12943 | B239: ITERUM - RONDONOPOLIS | C239: 07.571.116/0015-25 | D239: 82290 | E239: 1246187829 | F239: 45695 | H239: 1 | I239: Adtives | J239: 1585 | K239: 45639 | L239: 1010100 | M239: VENDAS MERCADO INTERNO | N239: 161 | O239: VENDA PROD. INDUSTRIALIZADO - NFE | P239: ITERUM - RONDONOPOLIS | Q239: =$R$1-F239 -> 441 | R239: =_xlfn.XLOOKUP(P239,'Painel Additive'!$B:$B,'Painel Additive'!$B:$B,0) -> ITERUM - RONDONOPOLIS | S239: =F239-K239 -> 56
