Workbook
Name \0: #N/A
Name \1: #REF!
Name \2: #REF!
Name \3: #REF!
Name \4: #REF!
Name \5: #REF!
Name \a: #N/A
Name \b: #N/A
Name \c: #N/A
Name \d: #N/A
Name \DSUM: #REF!
Name \e: #N/A
Name \EXP: #REF!
Name \f: #N/A
Name \g: #N/A
Name \GL: #REF!
Name \h: #REF!
Name \I: #REF!
Name \k: #REF!
Name \l: #REF!
Name \m: #N/A
Name \MPR2: #REF!
Name \n: #REF!
Name \o: #REF!
Name \p: #N/A
Name \q: #REF!
Name \R: #REF!
Name \s: #N/A
Name \t: #REF!
Name \u: #N/A
Name \w: #REF!
Name \x: #REF!
Name \y: #REF!
Name \z: #REF!
Name _: #REF!
Name __?Business___Market_Spr: #REF!
Name __?End_Use_Analysis___Sectoral_Gro: #REF!
Name __?INDUSTRY_MATERIAL_BALA: #REF!
Name __?INDUSTRY_MATERIAL_BALANCE___PROJECTI: #REF!
Name __?PE___Q1_REV: #REF!
Name __?PE_1996: #REF!
Name __?PE_BUSINESS___PAST___FUT: #REF!
Name __?PE_REV: #REF!
Name __?PRICE_FORECAST___1995: #REF!
Name __?PROFITABILITY__Q3_1996__: #REF!
Name __?Q3___SUMM: #REF!
Name __?Quarterwise_Collection_P: #REF!
Name __?Quarterwise_Export_P: #REF!
Name __?QUARTERWISE_PERFORMA: #REF!
Name __?RE: #REF!
Name _______________________________DAT5: #REF!
Name _______________________________DAT7: #REF!
Name ______________________________DAT1: #REF!
Name ______________________________DAT10: #REF!
Name _____________________________DAT5: #REF!
Name _____________________________DAT7: #REF!
Name ____________________________DAT1: #REF!
Name ____________________________DAT10: #REF!
Name ____________________________DAT5: #REF!
Name ____________________________DAT7: #REF!

Sheet AR - slide BoD
B1: Amounts in 000
B2: Total receivables | I2: =I22/1000 -> 59548.326 | J2: =J22/1000 -> 95548.817
B4: Receivables as on 28th Feb 25 | D4: BU | E4: Overdue | F4: Not Due | G4: Not Due | I4: Provision | J4: Provision | L4: Provision risks - overdue receivables | P4: Remark
L5: Probable | M5: Possible | N5: Rare
B6: Central do Adubo | D6: Fertilizer | E6: =E26/1000 -> 7560.7278 | F6: =F26/1000 -> 0 | G6: =G26/1000 -> 7560.7278 | I6: =I26/1000 -> 0 | J6: =J26/1000 -> 0 | L6: =L26/1000 -> 0 | M6: =M26/1000 -> 7560.7278 | N6: =N26/1000 -> 0 | P6: Creditor´s assembly Judicial recovery plan has not yet been approved by Creditors. Adfert advisors believe that the AS-IS plan will not be approved and new financial conditions will need to be presented.
B7: SM Agro / Fazenda Baturi | D7: Fertilizer | E7: =E27/1000 -> 3088.5311 | F7: =F27/1000 -> 0 | G7: =G27/1000 -> 3088.5311 | I7: =I27/1000 -> 3088.5311 | J7: =J27/1000 -> 0 | L7: =L27/1000 -> 3088.5311 | M7: =M27/1000 -> 0 | N7: =N27/1000 -> 0 | P7: Judicial collection lawsuit is ongoing.
B8: CBM Fertilizantes | D8: Fertilizer | E8: =E28/1000 -> 3044.8509 | F8: =F28/1000 -> 0 | G8: =G28/1000 -> 3044.8509 | I8: =I28/1000 -> 3044.8509 | J8: =J28/1000 -> 0 | L8: =L28/1000 -> 3044.8509 | M8: =M28/1000 -> 0 | N8: =N28/1000 -> 0 | P8: Adfert has taken legal action and collection recovery lawsuit has been filed. Payment plan was not succesful.
B9: Mogiana Tecno Agro | D9: Fertilizer | E9: =E29/1000 -> 2492.8421 | F9: =F29/1000 -> 0 | G9: =G29/1000 -> 2492.8421 | I9: =I29/1000 -> 0 | J9: =J29/1000 -> 0 | L9: =L29/1000 -> 0 | M9: =M29/1000 -> 2492.8421 | N9: =N29/1000 -> 0 | P9: AFT received a renewalled payment proposal. Monthly payments along 2 yrs, with Machineary as guarantee and worth 25% of Open Exposure. Formal proposal still pending full disclosre on documents and valuation on Machinery.
B10: Casa das Sementes | D10: Fertilizer | E10: =E30/1000 -> 1863.2009 | F10: =F30/1000 -> 0 | G10: =G30/1000 -> 1863.2009 | I10: =I30/1000 -> 1863.2009 | J10: =J30/1000 -> 0 | L10: =L30/1000 -> 1863.2009 | M10: =M30/1000 -> 0 | N10: =N30/1000 -> 0 | P10: Legal process ongoing and 100% of the invoices we provisioned.
B11: Terra Fértil | D11: Fertilizer | E11: =E31/1000 -> 1702.8487 | F11: =F31/1000 -> 0 | G11: =G31/1000 -> 1702.8487 | I11: =I31/1000 -> 1702.8487 | J11: =J31/1000 -> 0 | L11: =L31/1000 -> 1702.8487 | M11: =M31/1000 -> 0 | N11: =N31/1000 -> 0 | P11: AFT has reached a payment agreement: 15% paid by Oct 25 and 3 yearly installments (Oct 26-27-28). No discount on principal and price inflation indexed
B12: Agro Beraldo | D12: Fertilizer | E12: =E32/1000 -> 876.01175 | F12: =F32/1000 -> 0 | G12: =G32/1000 -> 876.01175 | I12: =I32/1000 -> 0 | J12: =J32/1000 -> 0 | L12: =L32/1000 -> 0 | M12: =M32/1000 -> 876.01175 | N12: =N32/1000 -> 0 | P12: Judicial collection lawsuit is ongoing.
B14: Total Over Due in Litigation (TOP 7) | E14: =E39/1000 -> 22315.752 | F14: 0 | G14: 0 | I14: =I39/1000 -> 10937.332 | J14: =J39/1000 -> 0 | L14: =L39/1000 -> 10937.332 | M14: =M39/1000 -> 11378.42 | N14: 0
B15: Total Over Due with Possible Loss | E15: =E45/1000 -> 6.07632 | F15: 0 | G15: 0 | I15: =I45/1000 -> 6.07632 | J15: =J45/1000 -> 0 | L15: =L45/1000 -> 6.07632 | M15: =M45/1000 -> 0 | N15: 0
B16: Low Risk - Expect to Receive soon | E16: =E46/1000 -> 1226.0065 | F16: =F46/1000 -> 0 | G16: =G46/1000 -> 1226.0065 | I16: =I46/1000 -> 177.60127 | J16: =J46/1000 -> 0 | L16: =L46/1000 -> 0 | M16: =M46/1000 -> 0 | N16: =N46/1000 -> 1226.0065 | P16: Provision as per corporate policy
B17: Total | E17: =E16+E15+E14 -> 23547.835 | F17: =F16+F15+F14 -> 0 | G17: =G16+G15+G14 -> 1226.0065 | I17: =I16+I15+I14 -> 11121.01 | J17: =J16+J15+J14 -> 0 | L17: =L14+L15 -> 10943.409 | M17: =M16+M14 -> 11378.42 | N17: =N16+N14 -> 1226.0065
B19: in BRl
B22: Total receivables | I22: =SUM(E123:F123) -> 59548326 | J22: =SUM(F123:G123) -> 95548817
B24: Receivables as on 30th Apr 26 | D24: BU | E24: Overdue | F24: Not Due | G24: Total | I24: Provision | J24: Write Off | L24: Collection Risk | P24: Remark
L25: Probable | M25: Possible | N25: Rare
B26: CENTRAL DO ADUBO COM E REPRESENTACAO LTD | D26: Fertilizers | E26: 7560727.8 | F26: 0 | G26: =SUM(E26:F26) -> 7560727.8 | I26: 0 | L26: =I26 -> 0 | M26: =E26-I26 -> 7560727.8 | P26: Current Status: Creditor´s Assembly has been approved. All suppliers to receive 35% (65% haircut) of total Outstanding in 10 years (2x per year installments) after a 18-months grace period, corrected by TR inflation index. Prefered suppliers, such as AFT, are eligible to full Overdue recovery based on future sales. 3% of all new CAD Sales to offset Old Overdues and 4% for sales with tenor (credit). This condition is non-binding and the client is to grant AFT a real estate guarantee of BRL 1MM. Upcoming Actions: Decision will now need to undergo approval and pass the entire appeal period. This step may still take a couple months to be completed.
B27: GRUPO LEANDRO SARTI | D27: Fertilizers | E27: 3088531.1 | F27: 0 | G27: =SUM(E27:F27) -> 3088531.1 | I27: 3088531.1 | L27: =I27 -> 3088531.1 | M27: =E27-I27 -> 0 | P27: Current Status: In Litigation via Collection enforcement claim. The judicial process is still in the initial phase, and we are in the period of notifying the parties involved. Upcoming Actions: We will await the procedures set forth by the court.
B28: AGRO BERALDO | D28: Fertilizers | E28: 3044850.9 | F28: 0 | G28: =SUM(E28:F28) -> 3044850.9 | I28: 3044850.9 | L28: =I28 -> 3044850.9 | M28: =E28-I28 -> 0 | P28: Current Status: The Litigation Collection enforcement claim process is ongoing. Upcoming Actions: AFT awaiting for further updates by the court.
B29: TERRA FERTIL - MACHADO | D29: Fertilizers | E29: 2492842.1 | F29: 0 | G29: =SUM(E29:F29) -> 2492842.1 | I29: 0 | L29: =I29 -> 0 | M29: =E29-I29 -> 2492842.1 | P29: Current Status: In Litigation via Collection enforcement claim. An agreement has been reached between parties, under the following terms: (i) Total settlement amount: R$ 3,192,985.64; (ii) Down payment: R$ 478,947.84, to be paid by October 30, 2025; (iii) Remaining balance: R$ 2,714,037.80, to be paid in three annual installments of R$ 904,679.26 each (2026 / 2027 / 2028), to be duly adjusted by inflation/court index. Upcoming Actions: AFT awaiting for the downpayment from the debtor to fulfill the agreement (Oct 20th 2025).
B30: MOGIANA TECNO AGRO | D30: Fertilizers | E30: 1863200.9 | F30: 0 | G30: =SUM(E30:F30) -> 1863200.9 | I30: 1863200.9 | L30: =I30 -> 1863200.9 | M30: =E30-I30 -> 0 | P30: Current Status: In Litigation via Collection enforcement claim. AFT received a proposal agreement, consisting of 12 initial installments of R$ 50,000.00, beginning March 28, which we had previously agreed after trying to negotiate a higher amount. From the 13th month, the proposal would be to rise monthly installments to R$ 100,000.00. This payment agreement would include both principal (R$ 2,502,567.34) and Interest (R$ 204,693.57). We have, via the enforcement collection claim received BRL 29k from the clients account via judicial decison. Upcoming Actions: we´ve not received feedback and are still assessing the viability of an agreed payment plan proposal. AFT is continuing to follow up on a payment schedule definition. AFT continues to follow on enforcement of any assets available from the client.
B31: CASA DAS SEMENTES | D31: Fertilizers | E31: 1702848.7 | F31: 0 | G31: =SUM(E31:F31) -> 1702848.7 | I31: 1702848.7 | L31: =I31 -> 1702848.7 | M31: =E31-I31 -> 0 | P31: Current Status: In Litigation via Collection enforcement claim. The process is ongoing, and we have successfully notified the debtor via judicial court. Upcoming Actions: AFT is seeking to seize assets from the debtor via the judicial claim which is ongoing.
B32: CBM FERTILIZANTES | D32: Fertilizers | E32: 876011.75 | F32: 0 | G32: =SUM(E32:F32) -> 876011.75 | I32: 0 | L32: =I32 -> 0 | M32: =E32-I32 -> 876011.75 | P32: Judicial settlement has been signed, under the following terms: (i) Total settlement amount: R$ 1,179,964.76, to be paid under the following conditions; (ii) Agreed payment in Two installments of R$ 100,000.00 each, due on April 24, 2025, and September 30th, 2025; Client has paid BRL 100k of the 1st installment and 2nd to be paid on the 30th of Sept. (iii) Three annual installments of R$ 326,654.92 , due on September 30, 2026, September 30, 2027, and September 30, 2028; Upcoming Actions: AFT awaiting for the payment plan agreed ofr September (another BRL 100k payment).
B33: GRUPO TRIANGULO AGRO | D33: Fertilizers | E33: 237309.12 | F33: 0 | G33: =SUM(E33:F33) -> 237309.12 | I33: 237309.12 | L33: =I33 -> 237309.12 | M33: =E33-I33 -> 0 | P33: Current Status: Client has issue a Judicial Recovery claim. The judicial process is still in the initial phase, and AFT has been notified. Upcoming Actions: AFT awaiting for the next steps to be set by court.
B34: TERRA FERTILIZANTES LTDA - ARAXÁ | D34: Additives | E34: 226233.6 | F34: 0 | G34: =SUM(E34:F34) -> 226233.6 | I34: 226233.6 | L34: =I34 -> 226233.6 | M34: =E34-I34 -> 0 | P34: May - 2024. In Litigation via collection enforcement. We don´t expect to have the collection. Client has been operation with a different Tax Id and we´re investigating how to link both companies to this claim.
B35: FAZENDA ARCOS SÃO JOÃO | D35: Fertilizers | E35: 988506.24 | F35: 0 | G35: =SUM(E35:F35) -> 988506.24 | I35: 539667.84 | L35: =I35 -> 539667.84 | M35: =E35-I35 -> 448838.4 | P35: Aug- 2025 Payment plan negotiation ongoing.
B36: ITERUM - RONDONOPOLIS | D36: Additives | E36: 213750 | F36: 0 | G36: =SUM(E36:F36) -> 213750 | I36: 213750 | L36: =I36 -> 213750 | M36: =E36-I36 -> 0 | P36: Dec- 2024 - Client facing fanancial difficulties and offered to return non-used final products. AFT is validating samples collected for quality assurance.
B37: GLINFERTIL - SAO FRANCISCO DO SUL | D37: Additives | E37: 20940 | F37: 0 | G37: =SUM(E37:F37) -> 20940 | I37: 20940 | L37: =I37 -> 20940 | M37: =E37-I37 -> 0 | P37: Nov 2023 Overdue. We don´t expect to receive collection from this client. The current status is that the client awaits for a court decision to accept the Judicial recovery process.
B39: Total Over Due in Litigation (TOP 12) | E39: =SUM(E26:E37) -> 22315752 | F39: =SUM(F26:F37) -> 0 | G39: =SUM(G26:G37) -> 22315752 | I39: =SUM(I26:I37) -> 10937332 | J39: =SUM(J26:J37) -> 0 | L39: =SUM(L26:L37) -> 10937332 | M39: =SUM(M26:M37) -> 11378420 | N39: =SUM(N26:N37) -> 0
B40: KLEYTON DUARTE SOARES | D40: Additives | E40: 100 | F40: 0 | G40: =SUM(E40:F40) -> 100 | I40: 100 | L40: =I40 -> 100 | M40: =E40-L40 -> 0 | P40: Jul - 2024 - Sale of old fixed assets to employees (chairs, desks etc) and it was not duly debited in employees payroll. Employee has left the company.
B41: MARIA JOSE DA SILVA | D41: Additives | E41: 50 | F41: 0 | G41: =SUM(E41:F41) -> 50 | I41: 50 | L41: =I41 -> 50 | M41: =E41-L41 -> 0 | P41: Aug - 2024 - Sale of old fixed assets to employees (chairs, desks etc) and it was not duly debited in employees payroll. Employee has left the company.
B42: GRUPO YARA | D42: Additives | E42: 5626.32 | F42: 0 | G42: =SUM(E42:F42) -> 5626.32 | I42: 5626.32 | L42: =I42 -> 5626.32 | M42: =E42-L42 -> 0 | P42: June 2024 - invoice underpayment due client claim of weight divergence
B43: SEU LIXO | D43: Additives | E43: 300 | F43: 0 | G43: =SUM(E43:F43) -> 300 | I43: 300 | L43: =I43 -> 300 | M43: =E43-L43 -> 0 | P43: Nov 2024 - sale of scrap materials.
B45: Total Over Due with Probable Loss | E45: =SUM(E40:E44) -> 6076.32 | F45: =SUM(F40:F44) -> 0 | G45: =SUM(G40:G44) -> 6076.32 | I45: =SUM(I40:I44) -> 6076.32 | J45: =SUM(J40:J44) -> 0 | L45: =SUM(L40:L44) -> 6076.32 | M45: =SUM(M40:M44) -> 0 | N45: =SUM(N40:N44) -> 0
B46: Low Risk - Expect to Receive soon | E46: =SUM(E47:E56) -> 1226006.5 | F46: =F57+F58+F59 -> 0 | G46: =SUM(G47:G56) -> 1226006.5 | I46: =SUM(I47:I56) -> 177601.27 | J46: =SUM(J47:J56) -> 0 | L46: =SUM(L47:L56) -> 0 | M46: =SUM(M47:M56) -> 0 | N46: =SUM(N47:N56) -> 1226006.5 | P46: Provision as per corporate policy
B47: AGROBROKERS - COLÔMBIA | D47: Additive Intl. | E47: 449507.69 | G47: 449507.69 | I47: 13485.231 | N47: =E47 -> 449507.69 | P47: Cargo cleared at Colombia port customs. AFT is in contact with the customer for validation of the payment plan.
B48: FERTIBAL - EQUADOR | D48: Additive Intl. | E48: 14548.35 | G48: =SUM(E48:F48) -> 14548.35 | I48: 436.4505 | N48: =E48 -> 14548.35 | P48: Jan - 2026 The client paid 50% of the amount in January 2026; the remainder will be paid in March.
...

Sheet AR - slide
B1: in BRl
B2: Receivables as on 31st March 25 | D2: BU | E2: Overdue | F2: Not Due | G2: Provision | I2: Risk Provisions | M2: Remark
I3: Probable | J3: Possible | K3: Rare
B4: Central do Adubo | D4: Fertilizer | E4: 7560727.8 | G4: 3780363.9 | I4: 3780363.9 | J4: 3780363.9 | M4: Creditor´s assembly has been schedulled for May 2025. Central has reached out to Adfert for preferred suppliers status and conditions are in negotiation along April early May to be presented in the Assembly.
B5: SM Agro / Fazenda Baturi | D5: Fertilizer | E5: 3088531.1 | F5: 0 | G5: 3088531.1 | I5: 3088531.1 | M5: Judicial collection lawsuit is ongoing.
B6: CBM Fertilizantes | D6: Fertilizer | E6: 1076345 | F6: 0 | G6: 1076345 | I6: 1076345 | M6: Payment plan in negotiation: 10% payment in 2025 + 3 bullet yearly payments for the remaining debt.
B7: Mogiana Tecno Agro | D7: Fertilizer | E7: 1892360 | F7: 0 | G7: 0 | I7: 0 | J7: 1892360 | M7: AFT received a renewalled payment proposal. Monthly payments along 2 yrs, with Machineary as guarantee and worth 25% of Open Exposure. Formal proposal still pending full disclosre on documents and valuation on Machinery.
B8: Casa das Sementes | D8: Fertilizer | E8: 1716645.3 | G8: 1716645.3 | I8: 1716645.3 | M8: Legal process ongoing and 100% of the invoices we provisioned.
B9: Terra Fértil | D9: Fertilizer | E9: 2971789.9 | G9: 89153.697 | J9: 2971789.9 | M9: AFT has reached a payment agreement: 15% paid by Oct 25 and 3 yearly installments (Oct 26-27-28). No discount on principal and price inflation indexed
B10: Agro Beraldo | D10: Fertilizer | E10: 3044850.9 | F10: 0 | G10: 91345.528 | J10: 3044850.9 | M10: Judicial collection lawsuit is ongoing.
B12: Total Over Due in Litigation (TOP 7) | E12: =SUM(E4:E10) -> 21351250 | F12: =SUM(F4:F10) -> 0 | G12: =SUM(G4:G10) -> 9842384.5 | I12: =SUM(I4:I10) -> 9661885.3 | J12: =SUM(J4:J10) -> 11689365 | K12: =SUM(K4:K10) -> 0
B13: Planta Rica Agronegócios Ltda | D13: Fertilizers | E13: 110528 | F13: 0 | G13: 110528 | I13: 110528 | M13: old overdue
B14: Equilíbrio - Mogi Mirim | D14: Fertilizers | E14: 22222.25 | F14: 0 | G14: 22222.25 | I14: 22222.25 | M14: old overdue due to Quality issues
B15: Terra Fertilizantes Ltda | D15: Additives | E15: 226233.6 | F15: 0 | G15: 6787.008 | I15: 226233.6 | M15: Judicial recovery started
B16: Plant Bem - Paranagua | D16: Additives | E16: 140872.6 | F16: 0 | G16: 140872.6 | I16: 140872.6 | M16: old overdue
B17: Fertisanta Fertilizantes | D17: Additives | E17: 41379 | F17: 0 | G17: 41379 | I17: 41379 | M17: old overdue
B18: GLINFERTIL - SAO FRANCISCO DO SUL | D18: Additives | E18: 20940 | G18: 20940 | I18: 20940
B19: Superbac | D19: Additives | E19: 102008.2 | G19: 3060.25 | I19: 102008.2 | M19: No agreenment on payment. Judicial recovery process to begin
B20: Delcorp S.A | D20: Additives | E20: 84291.45 | F20: 0 | G20: 84291.45 | I20: 84291.45 | M20: old overdue
B21: Total Over Due with Possible Loss | E21: =SUM(E13:E20) -> 748475.1 | F21: =SUM(F13:F20) -> 0 | G21: =SUM(G13:G20) -> 430080.56 | I21: =SUM(I13:I20) -> 748475.1 | J21: =SUM(J13:J20) -> 0 | K21: =SUM(K13:K20) -> 0
B22: Low Risk - Expect to Receive soon | E22: =SUM(E23:E43) -> 7425775.8 | F22: =F44+F45+F46 -> 35847180 | G22: =SUM(G23:G43) -> 526944.99 | M22: Provision as per corporate policy
B23: Grupo Fert Tocantins | D23: Additives | E23: =1991399-67239 -> 1924160 | G23: 67314 | K23: =E23 -> 1924160 | M23: Overdue received in the beginning of March
B24: GRUPO MOSAIC FERTILIZANTES DO BRASIL | D24: Additives | E24: =765704.79-80843.12 -> 684861.67 | G24: 66674.04 | K24: =E24 -> 684861.67
B25: ITERUM - RONDONOPOLIS | D25: Additives | E25: 213750 | G25: 1475.1
B26: GRUPO AMAGGI | D26: Additives | E26: 56400
B27: GRUPO HERINGER | D27: Additives | E27: 397800
B28: GRUPO MOSAIC FERTILIZANTES P K LTDA | D28: Additives | E28: =123685.2-16500 -> 107185.2
B29: GRUPO CIBRA | D29: Additives | E29: =414240-1200 -> 413040
B30: GRUPO YARA | D30: Additives | E30: =63226.32-57600 -> 5626.32
B31: LYCSA Argentina | D31: Int'll | E31: 256935.85 | G31: 256935.85 | J31: 256935.85
B32: FERTYMEND - EQUADOR | D32: Int'll | E32: 69886.47
B33: AGRO MIL AGROS SAS - COLOMBIA | D33: Int'll | E33: 136847.67
B34: FERTIBAL - EQUADOR | D34: Int'll | E34: 82123.57
B35: ASOCIACION DE COOPERATIVAS ARGENTINAS CL | D35: Int'll | E35: 703377.76
B36: TECNOMYL S.A. - PARAGUAY | D36: Int'll | E36: 201503.56
B37: ABOPAR - PARAGUAY | D37: Int'll | E37: 150938.02
B38: C I ACEPALMA SA - COLOMBIA | D38: Int'll | E38: 317041.26 | K38: =E38 -> 317041.26
B39: Indorama Senegal | D39: Int'll | E39: 381748.49 | G39: 0 | K39: =E39 -> 381748.49
B40: GRUPO TRIANGULO AGRO | D40: Fertilizers | E40: 237309.12 | G40: 0 | K40: 117330.4
B41: GRUPO R3 | D41: Fertilizers | E41: 659074 | G41: 0 | J41: 659074
...

Sheet AR
J3: Credit Analysis | N3: Guarantee | S3: Remark
C4: CUSTOMER | D4: BU | E4: Total AR | F4: Overdue | G4: Not Due | H4: Provision | J4: Value | K4: Type | L4: Period days | N4: Value | O4: Type | P4: Due date | Q4: Tenor
C5: CENTRAL DO ADUBO | D5: Fertilizer | E5: =F5+G5 -> 7560727.8 | F5: ='Painel Fertilizers'!O4 -> 7560727.8 | G5: ='Painel Fertilizers'!P4 -> 0 | H5: ='Painel Fertilizers'!X4 -> 0 | J5: 0 | K5: 0 | L5: 0 | N5: 0 | O5: 0 | P5: 0 | Q5: 0 | S5: Judicial recovery plan presented but yet to be approved by Creditors Asembly: a meeting was held with AFT and a proposal of 65% discount on face value presented with a 18-month grace period and repayment over 10 years (in 20 installments). Adfert has not received further details on the restructuring plan as previously agreed in the end of Oct. Creditors assembly yet to be marked and a vote will occur for the Debtors recovery plan approval. Adfert advisors have a strong believe that the plan as AS-IS will not be approved and new financial conditions will be needed by the debtors
C6: SM AGRO / FAZ. BATURI | D6: Fertilizer | E6: =F6+G6 -> #REF! | F6: ='Painel Fertilizers'!#REF! -> #REF! | G6: ='Painel Fertilizers'!#REF! -> #REF! | H6: ='Painel Fertilizers'!#REF! -> #REF! | J6: 300000 | K6: Clean | L6: 0 | N6: 740000 | O6: CPR | P6: 45566 | Q6: 10 months | S6: Client has phisycally closed its reseller shop. Current overdue invoices were dully protested at the registry office and legal action has been filed. Awaiting court´s decision ordering the defendants to be served for payment
C7: CBM FERTILIZANTES | D7: Fertilizer | E7: =F7+G7 -> 0 | F7: ='Painel Fertilizers'!O20 -> 0 | G7: 0 | H7: 0 | N7: 4000000 | O7: CPR-G | P7: 45505 | Q7: 1 year | S7: Adfert has taken legal action and collection recovery lawsuit to be filed within November. An agreement for a payment plan was not successfull
C8: MOGIANA TECNO AGRO | D8: Fertilizer | E8: =F8+G8 -> 2026078 | F8: 1892360 | G8: ='Painel Fertilizers'!P20 -> 133718 | H8: ='Painel Fertilizers'!X5 -> 3088531.1 | J8: 1000000 | K8: Surety Bond | L8: 360 | N8: 1892360 | O8: Surety Bond | P8: 45597 | Q8: 1 year | S8: The judicial collection lawsuit plan was signed and filed. Court decision has approved the settement agreement establishing a 24 months payment plan (montlhy payment). 1st installment not paid and the judicial collection is ongoing
C9: CASA DAS SEMENTES | D9: Fertilizer | E9: =F9+G9 -> 3044850.9 | F9: ='Painel Fertilizers'!O6 -> 3044850.9 | G9: ='Painel Fertilizers'!P6 -> 0 | H9: ='Painel Fertilizers'!X6 -> 3044850.9 | J9: 2000000 | K9: Surety Bond | L9: 120 | S9: Provision 100%. Client’s overdues were protested at the registry office. Legal process ongoing
C10: TERRA FERTIL - MACHADO | D10: Fertilizer | E10: =F10+G10 -> 876011.75 | F10: ='Painel Fertilizers'!O10 -> 876011.75 | G10: ='Painel Fertilizers'!P10 -> 0 | H10: ='Painel Fertilizers'!X10 -> 0 | N10: 5517407.7 | O10: Surety Bond | P10: 45606 | Q10: 1 year | S10: Guarantee sent to the legal department so that they begin legal proceedings to collect the amount due
C11: AGROBERALDO | D11: Fertilizer | E11: =F11+G11 -> 0 | F11: ='Painel Fertilizers'!O22 -> 0 | G11: ='Painel Fertilizers'!P22 -> 0 | H11: ='Painel Fertilizers'!X22 -> 0 | N11: 3000000 | O11: Surety Bond | P11: 45627 | Q11: 1 year | S11: Guarantee sent to the legal department so that they begin legal proceedings to collect the amount due
C12: Total Over Due in Litigation | E12: =SUM(E5:E11) -> #REF! | F12: =SUM(F5:F11) -> #REF! | G12: =SUM(G5:G11) -> #REF! | H12: =SUM(H5:H11) -> #REF!
C13: PLANTA RICA AGRONEGÓCIOS LTDA | D13: Fertilizers | E13: =F13+G13 -> 110528 | F13: 110528 | G13: 0 | H13: 110528 | S13: old overdue
C14: FAZENDA BRAVINHOS | D14: Fertilizers | E14: =F14+G14 -> 34132.18 | F14: 34132.18 | G14: 0 | H14: 1023.9654 | S14: Judicial recovery started
C15: EQUILIBRIO - MOGI MIRIM | D15: Fertilizers | E15: =F15+G15 -> 22222.25 | F15: 22222.25 | G15: 0 | H15: 22222.25 | S15: old overdue
C16: TERRA FERTILIZANTES LTDA | D16: Aditives | E16: =F16+G16 -> 226233.6 | F16: 226233.6 | G16: 0 | H16: ='Painel Additive'!X6 -> 63226.32 | S16: Judicial recovery started
C17: PLANT BEM - PARANAGUÁ | D17: Aditives | E17: =F17+G17 -> 140872.6 | F17: 140872.6 | G17: 0 | H17: 140872.6 | S17: old overdue
C18: FERTISANTA FERTILIZANTES | D18: Aditives | E18: =F18+G18 -> 41379 | F18: 41379 | G18: 0 | H18: 41379 | S18: old overdue
C19: DELCORP S.A | D19: Aditives | E19: =F19+G19 -> 84291.45 | F19: 84291.45 | G19: 0 | H19: 84291.45 | S19: old overdue
C20: Total Over Due with Possible Loss | E20: =SUM(E13:E19) -> 659659.08 | F20: =SUM(F13:F19) -> 659659.08 | G20: =SUM(G13:G19) -> 0 | H20: =SUM(H13:H19) -> 463543.59
C21: Low Risk - Expect to Receive soon | E21: =F21+G21 -> #REF! | F21: =-(F20+F12)+'Painel Additive'!O1+'Painel Fertilizers'!O1+'Painel International'!O1 -> #REF! | G21: 0 | H21: ='Bad Debt Provision'!#REF! - (H12+H20) -> #REF! | S21: Provision as per corporate policy
C22: Not Due | E22: =F22+G22 -> 34736830 | F22: 0 | G22: ='Painel Additive'!P1+'Painel Fertilizers'!P1+'Painel International'!P1 -> 34736830 | H22: 0
C23: Total | E23: =SUM(E20:E22)+E12 -> #REF! | F23: =SUM(F20:F22)+F12 -> #REF! | G23: =SUM(G20:G22)+G12 -> #REF! | H23: =SUM(H20:H22)+H12 -> #REF!

Sheet Data total
D1: =SUBTOTAL(9,D3:D1086) -> 59548326 | E1: ='Data Additive'!D1+'Data Fertilizers'!D1+'Data International'!D1 -> 59371743 | F1: ='Data Additive'!D1+'Data Fertilizers'!D1+'Data International'!D1+'freight debit notes'!D1 -> 59548326 | G1: =D1-F1 -> 0 | R1: 46141
A2: CODPARC | B2: NOMEPARC | C2: CNPJ | D2: Valor | E2: NUFIN | F2: DTVENC | G2: DHBAIXA | H2: AD_BU | I2: NOME_BU | J2: NUMNOTA | K2: DTENTSAI | L2: CODNAT | M2: DESCRNAT | N2: CODTIPOPER | O2: OPERACAO | P2: Grupo | Q2: Dias vencidos
A3: 205 | B3: FERTIPAR - RONDONÓPOLIS | C3: 09.384.948/0002-43 | D3: 80589.6 | E3: 1246271690 | F3: 46157 | H3: 1 | I3: Adtives | J3: 11158 | K3: 46129 | L3: 1010100 | M3: VENDAS MERCADO INTERNO | N3: 161 | O3: VENDA PROD. INDUSTRIALIZADO - NFE | P3: GRUPO FERTIPAR FERTILIZANTES MATO GROSSO | Q3: =$R$1-F3 -> -16 | R3: =_xlfn.XLOOKUP(E3,'Data Additive'!E:E,'Data Additive'!E:E,0) -> 1246271690
A4: 205 | B4: FERTIPAR - RONDONÓPOLIS | C4: 09.384.948/0002-43 | D4: 81051.4 | E4: 1246273002 | F4: 46168 | H4: 1 | I4: Adtives | J4: 11248 | K4: 46140 | L4: 1010100 | M4: VENDAS MERCADO INTERNO | N4: 161 | O4: VENDA PROD. INDUSTRIALIZADO - NFE | P4: GRUPO FERTIPAR FERTILIZANTES MATO GROSSO | Q4: =$R$1-F4 -> -27 | R4: =_xlfn.XLOOKUP(E4,'Data Additive'!E:E,'Data Additive'!E:E,0) -> 1246273002
A5: 1257 | B5: MOSAIC - CAMPO GRANDE | C5: 61.156.501/0081-30 | D5: 1980.8 | E5: 1246032946 | F5: 44774 | H5: 1 | I5: Adtives | J5: 17935 | K5: 44714 | L5: 1010100 | M5: VENDAS MERCADO INTERNO | N5: 56 | O5: VENDA A ORDEM | P5: GRUPO MOSAIC FERTILIZANTES DO BRASIL | Q5: =$R$1-F5 -> 1367 | R5: =_xlfn.XLOOKUP(E5,'Data Additive'!E:E,'Data Additive'!E:E,0) -> 1246032946
A6: 1953 | B6: AMAGGI - COMODORO | C6: 77.294.254/0075-20 | D6: 58917.8 | E6: 1246267986 | F6: 46158 | H6: 1 | I6: Adtives | J6: 10907 | K6: 46098 | L6: 1010100 | M6: VENDAS MERCADO INTERNO | N6: 161 | O6: VENDA PROD. INDUSTRIALIZADO - NFE | P6: GRUPO AMAGGI | Q6: =$R$1-F6 -> -17 | R6: =_xlfn.XLOOKUP(E6,'Data Additive'!E:E,'Data Additive'!E:E,0) -> 1246267986
A7: 1787 | B7: MOSAIC - UBERABA (CIU1) | C7: 33.931.486/0014-55 | D7: 107059.2 | E7: 1246262114 | F7: 46146 | G7: 46146 | H7: 1 | I7: Adtives | J7: 10629 | K7: 46056 | L7: 1010100 | M7: VENDAS MERCADO INTERNO | N7: 161 | O7: VENDA PROD. INDUSTRIALIZADO - NFE | P7: GRUPO MOSAIC FERTILIZANTES P K LTDA | Q7: =$R$1-F7 -> -5 | R7: =_xlfn.XLOOKUP(E7,'Data Additive'!E:E,'Data Additive'!E:E,0) -> 1246262114
A8: 1787 | B8: MOSAIC - UBERABA (CIU1) | C8: 33.931.486/0014-55 | D8: 3600 | E8: 1246031589 | F8: 44784 | H8: 1 | I8: Adtives | J8: 1246031589 | K8: 44769 | L8: 3041000 | M8: FRETES DIVERSOS | N8: 46 | O8: FINANCEIRO GERAL | P8: GRUPO MOSAIC FERTILIZANTES P K LTDA | Q8: =$R$1-F8 -> 1357 | R8: =_xlfn.XLOOKUP(E8,'Data Additive'!E:E,'Data Additive'!E:E,0) -> 0
A9: 1787 | B9: MOSAIC - UBERABA (CIU1) | C9: 33.931.486/0014-55 | D9: 2700 | E9: 1246055596 | F9: 44889 | H9: 1 | I9: Adtives | J9: 1246055596 | K9: 44889 | L9: 3041000 | M9: FRETES DIVERSOS | N9: 46 | O9: FINANCEIRO GERAL | P9: GRUPO MOSAIC FERTILIZANTES P K LTDA | Q9: =$R$1-F9 -> 1252 | R9: =_xlfn.XLOOKUP(E9,'Data Additive'!E:E,'Data Additive'!E:E,0) -> 0
A10: 1787 | B10: MOSAIC - UBERABA (CIU1) | C10: 33.931.486/0014-55 | D10: 109862.4 | E10: 1246271310 | F10: 46216 | H10: 1 | I10: Adtives | J10: 11116 | K10: 46126 | L10: 1010100 | M10: VENDAS MERCADO INTERNO | N10: 161 | O10: VENDA PROD. INDUSTRIALIZADO - NFE | P10: GRUPO MOSAIC FERTILIZANTES P K LTDA | Q10: =$R$1-F10 -> -75 | R10: =_xlfn.XLOOKUP(E10,'Data Additive'!E:E,'Data Additive'!E:E,0) -> 1246271310
A11: 1787 | B11: MOSAIC - UBERABA (CIU1) | C11: 33.931.486/0014-55 | D11: 116928 | E11: 1246267948 | F11: 46187 | H11: 1 | I11: Adtives | J11: 10899 | K11: 46097 | L11: 1010100 | M11: VENDAS MERCADO INTERNO | N11: 161 | O11: VENDA PROD. INDUSTRIALIZADO - NFE | P11: GRUPO MOSAIC FERTILIZANTES P K LTDA | Q11: =$R$1-F11 -> -46 | R11: =_xlfn.XLOOKUP(E11,'Data Additive'!E:E,'Data Additive'!E:E,0) -> 1246267948
A12: 1787 | B12: MOSAIC - UBERABA (CIU1) | C12: 33.931.486/0014-55 | D12: 115891.2 | E12: 1246262540 | F12: 46149 | H12: 1 | I12: Adtives | J12: 10652 | K12: 46059 | L12: 1010100 | M12: VENDAS MERCADO INTERNO | N12: 161 | O12: VENDA PROD. INDUSTRIALIZADO - NFE | P12: GRUPO MOSAIC FERTILIZANTES P K LTDA | Q12: =$R$1-F12 -> -8 | R12: =_xlfn.XLOOKUP(E12,'Data Additive'!E:E,'Data Additive'!E:E,0) -> 1246262540
A13: 1787 | B13: MOSAIC - UBERABA (CIU1) | C13: 33.931.486/0014-55 | D13: 103795.2 | E13: 1246268633 | F13: 46194 | H13: 1 | I13: Adtives | J13: 10957 | K13: 46104 | L13: 1010100 | M13: VENDAS MERCADO INTERNO | N13: 161 | O13: VENDA PROD. INDUSTRIALIZADO - NFE | P13: GRUPO MOSAIC FERTILIZANTES P K LTDA | Q13: =$R$1-F13 -> -53 | R13: =_xlfn.XLOOKUP(E13,'Data Additive'!E:E,'Data Additive'!E:E,0) -> 1246268633
A14: 1787 | B14: MOSAIC - UBERABA (CIU1) | C14: 33.931.486/0014-55 | D14: 111360 | E14: 1246268748 | F14: 46195 | H14: 1 | I14: Adtives | J14: 10965 | K14: 46105 | L14: 1010100 | M14: VENDAS MERCADO INTERNO | N14: 161 | O14: VENDA PROD. INDUSTRIALIZADO - NFE | P14: GRUPO MOSAIC FERTILIZANTES P K LTDA | Q14: =$R$1-F14 -> -54 | R14: =_xlfn.XLOOKUP(E14,'Data Additive'!E:E,'Data Additive'!E:E,0) -> 1246268748
A15: 1787 | B15: MOSAIC - UBERABA (CIU1) | C15: 33.931.486/0014-55 | D15: 114662.4 | E15: 1246268585 | F15: 46161 | H15: 1 | I15: Adtives | J15: 10953 | K15: 46101 | L15: 1010100 | M15: VENDAS MERCADO INTERNO | N15: 161 | O15: VENDA PROD. INDUSTRIALIZADO - NFE | P15: GRUPO MOSAIC FERTILIZANTES P K LTDA | Q15: =$R$1-F15 -> -20 | R15: =_xlfn.XLOOKUP(E15,'Data Additive'!E:E,'Data Additive'!E:E,0) -> 1246268585
A16: 1787 | B16: MOSAIC - UBERABA (CIU1) | C16: 33.931.486/0014-55 | D16: 115852.8 | E16: 1246270635 | F16: 46210 | H16: 1 | I16: Adtives | J16: 11072 | K16: 46120 | L16: 1010100 | M16: VENDAS MERCADO INTERNO | N16: 161 | O16: VENDA PROD. INDUSTRIALIZADO - NFE | P16: GRUPO MOSAIC FERTILIZANTES P K LTDA | Q16: =$R$1-F16 -> -69 | R16: =_xlfn.XLOOKUP(E16,'Data Additive'!E:E,'Data Additive'!E:E,0) -> 1246270635
A17: 1787 | B17: MOSAIC - UBERABA (CIU1) | C17: 33.931.486/0014-55 | D17: 114739.2 | E17: 1246271165 | F17: 46215 | H17: 1 | I17: Adtives | J17: 11105 | K17: 46125 | L17: 1010100 | M17: VENDAS MERCADO INTERNO | N17: 161 | O17: VENDA PROD. INDUSTRIALIZADO - NFE | P17: GRUPO MOSAIC FERTILIZANTES P K LTDA | Q17: =$R$1-F17 -> -74 | R17: =_xlfn.XLOOKUP(E17,'Data Additive'!E:E,'Data Additive'!E:E,0) -> 1246271165
A18: 1787 | B18: MOSAIC - UBERABA (CIU1) | C18: 33.931.486/0014-55 | D18: 114969.6 | E18: 1246264543 | F18: 46166 | H18: 1 | I18: Adtives | J18: 10746 | K18: 46076 | L18: 1010100 | M18: VENDAS MERCADO INTERNO | N18: 161 | O18: VENDA PROD. INDUSTRIALIZADO - NFE | P18: GRUPO MOSAIC FERTILIZANTES P K LTDA | Q18: =$R$1-F18 -> -25 | R18: =_xlfn.XLOOKUP(E18,'Data Additive'!E:E,'Data Additive'!E:E,0) -> 1246264543
A19: 1787 | B19: MOSAIC - UBERABA (CIU1) | C19: 33.931.486/0014-55 | D19: 113356.8 | E19: 1246269731 | F19: 46202 | H19: 1 | I19: Adtives | J19: 11014 | K19: 46112 | L19: 1010100 | M19: VENDAS MERCADO INTERNO | N19: 161 | O19: VENDA PROD. INDUSTRIALIZADO - NFE | P19: GRUPO MOSAIC FERTILIZANTES P K LTDA | Q19: =$R$1-F19 -> -61 | R19: =_xlfn.XLOOKUP(E19,'Data Additive'!E:E,'Data Additive'!E:E,0) -> 1246269731
... A76: 33 | B76: HERINGER - PARANAGUÁ | C76: 22.266.175/0031-01 | D76: 99167.6 | E76: 1246271248 | F76: 46155 | H76: 1 | I76: Adtives | J76: 11114 | K76: 46125 | L76: 1010100 | M76: VENDAS MERCADO INTERNO | N76: 161 | O76: VENDA PROD. INDUSTRIALIZADO - NFE | P76: GRUPO HERINGER | Q76: =$R$1-F76 -> -14 | R76: =_xlfn.XLOOKUP(E76,'Data Additive'!E:E,'Data Additive'!E:E,0) -> 1246271248
A77: 214 | B77: UNIFERTIL - CANOAS UN1 | C77: 87.249.561/0001-07 | D77: 82931.8 | E77: 1246270505 | F77: 46147 | G77: 46147 | H77: 1 | I77: Adtives | J77: 11065 | K77: 46119 | L77: 1010100 | M77: VENDAS MERCADO INTERNO | N77: 161 | O77: VENDA PROD. INDUSTRIALIZADO - NFE | P77: GRUPO UNIFERTIL | Q77: =$R$1-F77 -> -6 | R77: =_xlfn.XLOOKUP(E77,'Data Additive'!E:E,'Data Additive'!E:E,0) -> 1246270505
A78: 214 | B78: UNIFERTIL - CANOAS UN1 | C78: 87.249.561/0001-07 | D78: 82854.1 | E78: 1246272851 | F78: 46167 | H78: 1 | I78: Adtives | J78: 11237 | K78: 46139 | L78: 1010100 | M78: VENDAS MERCADO INTERNO | N78: 161 | O78: VENDA PROD. INDUSTRIALIZADO - NFE | P78: GRUPO UNIFERTIL | Q78: =$R$1-F78 -> -26 | R78: =_xlfn.XLOOKUP(E78,'Data Additive'!E:E,'Data Additive'!E:E,0) -> 1246272851
A79: 214 | B79: UNIFERTIL - CANOAS UN1 | C79: 87.249.561/0001-07 | D79: 99281.7 | E79: 1246271672 | F79: 46157 | H79: 1 | I79: Adtives | J79: 11156 | K79: 46129 | L79: 1010100 | M79: VENDAS MERCADO INTERNO | N79: 161 | O79: VENDA PROD. INDUSTRIALIZADO - NFE | P79: GRUPO UNIFERTIL | Q79: =$R$1-F79 -> -16 | R79: =_xlfn.XLOOKUP(E79,'Data Additive'!E:E,'Data Additive'!E:E,0) -> 1246271672
A80: 2 | B80: CARGILL - UBERLÂNDIA | C80: 60.498.706/0134-88 | D80: 13431 | E80: 1246272905 | F80: 46168 | G80: 46146 | H80: 3 | I80: Job Work | J80: 2898 | K80: 46140 | L80: 1010100 | M80: VENDAS MERCADO INTERNO | N80: 199 | O80: VENDA MERC INDUSTRIALIZADA TERCEIROS | P80: GRUPO CARGILL | Q80: =$R$1-F80 -> -27 | R80: =_xlfn.XLOOKUP(E80,'Data Additive'!E:E,'Data Additive'!E:E,0) -> 1246272905
A81: 183 | B81: HERINGER - RONDONÓPOLIS II | C81: 22.266.175/0036-08 | D81: 4231.96 | E81: 1246014155 | F81: 47847 | H81: 1 | I81: Adtives | J81: 8361 | K81: 43384 | L81: 1010100 | M81: VENDAS MERCADO INTERNO | N81: 161 | O81: VENDA PROD. INDUSTRIALIZADO - NFE | P81: GRUPO HERINGER | Q81: =$R$1-F81 -> -1706 | R81: =_xlfn.XLOOKUP(E81,'Data Additive'!E:E,'Data Additive'!E:E,0) -> 1246014155
A82: 183 | B82: HERINGER - RONDONÓPOLIS II | C82: 22.266.175/0036-08 | D82: 4045.01 | E82: 1246014156 | F82: 48212 | H82: 1 | I82: Adtives | J82: 8361 | K82: 43384 | L82: 1010100 | M82: VENDAS MERCADO INTERNO | N82: 161 | O82: VENDA PROD. INDUSTRIALIZADO - NFE | P82: GRUPO HERINGER | Q82: =$R$1-F82 -> -2071 | R82: =_xlfn.XLOOKUP(E82,'Data Additive'!E:E,'Data Additive'!E:E,0) -> 1246014156
A83: 183 | B83: HERINGER - RONDONÓPOLIS II | C83: 22.266.175/0036-08 | D83: 4339.6 | E83: 1246014157 | F83: 48578 | H83: 1 | I83: Adtives | J83: 8361 | K83: 43384 | L83: 1010100 | M83: VENDAS MERCADO INTERNO | N83: 161 | O83: VENDA PROD. INDUSTRIALIZADO - NFE | P83: GRUPO HERINGER | Q83: =$R$1-F83 -> -2437 | R83: =_xlfn.XLOOKUP(E83,'Data Additive'!E:E,'Data Additive'!E:E,0) -> 1246014157
A84: 183 | B84: HERINGER - RONDONÓPOLIS II | C84: 22.266.175/0036-08 | D84: 7512.16 | E84: 1246014158 | F84: 48943 | H84: 1 | I84: Adtives | J84: 8361 | K84: 43384 | L84: 1010100 | M84: VENDAS MERCADO INTERNO | N84: 161 | O84: VENDA PROD. INDUSTRIALIZADO - NFE | P84: GRUPO HERINGER | Q84: =$R$1-F84 -> -2802 | R84: =_xlfn.XLOOKUP(E84,'Data Additive'!E:E,'Data Additive'!E:E,0) -> 1246014158
A85: 183 | B85: HERINGER - RONDONÓPOLIS II | C85: 22.266.175/0036-08 | D85: 30552.86 | E85: 1246014159 | F85: 49308 | H85: 1 | I85: Adtives | J85: 8361 | K85: 43384 | L85: 1010100 | M85: VENDAS MERCADO INTERNO | N85: 161 | O85: VENDA PROD. INDUSTRIALIZADO - NFE | P85: GRUPO HERINGER | Q85: =$R$1-F85 -> -3167 | R85: =_xlfn.XLOOKUP(E85,'Data Additive'!E:E,'Data Additive'!E:E,0) -> 1246014159
A86: 183 | B86: HERINGER - RONDONÓPOLIS II | C86: 22.266.175/0036-08 | D86: 1512.63 | E86: 1246014161 | F86: 50039 | H86: 1 | I86: Adtives | J86: 8361 | K86: 43384 | L86: 1010100 | M86: VENDAS MERCADO INTERNO | N86: 161 | O86: VENDA PROD. INDUSTRIALIZADO - NFE | P86: GRUPO HERINGER | Q86: =$R$1-F86 -> -3898 | R86: =_xlfn.XLOOKUP(E86,'Data Additive'!E:E,'Data Additive'!E:E,0) -> 1246014161
A87: 183 | B87: HERINGER - RONDONÓPOLIS II | C87: 22.266.175/0036-08 | D87: 1982.85 | E87: 1246014162 | F87: 50404 | H87: 1 | I87: Adtives | J87: 8361 | K87: 43384 | L87: 1010100 | M87: VENDAS MERCADO INTERNO | N87: 161 | O87: VENDA PROD. INDUSTRIALIZADO - NFE | P87: GRUPO HERINGER | Q87: =$R$1-F87 -> -4263 | R87: =_xlfn.XLOOKUP(E87,'Data Additive'!E:E,'Data Additive'!E:E,0) -> 1246014162
A88: 183 | B88: HERINGER - RONDONÓPOLIS II | C88: 22.266.175/0036-08 | D88: 2549.38 | E88: 1246014163 | F88: 50769 | H88: 1 | I88: Adtives | J88: 8361 | K88: 43384 | L88: 1010100 | M88: VENDAS MERCADO INTERNO | N88: 161 | O88: VENDA PROD. INDUSTRIALIZADO - NFE | P88: GRUPO HERINGER | Q88: =$R$1-F88 -> -4628 | R88: =_xlfn.XLOOKUP(E88,'Data Additive'!E:E,'Data Additive'!E:E,0) -> 1246014163
A89: 183 | B89: HERINGER - RONDONÓPOLIS II | C89: 22.266.175/0036-08 | D89: 5546.31 | E89: 1246014165 | F89: 51500 | H89: 1 | I89: Adtives | J89: 8361 | K89: 43384 | L89: 1010100 | M89: VENDAS MERCADO INTERNO | N89: 161 | O89: VENDA PROD. INDUSTRIALIZADO - NFE | P89: GRUPO HERINGER | Q89: =$R$1-F89 -> -5359 | R89: =_xlfn.XLOOKUP(E89,'Data Additive'!E:E,'Data Additive'!E:E,0) -> 1246014165
A90: 183 | B90: HERINGER - RONDONÓPOLIS II | C90: 22.266.175/0036-08 | D90: 5546.31 | E90: 1246014166 | F90: 51865 | H90: 1 | I90: Adtives | J90: 8361 | K90: 43384 | L90: 1010100 | M90: VENDAS MERCADO INTERNO | N90: 161 | O90: VENDA PROD. INDUSTRIALIZADO - NFE | P90: GRUPO HERINGER | Q90: =$R$1-F90 -> -5724 | R90: =_xlfn.XLOOKUP(E90,'Data Additive'!E:E,'Data Additive'!E:E,0) -> 1246014166
A91: 183 | B91: HERINGER - RONDONÓPOLIS II | C91: 22.266.175/0036-08 | D91: 5546.31 | E91: 1246014167 | F91: 52230 | H91: 1 | I91: Adtives | J91: 8361 | K91: 43384 | L91: 1010100 | M91: VENDAS MERCADO INTERNO | N91: 161 | O91: VENDA PROD. INDUSTRIALIZADO - NFE | P91: GRUPO HERINGER | Q91: =$R$1-F91 -> -6089 | R91: =_xlfn.XLOOKUP(E91,'Data Additive'!E:E,'Data Additive'!E:E,0) -> 1246014167
A92: 183 | B92: HERINGER - RONDONÓPOLIS II | C92: 22.266.175/0036-08 | D92: 5546.31 | E92: 1246014168 | F92: 52595 | H92: 1 | I92: Adtives | J92: 8361 | K92: 43384 | L92: 1010100 | M92: VENDAS MERCADO INTERNO | N92: 161 | O92: VENDA PROD. INDUSTRIALIZADO - NFE | P92: GRUPO HERINGER | Q92: =$R$1-F92 -> -6454 | R92: =_xlfn.XLOOKUP(E92,'Data Additive'!E:E,'Data Additive'!E:E,0) -> 1246014168
... A112: 201 | B112: JOSAPAR - PELOTAS | C112: 87.456.562/0006-37 | D112: 185040 | E112: 1246269671 | F112: 46231 | H112: 1 | I112: Adtives | J112: 2855 | K112: 46111 | L112: 1010100 | M112: VENDAS MERCADO INTERNO | N112: 161 | O112: VENDA PROD. INDUSTRIALIZADO - NFE | P112: GRUPO JOSAPAR | Q112: =$R$1-F112 -> -90 | R112: =_xlfn.XLOOKUP(E112,'Data Additive'!E:E,'Data Additive'!E:E,0) -> 1246269671
A113: 903 | B113: YARA - PONTA GROSSA | C113: 92.660.604/0138-37 | D113: 133334.43 | E113: 1246268951 | F113: 46146 | G113: 46146 | H113: 1 | I113: Adtives | J113: 10971 | K113: 46106 | L113: 1010100 | M113: VENDAS MERCADO INTERNO | N113: 161 | O113: VENDA PROD. INDUSTRIALIZADO - NFE | P113: GRUPO YARA | Q113: =$R$1-F113 -> -5 | R113: =_xlfn.XLOOKUP(E113,'Data Additive'!E:E,'Data Additive'!E:E,0) -> 1246268951
A114: 903 | B114: YARA - PONTA GROSSA | C114: 92.660.604/0138-37 | D114: 135135.03 | E114: 1246272230 | F114: 46175 | H114: 1 | I114: Adtives | J114: 11199 | K114: 46135 | L114: 1010100 | M114: VENDAS MERCADO INTERNO | N114: 161 | O114: VENDA PROD. INDUSTRIALIZADO - NFE | P114: GRUPO YARA | Q114: =$R$1-F114 -> -34 | R114: =_xlfn.XLOOKUP(E114,'Data Additive'!E:E,'Data Additive'!E:E,0) -> 1246272230
A115: 903 | B115: YARA - PONTA GROSSA | C115: 92.660.604/0138-37 | D115: 134594.85 | E115: 1246270087 | F115: 46154 | H115: 1 | I115: Adtives | J115: 11034 | K115: 46114 | L115: 1010100 | M115: VENDAS MERCADO INTERNO | N115: 161 | O115: VENDA PROD. INDUSTRIALIZADO - NFE | P115: GRUPO YARA | Q115: =$R$1-F115 -> -13 | R115: =_xlfn.XLOOKUP(E115,'Data Additive'!E:E,'Data Additive'!E:E,0) -> 1246270087
...

Sheet freight debit notes
D1: =SUBTOTAL(9,D3:D999) -> 176583.12 | Q1: 46141
A2: CODPARC | B2: NOMEPARC | C2: CNPJ | D2: Valor | E2: NUFIN | F2: DTVENC | G2: DHBAIXA | H2: AD_BU | I2: NOME_BU | J2: NUMNOTA | K2: DTENTSAI | L2: CODNAT | M2: DESCRNAT | N2: CODTIPOPER | O2: OPERACAO | P2: Grupo | Q2: Dias vencidos
A3: 1787 | B3: MOSAIC - UBERABA (CIU1) | C3: 33.931.486/0014-55 | D3: 3600 | E3: 1246031589 | F3: 44784 | H3: 1 | I3: Adtives | J3: 1246031589 | K3: 44769 | L3: 3041000 | M3: FRETES DIVERSOS | N3: 46 | O3: FINANCEIRO GERAL | P3: GRUPO MOSAIC FERTILIZANTES P K LTDA | Q3: =$Q$1-F3 -> 1357
A4: 1787 | B4: MOSAIC - UBERABA (CIU1) | C4: 33.931.486/0014-55 | D4: 2700 | E4: 1246055596 | F4: 44889 | H4: 1 | I4: Adtives | J4: 1246055596 | K4: 44889 | L4: 3041000 | M4: FRETES DIVERSOS | N4: 46 | O4: FINANCEIRO GERAL | P4: GRUPO MOSAIC FERTILIZANTES P K LTDA | Q4: =$Q$1-F4 -> 1252
A5: 1788 | B5: MOSAIC - UBERABA (CIU2) | C5: 33.931.486/0021-84 | D5: 5400 | E5: 1246055599 | F5: 44889 | H5: 1 | I5: Adtives | J5: 1246055599 | K5: 44889 | L5: 3041000 | M5: FRETES DIVERSOS | N5: 46 | O5: FINANCEIRO GERAL | P5: GRUPO MOSAIC FERTILIZANTES P K LTDA | Q5: =$Q$1-F5 -> 1252
A6: 1788 | B6: MOSAIC - UBERABA (CIU2) | C6: 33.931.486/0021-84 | D6: 1200 | E6: 1246190701 | F6: 45674 | H6: 1 | I6: Adtives | J6: 1246190701 | K6: 45659 | L6: 3041000 | M6: FRETES DIVERSOS | N6: 46 | O6: FINANCEIRO GERAL | P6: GRUPO MOSAIC FERTILIZANTES P K LTDA | Q6: =$Q$1-F6 -> 467
A7: 1789 | B7: MOSAIC - ARAXA (CMA) | C7: 33.931.486/0019-60 | D7: 2700 | E7: 1246120461 | F7: 45294 | H7: 1 | I7: Adtives | J7: 191223 | K7: 45279 | L7: 3041000 | M7: FRETES DIVERSOS | N7: 46 | O7: FINANCEIRO GERAL | P7: GRUPO MOSAIC FERTILIZANTES P K LTDA | Q7: =$Q$1-F7 -> 847
A8: 1789 | B8: MOSAIC - ARAXA (CMA) | C8: 33.931.486/0019-60 | D8: 900 | E8: 1246146095 | F8: 45428 | H8: 1 | I8: Adtives | J8: 1246120461 | K8: 45428 | L8: 3041000 | M8: FRETES DIVERSOS | N8: 46 | O8: FINANCEIRO GERAL | P8: GRUPO MOSAIC FERTILIZANTES P K LTDA | Q8: =$Q$1-F8 -> 713
A9: 43 | B9: CIBRA - CAMACARI | C9: 00.117.842/0001-28 | D9: 3600 | E9: 1246271938 | F9: 46147 | H9: 1 | I9: Adtives | J9: 1246271938 | K9: 46132 | L9: 3042200 | M9: DIÁRIAS E ESTADIA DE MOTORISTAS | N9: 46 | O9: FINANCEIRO GERAL | P9: GRUPO CIBRA | Q9: =$Q$1-F9 -> -6
A10: 43 | B10: CIBRA - CAMACARI | C10: 00.117.842/0001-28 | D10: 3600 | E10: 1246271937 | F10: 46147 | H10: 1 | I10: Adtives | J10: 1246271937 | K10: 46132 | L10: 3042200 | M10: DIÁRIAS E ESTADIA DE MOTORISTAS | N10: 46 | O10: FINANCEIRO GERAL | P10: GRUPO CIBRA | Q10: =$Q$1-F10 -> -6
A11: 43 | B11: CIBRA - CAMACARI | C11: 00.117.842/0001-28 | D11: 3600 | E11: 1246271931 | F11: 46147 | H11: 1 | I11: Adtives | J11: 1246271931 | K11: 46132 | L11: 3042200 | M11: DIÁRIAS E ESTADIA DE MOTORISTAS | N11: 46 | O11: FINANCEIRO GERAL | P11: GRUPO CIBRA | Q11: =$Q$1-F11 -> -6
A12: 43 | B12: CIBRA - CAMACARI | C12: 00.117.842/0001-28 | D12: 6000 | E12: 1246271936 | F12: 46147 | H12: 1 | I12: Adtives | J12: 1246271936 | K12: 46132 | L12: 3042200 | M12: DIÁRIAS E ESTADIA DE MOTORISTAS | N12: 46 | O12: FINANCEIRO GERAL | P12: GRUPO CIBRA | Q12: =$Q$1-F12 -> -6
A13: 43 | B13: CIBRA - CAMACARI | C13: 00.117.842/0001-28 | D13: 2400 | E13: 1246271921 | F13: 46147 | H13: 1 | I13: Adtives | J13: 1246271921 | K13: 46132 | L13: 3042200 | M13: DIÁRIAS E ESTADIA DE MOTORISTAS | N13: 46 | O13: FINANCEIRO GERAL | P13: GRUPO CIBRA | Q13: =$Q$1-F13 -> -6
A14: 1159 | B14: YARA - RIO GRANDE | C14: 92.660.604/0013-16 | D14: 1800 | E14: 1246087936 | F14: 45112 | H14: 1 | I14: Adtives | J14: 1246087936 | K14: 45097 | L14: 3041000 | M14: FRETES DIVERSOS | N14: 46 | O14: FINANCEIRO GERAL | P14: GRUPO YARA | Q14: =$Q$1-F14 -> 1029
... A54: 7022 | B54: STRATOS/MOSAIC - ROSARIO DO CATETE | C54: 31.009.644/0001-74 | D54: 1800 | E54: 1246054442 | F54: 44897 | H54: 1 | I54: Adtives | J54: 1246054442 | K54: 44882 | L54: 3041000 | M54: FRETES DIVERSOS | N54: 46 | O54: FINANCEIRO GERAL | P54: STRATOS/MOSAIC - ROSARIO DO CATETE | Q54: =$Q$1-F54 -> 1244

Sheet Data Additive
D1: =SUBTOTAL(9,$D$3:$D$866) -> 25978603 | R1: 46141
A2: CODPARC | B2: NOMEPARC | C2: CNPJ | D2: Valor | E2: NUFIN | F2: DTVENC | G2: DHBAIXA | H2: AD_BU | I2: NOME_BU | J2: NUMNOTA | K2: DTENTSAI | L2: CODNAT | M2: DESCRNAT | N2: CODTIPOPER | O2: OPERACAO | P2: Grupo | Q2: Dias vencidos
A3: 205 | B3: FERTIPAR - RONDONÓPOLIS | C3: 09.384.948/0002-43 | D3: 80589.6 | E3: 1246271690 | F3: 46157 | H3: 1 | I3: Adtives | J3: 11158 | K3: 46129 | L3: 1010100 | M3: VENDAS MERCADO INTERNO | N3: 161 | O3: VENDA PROD. INDUSTRIALIZADO - NFE | P3: GRUPO FERTIPAR FERTILIZANTES MATO GROSSO | Q3: =$R$1-F3 -> -16 | R3: =_xlfn.XLOOKUP(P3,'Painel Additive'!$B:$B,'Painel Additive'!$B:$B,0) -> GRUPO FERTIPAR FERTILIZANTES MATO GROSSO | S3: =F3-K3 -> 28
A4: 205 | B4: FERTIPAR - RONDONÓPOLIS | C4: 09.384.948/0002-43 | D4: 81051.4 | E4: 1246273002 | F4: 46168 | H4: 1 | I4: Adtives | J4: 11248 | K4: 46140 | L4: 1010100 | M4: VENDAS MERCADO INTERNO | N4: 161 | O4: VENDA PROD. INDUSTRIALIZADO - NFE | P4: GRUPO FERTIPAR FERTILIZANTES MATO GROSSO | Q4: =$R$1-F4 -> -27 | R4: =_xlfn.XLOOKUP(P4,'Painel Additive'!$B:$B,'Painel Additive'!$B:$B,0) -> GRUPO FERTIPAR FERTILIZANTES MATO GROSSO | S4: =F4-K4 -> 28
A5: 1257 | B5: MOSAIC - CAMPO GRANDE | C5: 61.156.501/0081-30 | D5: 1980.8 | E5: 1246032946 | F5: 44774 | H5: 1 | I5: Adtives | J5: 17935 | K5: 44714 | L5: 1010100 | M5: VENDAS MERCADO INTERNO | N5: 56 | O5: VENDA A ORDEM | P5: GRUPO MOSAIC FERTILIZANTES DO BRASIL | Q5: =$R$1-F5 -> 1367 | R5: =_xlfn.XLOOKUP(P5,'Painel Additive'!$B:$B,'Painel Additive'!$B:$B,0) -> GRUPO MOSAIC FERTILIZANTES DO BRASIL | S5: =F5-K5 -> 60
A6: 1953 | B6: AMAGGI - COMODORO | C6: 77.294.254/0075-20 | D6: 58917.8 | E6: 1246267986 | F6: 46158 | H6: 1 | I6: Adtives | J6: 10907 | K6: 46098 | L6: 1010100 | M6: VENDAS MERCADO INTERNO | N6: 161 | O6: VENDA PROD. INDUSTRIALIZADO - NFE | P6: GRUPO AMAGGI | Q6: =$R$1-F6 -> -17 | R6: =_xlfn.XLOOKUP(P6,'Painel Additive'!$B:$B,'Painel Additive'!$B:$B,0) -> GRUPO AMAGGI | S6: =F6-K6 -> 60
A7: 1787 | B7: MOSAIC - UBERABA (CIU1) | C7: 33.931.486/0014-55 | D7: 107059.2 | E7: 1246262114 | F7: 46146 | G7: 46146 | H7: 1 | I7: Adtives | J7: 10629 | K7: 46056 | L7: 1010100 | M7: VENDAS MERCADO INTERNO | N7: 161 | O7: VENDA PROD. INDUSTRIALIZADO - NFE | P7: GRUPO MOSAIC FERTILIZANTES P K LTDA | Q7: =$R$1-F7 -> -5 | R7: =_xlfn.XLOOKUP(P7,'Painel Additive'!$B:$B,'Painel Additive'!$B:$B,0) -> GRUPO MOSAIC FERTILIZANTES P K LTDA | S7: =F7-K7 -> 90
A8: 1787 | B8: MOSAIC - UBERABA (CIU1) | C8: 33.931.486/0014-55 | D8: 109862.4 | E8: 1246271310 | F8: 46216 | H8: 1 | I8: Adtives | J8: 11116 | K8: 46126 | L8: 1010100 | M8: VENDAS MERCADO INTERNO | N8: 161 | O8: VENDA PROD. INDUSTRIALIZADO - NFE | P8: GRUPO MOSAIC FERTILIZANTES P K LTDA | Q8: =$R$1-F8 -> -75 | R8: =_xlfn.XLOOKUP(P8,'Painel Additive'!$B:$B,'Painel Additive'!$B:$B,0) -> GRUPO MOSAIC FERTILIZANTES P K LTDA | S8: =F8-K8 -> 90
A9: 1787 | B9: MOSAIC - UBERABA (CIU1) | C9: 33.931.486/0014-55 | D9: 116928 | E9: 1246267948 | F9: 46187 | H9: 1 | I9: Adtives | J9: 10899 | K9: 46097 | L9: 1010100 | M9: VENDAS MERCADO INTERNO | N9: 161 | O9: VENDA PROD. INDUSTRIALIZADO - NFE | P9: GRUPO MOSAIC FERTILIZANTES P K LTDA | Q9: =$R$1-F9 -> -46 | R9: =_xlfn.XLOOKUP(P9,'Painel Additive'!$B:$B,'Painel Additive'!$B:$B,0) -> GRUPO MOSAIC FERTILIZANTES P K LTDA | S9: =F9-K9 -> 90
A10: 1787 | B10: MOSAIC - UBERABA (CIU1) | C10: 33.931.486/0014-55 | D10: 115891.2 | E10: 1246262540 | F10: 46149 | H10: 1 | I10: Adtives | J10: 10652 | K10: 46059 | L10: 1010100 | M10: VENDAS MERCADO INTERNO | N10: 161 | O10: VENDA PROD. INDUSTRIALIZADO - NFE | P10: GRUPO MOSAIC FERTILIZANTES P K LTDA | Q10: =$R$1-F10 -> -8 | R10: =_xlfn.XLOOKUP(P10,'Painel Additive'!$B:$B,'Painel Additive'!$B:$B,0) -> GRUPO MOSAIC FERTILIZANTES P K LTDA | S10: =F10-K10 -> 90
A11: 1787 | B11: MOSAIC - UBERABA (CIU1) | C11: 33.931.486/0014-55 | D11: 103795.2 | E11: 1246268633 | F11: 46194 | H11: 1 | I11: Adtives | J11: 10957 | K11: 46104 | L11: 1010100 | M11: VENDAS MERCADO INTERNO | N11: 161 | O11: VENDA PROD. INDUSTRIALIZADO - NFE | P11: GRUPO MOSAIC FERTILIZANTES P K LTDA | Q11: =$R$1-F11 -> -53 | R11: =_xlfn.XLOOKUP(P11,'Painel Additive'!$B:$B,'Painel Additive'!$B:$B,0) -> GRUPO MOSAIC FERTILIZANTES P K LTDA | S11: =F11-K11 -> 90
A12: 1787 | B12: MOSAIC - UBERABA (CIU1) | C12: 33.931.486/0014-55 | D12: 111360 | E12: 1246268748 | F12: 46195 | H12: 1 | I12: Adtives | J12: 10965 | K12: 46105 | L12: 1010100 | M12: VENDAS MERCADO INTERNO | N12: 161 | O12: VENDA PROD. INDUSTRIALIZADO - NFE | P12: GRUPO MOSAIC FERTILIZANTES P K LTDA | Q12: =$R$1-F12 -> -54 | R12: =_xlfn.XLOOKUP(P12,'Painel Additive'!$B:$B,'Painel Additive'!$B:$B,0) -> GRUPO MOSAIC FERTILIZANTES P K LTDA | S12: =F12-K12 -> 90
A13: 1787 | B13: MOSAIC - UBERABA (CIU1) | C13: 33.931.486/0014-55 | D13: 114662.4 | E13: 1246268585 | F13: 46161 | H13: 1 | I13: Adtives | J13: 10953 | K13: 46101 | L13: 1010100 | M13: VENDAS MERCADO INTERNO | N13: 161 | O13: VENDA PROD. INDUSTRIALIZADO - NFE | P13: GRUPO MOSAIC FERTILIZANTES P K LTDA | Q13: =$R$1-F13 -> -20 | R13: =_xlfn.XLOOKUP(P13,'Painel Additive'!$B:$B,'Painel Additive'!$B:$B,0) -> GRUPO MOSAIC FERTILIZANTES P K LTDA | S13: =F13-K13 -> 60
A14: 1787 | B14: MOSAIC - UBERABA (CIU1) | C14: 33.931.486/0014-55 | D14: 115852.8 | E14: 1246270635 | F14: 46210 | H14: 1 | I14: Adtives | J14: 11072 | K14: 46120 | L14: 1010100 | M14: VENDAS MERCADO INTERNO | N14: 161 | O14: VENDA PROD. INDUSTRIALIZADO - NFE | P14: GRUPO MOSAIC FERTILIZANTES P K LTDA | Q14: =$R$1-F14 -> -69 | R14: =_xlfn.XLOOKUP(P14,'Painel Additive'!$B:$B,'Painel Additive'!$B:$B,0) -> GRUPO MOSAIC FERTILIZANTES P K LTDA | S14: =F14-K14 -> 90
A15: 1787 | B15: MOSAIC - UBERABA (CIU1) | C15: 33.931.486/0014-55 | D15: 114739.2 | E15: 1246271165 | F15: 46215 | H15: 1 | I15: Adtives | J15: 11105 | K15: 46125 | L15: 1010100 | M15: VENDAS MERCADO INTERNO | N15: 161 | O15: VENDA PROD. INDUSTRIALIZADO - NFE | P15: GRUPO MOSAIC FERTILIZANTES P K LTDA | Q15: =$R$1-F15 -> -74 | R15: =_xlfn.XLOOKUP(P15,'Painel Additive'!$B:$B,'Painel Additive'!$B:$B,0) -> GRUPO MOSAIC FERTILIZANTES P K LTDA | S15: =F15-K15 -> 90
A16: 1787 | B16: MOSAIC - UBERABA (CIU1) | C16: 33.931.486/0014-55 | D16: 114969.6 | E16: 1246264543 | F16: 46166 | H16: 1 | I16: Adtives | J16: 10746 | K16: 46076 | L16: 1010100 | M16: VENDAS MERCADO INTERNO | N16: 161 | O16: VENDA PROD. INDUSTRIALIZADO - NFE | P16: GRUPO MOSAIC FERTILIZANTES P K LTDA | Q16: =$R$1-F16 -> -25 | R16: =_xlfn.XLOOKUP(P16,'Painel Additive'!$B:$B,'Painel Additive'!$B:$B,0) -> GRUPO MOSAIC FERTILIZANTES P K LTDA | S16: =F16-K16 -> 90
A17: 1787 | B17: MOSAIC - UBERABA (CIU1) | C17: 33.931.486/0014-55 | D17: 113356.8 | E17: 1246269731 | F17: 46202 | H17: 1 | I17: Adtives | J17: 11014 | K17: 46112 | L17: 1010100 | M17: VENDAS MERCADO INTERNO | N17: 161 | O17: VENDA PROD. INDUSTRIALIZADO - NFE | P17: GRUPO MOSAIC FERTILIZANTES P K LTDA | Q17: =$R$1-F17 -> -61 | R17: =_xlfn.XLOOKUP(P17,'Painel Additive'!$B:$B,'Painel Additive'!$B:$B,0) -> GRUPO MOSAIC FERTILIZANTES P K LTDA | S17: =F17-K17 -> 90
A18: 1787 | B18: MOSAIC - UBERABA (CIU1) | C18: 33.931.486/0014-55 | D18: 110246.4 | E18: 1246272757 | F18: 46229 | H18: 1 | I18: Adtives | J18: 11229 | K18: 46139 | L18: 1010100 | M18: VENDAS MERCADO INTERNO | N18: 161 | O18: VENDA PROD. INDUSTRIALIZADO - NFE | P18: GRUPO MOSAIC FERTILIZANTES P K LTDA | Q18: =$R$1-F18 -> -88 | R18: =_xlfn.XLOOKUP(P18,'Painel Additive'!$B:$B,'Painel Additive'!$B:$B,0) -> GRUPO MOSAIC FERTILIZANTES P K LTDA | S18: =F18-K18 -> 90
A19: 1787 | B19: MOSAIC - UBERABA (CIU1) | C19: 33.931.486/0014-55 | D19: 115392 | E19: 1246265885 | F19: 46173 | H19: 1 | I19: Adtives | J19: 10791 | K19: 46083 | L19: 1010100 | M19: VENDAS MERCADO INTERNO | N19: 161 | O19: VENDA PROD. INDUSTRIALIZADO - NFE | P19: GRUPO MOSAIC FERTILIZANTES P K LTDA | Q19: =$R$1-F19 -> -32 | R19: =_xlfn.XLOOKUP(P19,'Painel Additive'!$B:$B,'Painel Additive'!$B:$B,0) -> GRUPO MOSAIC FERTILIZANTES P K LTDA | S19: =F19-K19 -> 90
... A65: 33 | B65: HERINGER - PARANAGUÁ | C65: 22.266.175/0031-01 | D65: 99167.6 | E65: 1246271248 | F65: 46155 | H65: 1 | I65: Adtives | J65: 11114 | K65: 46125 | L65: 1010100 | M65: VENDAS MERCADO INTERNO | N65: 161 | O65: VENDA PROD. INDUSTRIALIZADO - NFE | P65: GRUPO HERINGER | Q65: =$R$1-F65 -> -14 | R65: =_xlfn.XLOOKUP(P65,'Painel Additive'!$B:$B,'Painel Additive'!$B:$B,0) -> GRUPO HERINGER | S65: =F65-K65 -> 30
A66: 214 | B66: UNIFERTIL - CANOAS UN1 | C66: 87.249.561/0001-07 | D66: 82931.8 | E66: 1246270505 | F66: 46147 | G66: 46147 | H66: 1 | I66: Adtives | J66: 11065 | K66: 46119 | L66: 1010100 | M66: VENDAS MERCADO INTERNO | N66: 161 | O66: VENDA PROD. INDUSTRIALIZADO - NFE | P66: GRUPO UNIFERTIL | Q66: =$R$1-F66 -> -6 | R66: =_xlfn.XLOOKUP(P66,'Painel Additive'!$B:$B,'Painel Additive'!$B:$B,0) -> GRUPO UNIFERTIL | S66: =F66-K66 -> 28
A67: 214 | B67: UNIFERTIL - CANOAS UN1 | C67: 87.249.561/0001-07 | D67: 82854.1 | E67: 1246272851 | F67: 46167 | H67: 1 | I67: Adtives | J67: 11237 | K67: 46139 | L67: 1010100 | M67: VENDAS MERCADO INTERNO | N67: 161 | O67: VENDA PROD. INDUSTRIALIZADO - NFE | P67: GRUPO UNIFERTIL | Q67: =$R$1-F67 -> -26 | R67: =_xlfn.XLOOKUP(P67,'Painel Additive'!$B:$B,'Painel Additive'!$B:$B,0) -> GRUPO UNIFERTIL | S67: =F67-K67 -> 28
A68: 214 | B68: UNIFERTIL - CANOAS UN1 | C68: 87.249.561/0001-07 | D68: 99281.7 | E68: 1246271672 | F68: 46157 | H68: 1 | I68: Adtives | J68: 11156 | K68: 46129 | L68: 1010100 | M68: VENDAS MERCADO INTERNO | N68: 161 | O68: VENDA PROD. INDUSTRIALIZADO - NFE | P68: GRUPO UNIFERTIL | Q68: =$R$1-F68 -> -16 | R68: =_xlfn.XLOOKUP(P68,'Painel Additive'!$B:$B,'Painel Additive'!$B:$B,0) -> GRUPO UNIFERTIL | S68: =F68-K68 -> 28
A69: 2 | B69: CARGILL - UBERLÂNDIA | C69: 60.498.706/0134-88 | D69: 13431 | E69: 1246272905 | F69: 46168 | G69: 46146 | H69: 3 | I69: Job Work | J69: 2898 | K69: 46140 | L69: 1010100 | M69: VENDAS MERCADO INTERNO | N69: 199 | O69: VENDA MERC INDUSTRIALIZADA TERCEIROS | P69: GRUPO CARGILL | Q69: =$R$1-F69 -> -27 | R69: =_xlfn.XLOOKUP(P69,'Painel Additive'!$B:$B,'Painel Additive'!$B:$B,0) -> GRUPO CARGILL | S69: =F69-K69 -> 28
A70: 183 | B70: HERINGER - RONDONÓPOLIS II | C70: 22.266.175/0036-08 | D70: 4231.96 | E70: 1246014155 | F70: 47847 | H70: 1 | I70: Adtives | J70: 8361 | K70: 43384 | L70: 1010100 | M70: VENDAS MERCADO INTERNO | N70: 161 | O70: VENDA PROD. INDUSTRIALIZADO - NFE | P70: GRUPO HERINGER | Q70: =$R$1-F70 -> -1706 | R70: =_xlfn.XLOOKUP(P70,'Painel Additive'!$B:$B,'Painel Additive'!$B:$B,0) -> GRUPO HERINGER | S70: =F70-K70 -> 4463
A71: 183 | B71: HERINGER - RONDONÓPOLIS II | C71: 22.266.175/0036-08 | D71: 4045.01 | E71: 1246014156 | F71: 48212 | H71: 1 | I71: Adtives | J71: 8361 | K71: 43384 | L71: 1010100 | M71: VENDAS MERCADO INTERNO | N71: 161 | O71: VENDA PROD. INDUSTRIALIZADO - NFE | P71: GRUPO HERINGER | Q71: =$R$1-F71 -> -2071 | R71: =_xlfn.XLOOKUP(P71,'Painel Additive'!$B:$B,'Painel Additive'!$B:$B,0) -> GRUPO HERINGER | S71: =F71-K71 -> 4828
A72: 183 | B72: HERINGER - RONDONÓPOLIS II | C72: 22.266.175/0036-08 | D72: 4339.6 | E72: 1246014157 | F72: 48578 | H72: 1 | I72: Adtives | J72: 8361 | K72: 43384 | L72: 1010100 | M72: VENDAS MERCADO INTERNO | N72: 161 | O72: VENDA PROD. INDUSTRIALIZADO - NFE | P72: GRUPO HERINGER | Q72: =$R$1-F72 -> -2437 | R72: =_xlfn.XLOOKUP(P72,'Painel Additive'!$B:$B,'Painel Additive'!$B:$B,0) -> GRUPO HERINGER | S72: =F72-K72 -> 5194
A73: 183 | B73: HERINGER - RONDONÓPOLIS II | C73: 22.266.175/0036-08 | D73: 7512.16 | E73: 1246014158 | F73: 48943 | H73: 1 | I73: Adtives | J73: 8361 | K73: 43384 | L73: 1010100 | M73: VENDAS MERCADO INTERNO | N73: 161 | O73: VENDA PROD. INDUSTRIALIZADO - NFE | P73: GRUPO HERINGER | Q73: =$R$1-F73 -> -2802 | R73: =_xlfn.XLOOKUP(P73,'Painel Additive'!$B:$B,'Painel Additive'!$B:$B,0) -> GRUPO HERINGER | S73: =F73-K73 -> 5559
A74: 183 | B74: HERINGER - RONDONÓPOLIS II | C74: 22.266.175/0036-08 | D74: 30552.86 | E74: 1246014159 | F74: 49308 | H74: 1 | I74: Adtives | J74: 8361 | K74: 43384 | L74: 1010100 | M74: VENDAS MERCADO INTERNO | N74: 161 | O74: VENDA PROD. INDUSTRIALIZADO - NFE | P74: GRUPO HERINGER | Q74: =$R$1-F74 -> -3167 | R74: =_xlfn.XLOOKUP(P74,'Painel Additive'!$B:$B,'Painel Additive'!$B:$B,0) -> GRUPO HERINGER | S74: =F74-K74 -> 5924
A75: 183 | B75: HERINGER - RONDONÓPOLIS II | C75: 22.266.175/0036-08 | D75: 1512.63 | E75: 1246014161 | F75: 50039 | H75: 1 | I75: Adtives | J75: 8361 | K75: 43384 | L75: 1010100 | M75: VENDAS MERCADO INTERNO | N75: 161 | O75: VENDA PROD. INDUSTRIALIZADO - NFE | P75: GRUPO HERINGER | Q75: =$R$1-F75 -> -3898 | R75: =_xlfn.XLOOKUP(P75,'Painel Additive'!$B:$B,'Painel Additive'!$B:$B,0) -> GRUPO HERINGER | S75: =F75-K75 -> 6655
A76: 183 | B76: HERINGER - RONDONÓPOLIS II | C76: 22.266.175/0036-08 | D76: 1982.85 | E76: 1246014162 | F76: 50404 | H76: 1 | I76: Adtives | J76: 8361 | K76: 43384 | L76: 1010100 | M76: VENDAS MERCADO INTERNO | N76: 161 | O76: VENDA PROD. INDUSTRIALIZADO - NFE | P76: GRUPO HERINGER | Q76: =$R$1-F76 -> -4263 | R76: =_xlfn.XLOOKUP(P76,'Painel Additive'!$B:$B,'Painel Additive'!$B:$B,0) -> GRUPO HERINGER | S76: =F76-K76 -> 7020
A77: 183 | B77: HERINGER - RONDONÓPOLIS II | C77: 22.266.175/0036-08 | D77: 2549.38 | E77: 1246014163 | F77: 50769 | H77: 1 | I77: Adtives | J77: 8361 | K77: 43384 | L77: 1010100 | M77: VENDAS MERCADO INTERNO | N77: 161 | O77: VENDA PROD. INDUSTRIALIZADO - NFE | P77: GRUPO HERINGER | Q77: =$R$1-F77 -> -4628 | R77: =_xlfn.XLOOKUP(P77,'Painel Additive'!$B:$B,'Painel Additive'!$B:$B,0) -> GRUPO HERINGER | S77: =F77-K77 -> 7385
A78: 183 | B78: HERINGER - RONDONÓPOLIS II | C78: 22.266.175/0036-08 | D78: 5546.31 | E78: 1246014165 | F78: 51500 | H78: 1 | I78: Adtives | J78: 8361 | K78: 43384 | L78: 1010100 | M78: VENDAS MERCADO INTERNO | N78: 161 | O78: VENDA PROD. INDUSTRIALIZADO - NFE | P78: GRUPO HERINGER | Q78: =$R$1-F78 -> -5359 | R78: =_xlfn.XLOOKUP(P78,'Painel Additive'!$B:$B,'Painel Additive'!$B:$B,0) -> GRUPO HERINGER | S78: =F78-K78 -> 8116
A79: 183 | B79: HERINGER - RONDONÓPOLIS II | C79: 22.266.175/0036-08 | D79: 5546.31 | E79: 1246014166 | F79: 51865 | H79: 1 | I79: Adtives | J79: 8361 | K79: 43384 | L79: 1010100 | M79: VENDAS MERCADO INTERNO | N79: 161 | O79: VENDA PROD. INDUSTRIALIZADO - NFE | P79: GRUPO HERINGER | Q79: =$R$1-F79 -> -5724 | R79: =_xlfn.XLOOKUP(P79,'Painel Additive'!$B:$B,'Painel Additive'!$B:$B,0) -> GRUPO HERINGER | S79: =F79-K79 -> 8481
A80: 183 | B80: HERINGER - RONDONÓPOLIS II | C80: 22.266.175/0036-08 | D80: 5546.31 | E80: 1246014167 | F80: 52230 | H80: 1 | I80: Adtives | J80: 8361 | K80: 43384 | L80: 1010100 | M80: VENDAS MERCADO INTERNO | N80: 161 | O80: VENDA PROD. INDUSTRIALIZADO - NFE | P80: GRUPO HERINGER | Q80: =$R$1-F80 -> -6089 | R80: =_xlfn.XLOOKUP(P80,'Painel Additive'!$B:$B,'Painel Additive'!$B:$B,0) -> GRUPO HERINGER | S80: =F80-K80 -> 8846
A81: 183 | B81: HERINGER - RONDONÓPOLIS II | C81: 22.266.175/0036-08 | D81: 5546.31 | E81: 1246014168 | F81: 52595 | H81: 1 | I81: Adtives | J81: 8361 | K81: 43384 | L81: 1010100 | M81: VENDAS MERCADO INTERNO | N81: 161 | O81: VENDA PROD. INDUSTRIALIZADO - NFE | P81: GRUPO HERINGER | Q81: =$R$1-F81 -> -6454 | R81: =_xlfn.XLOOKUP(P81,'Painel Additive'!$B:$B,'Painel Additive'!$B:$B,0) -> GRUPO HERINGER | S81: =F81-K81 -> 9211
... A101: 201 | B101: JOSAPAR - PELOTAS | C101: 87.456.562/0006-37 | D101: 185040 | E101: 1246269671 | F101: 46231 | H101: 1 | I101: Adtives | J101: 2855 | K101: 46111 | L101: 1010100 | M101: VENDAS MERCADO INTERNO | N101: 161 | O101: VENDA PROD. INDUSTRIALIZADO - NFE | P101: GRUPO JOSAPAR | Q101: =$R$1-F101 -> -90 | R101: =_xlfn.XLOOKUP(P101,'Painel Additive'!$B:$B,'Painel Additive'!$B:$B,0) -> GRUPO JOSAPAR | S101: =F101-K101 -> 120
A102: 903 | B102: YARA - PONTA GROSSA | C102: 92.660.604/0138-37 | D102: 133334.43 | E102: 1246268951 | F102: 46146 | G102: 46146 | H102: 1 | I102: Adtives | J102: 10971 | K102: 46106 | L102: 1010100 | M102: VENDAS MERCADO INTERNO | N102: 161 | O102: VENDA PROD. INDUSTRIALIZADO - NFE | P102: GRUPO YARA | Q102: =$R$1-F102 -> -5 | R102: =_xlfn.XLOOKUP(P102,'Painel Additive'!$B:$B,'Painel Additive'!$B:$B,0) -> GRUPO YARA | S102: =F102-K102 -> 40
