Workbook
Name \0: #N/A
Name \1: #REF!
Name \2: #REF!
Name \3: #REF!
Name \4: #REF!
Name \5: #REF!
Name \a: #N/A
Name \b: #N/A
Name \c: #N/A
Name \d: #N/A
Name \DSUM: #REF!
Name \e: #N/A
Name \EXP: #REF!
Name \f: #N/A
Name \g: #N/A
Name \GL: #REF!
Name \h: #REF!
Name \I: #REF!
Name \k: #REF!
Name \l: #REF!
Name \m: #N/A
Name \MPR2: #REF!
Name \n: #REF!
Name \o: #REF!
Name \p: #N/A
Name \q: #REF!
Name \R: #REF!
Name \s: #N/A
Name \t: #REF!
Name \u: #N/A
Name \w: #REF!
Name \x: #REF!
Name \y: #REF!
Name \z: #REF!
Name _: #REF!
Name __?Business___Market_Spr: #REF!
Name __?End_Use_Analysis___Sectoral_Gro: #REF!
Name __?INDUSTRY_MATERIAL_BALA: #REF!
Name __?INDUSTRY_MATERIAL_BALANCE___PROJECTI: #REF!
Name __?PE___Q1_REV: #REF!
Name __?PE_1996: #REF!
Name __?PE_BUSINESS___PAST___FUT: #REF!
Name __?PE_REV: #REF!
Name __?PRICE_FORECAST___1995: #REF!
Name __?PROFITABILITY__Q3_1996__: #REF!
Name __?Q3___SUMM: #REF!
Name __?Quarterwise_Collection_P: #REF!
Name __?Quarterwise_Export_P: #REF!
Name __?QUARTERWISE_PERFORMA: #REF!
Name __?RE: #REF!
Name _______________________________DAT5: #REF!
Name _______________________________DAT7: #REF!
Name ______________________________DAT1: #REF!
Name ______________________________DAT10: #REF!
Name _____________________________DAT5: #REF!
Name _____________________________DAT7: #REF!
Name ____________________________DAT1: #REF!
Name ____________________________DAT10: #REF!
Name ____________________________DAT5: #REF!
Name ____________________________DAT7: #REF!

Sheet AR - slide BoD
B1: Amounts in 000
B2: Total receivables | I2: =I22/1000 -> 64140.011 | J2: =J22/1000 -> 105264.99
B4: Receivables as on 28th Feb 25 | D4: BU | E4: Overdue | F4: Not Due | G4: Not Due | I4: Provision | J4: Provision | L4: Provision risks - overdue receivables | P4: Remark
L5: Probable | M5: Possible | N5: Rare
B6: Central do Adubo | D6: Fertilizer | E6: =E26/1000 -> 7560.7278 | F6: =F26/1000 -> 0 | G6: =G26/1000 -> 7560.7278 | I6: =I26/1000 -> 0 | J6: =J26/1000 -> 0 | L6: =L26/1000 -> 0 | M6: =M26/1000 -> 7560.7278 | N6: =N26/1000 -> 0 | P6: Creditor´s assembly Judicial recovery plan has not yet been approved by Creditors. Adfert advisors believe that the AS-IS plan will not be approved and new financial conditions will need to be presented.
B7: SM Agro / Fazenda Baturi | D7: Fertilizer | E7: =E27/1000 -> 3088.5311 | F7: =F27/1000 -> 0 | G7: =G27/1000 -> 3088.5311 | I7: =I27/1000 -> 3088.5311 | J7: =J27/1000 -> 0 | L7: =L27/1000 -> 3088.5311 | M7: =M27/1000 -> 0 | N7: =N27/1000 -> 0 | P7: Judicial collection lawsuit is ongoing.
B8: CBM Fertilizantes | D8: Fertilizer | E8: =E28/1000 -> 3044.8509 | F8: =F28/1000 -> 0 | G8: =G28/1000 -> 3044.8509 | I8: =I28/1000 -> 3044.8509 | J8: =J28/1000 -> 0 | L8: =L28/1000 -> 3044.8509 | M8: =M28/1000 -> 0 | N8: =N28/1000 -> 0 | P8: Adfert has taken legal action and collection recovery lawsuit has been filed. Payment plan was not succesful.
B9: Mogiana Tecno Agro | D9: Fertilizer | E9: =E29/1000 -> 2492.8421 | F9: =F29/1000 -> 0 | G9: =G29/1000 -> 2492.8421 | I9: =I29/1000 -> 0 | J9: =J29/1000 -> 0 | L9: =L29/1000 -> 0 | M9: =M29/1000 -> 2492.8421 | N9: =N29/1000 -> 0 | P9: AFT received a renewalled payment proposal. Monthly payments along 2 yrs, with Machineary as guarantee and worth 25% of Open Exposure. Formal proposal still pending full disclosre on documents and valuation on Machinery.
B10: Casa das Sementes | D10: Fertilizer | E10: =E30/1000 -> 1863.2009 | F10: =F30/1000 -> 0 | G10: =G30/1000 -> 1863.2009 | I10: =I30/1000 -> 1863.2009 | J10: =J30/1000 -> 0 | L10: =L30/1000 -> 1863.2009 | M10: =M30/1000 -> 0 | N10: =N30/1000 -> 0 | P10: Legal process ongoing and 100% of the invoices we provisioned.
B11: Terra Fértil | D11: Fertilizer | E11: =E31/1000 -> 1702.8487 | F11: =F31/1000 -> 0 | G11: =G31/1000 -> 1702.8487 | I11: =I31/1000 -> 1702.8487 | J11: =J31/1000 -> 0 | L11: =L31/1000 -> 1702.8487 | M11: =M31/1000 -> 0 | N11: =N31/1000 -> 0 | P11: AFT has reached a payment agreement: 15% paid by Oct 25 and 3 yearly installments (Oct 26-27-28). No discount on principal and price inflation indexed
B12: Agro Beraldo | D12: Fertilizer | E12: =E32/1000 -> 876.01175 | F12: =F32/1000 -> 0 | G12: =G32/1000 -> 876.01175 | I12: =I32/1000 -> 0 | J12: =J32/1000 -> 0 | L12: =L32/1000 -> 0 | M12: =M32/1000 -> 876.01175 | N12: =N32/1000 -> 0 | P12: Judicial collection lawsuit is ongoing.
B14: Total Over Due in Litigation (TOP 7) | E14: =E39/1000 -> 22315.752 | F14: 0 | G14: 0 | I14: =I39/1000 -> 10937.332 | J14: =J39/1000 -> 0 | L14: =L39/1000 -> 10937.332 | M14: =M39/1000 -> 11378.42 | N14: 0
B15: Total Over Due with Possible Loss | E15: =E45/1000 -> 6.07632 | F15: 0 | G15: 0 | I15: =I45/1000 -> 6.07632 | J15: =J45/1000 -> 0 | L15: =L45/1000 -> 6.07632 | M15: =M45/1000 -> 0 | N15: 0
B16: Low Risk - Expect to Receive soon | E16: =E46/1000 -> 693.20556 | F16: =F46/1000 -> 0 | G16: =G46/1000 -> 693.20556 | I16: =I46/1000 -> 163.97203 | J16: =J46/1000 -> 0 | L16: =L46/1000 -> 0 | M16: =M46/1000 -> 0 | N16: =N46/1000 -> 693.20556 | P16: Provision as per corporate policy
B17: Total | E17: =E16+E15+E14 -> 23015.034 | F17: =F16+F15+F14 -> 0 | G17: =G16+G15+G14 -> 693.20556 | I17: =I16+I15+I14 -> 11107.381 | J17: =J16+J15+J14 -> 0 | L17: =L14+L15 -> 10943.409 | M17: =M16+M14 -> 11378.42 | N17: =N16+N14 -> 693.20556
B19: in BRl
B22: Total receivables | I22: =SUM(E124:F124) -> 64140011 | J22: =SUM(F124:G124) -> 1.0526499e+08
B24: Receivables as on 31th May 26 | D24: BU | E24: Overdue | F24: Not Due | G24: Total | I24: Provision | J24: Write Off | L24: Collection Risk | P24: Remark
L25: Probable | M25: Possible | N25: Rare
B26: CENTRAL DO ADUBO COM E REPRESENTACAO LTD | D26: Fertilizers | E26: 7560727.8 | F26: 0 | G26: =SUM(E26:F26) -> 7560727.8 | I26: 0 | L26: =I26 -> 0 | M26: =E26-I26 -> 7560727.8 | P26: Current Status: Creditor´s Assembly has been approved. All suppliers to receive 35% (65% haircut) of total Outstanding in 10 years (2x per year installments) after a 18-months grace period, corrected by TR inflation index. Prefered suppliers, such as AFT, are eligible to full Overdue recovery based on future sales. 3% of all new CAD Sales to offset Old Overdues and 4% for sales with tenor (credit). This condition is non-binding and the client is to grant AFT a real estate guarantee of BRL 1MM. Upcoming Actions: Decision will now need to undergo approval and pass the entire appeal period. This step may still take a couple months to be completed.
B27: GRUPO LEANDRO SARTI | D27: Fertilizers | E27: 3088531.1 | F27: 0 | G27: =SUM(E27:F27) -> 3088531.1 | I27: 3088531.1 | L27: =I27 -> 3088531.1 | M27: =E27-I27 -> 0 | P27: Current Status: In Litigation via Collection enforcement claim. The judicial process is still in the initial phase, and we are in the period of notifying the parties involved. Upcoming Actions: We will await the procedures set forth by the court.
B28: AGRO BERALDO | D28: Fertilizers | E28: 3044850.9 | F28: 0 | G28: =SUM(E28:F28) -> 3044850.9 | I28: 3044850.9 | L28: =I28 -> 3044850.9 | M28: =E28-I28 -> 0 | P28: Current Status: The Litigation Collection enforcement claim process is ongoing. Upcoming Actions: AFT awaiting for further updates by the court.
B29: TERRA FERTIL - MACHADO | D29: Fertilizers | E29: 2492842.1 | F29: 0 | G29: =SUM(E29:F29) -> 2492842.1 | I29: 0 | L29: =I29 -> 0 | M29: =E29-I29 -> 2492842.1 | P29: Current Status: In Litigation via Collection enforcement claim. An agreement has been reached between parties, under the following terms: (i) Total settlement amount: R$ 3,192,985.64; (ii) Down payment: R$ 478,947.84, to be paid by October 30, 2025; (iii) Remaining balance: R$ 2,714,037.80, to be paid in three annual installments of R$ 904,679.26 each (2026 / 2027 / 2028), to be duly adjusted by inflation/court index. Upcoming Actions: AFT awaiting for the downpayment from the debtor to fulfill the agreement (Oct 20th 2025).
B30: MOGIANA TECNO AGRO | D30: Fertilizers | E30: 1863200.9 | F30: 0 | G30: =SUM(E30:F30) -> 1863200.9 | I30: 1863200.9 | L30: =I30 -> 1863200.9 | M30: =E30-I30 -> 0 | P30: Current Status: In Litigation via Collection enforcement claim. AFT received a proposal agreement, consisting of 12 initial installments of R$ 50,000.00, beginning March 28, which we had previously agreed after trying to negotiate a higher amount. From the 13th month, the proposal would be to rise monthly installments to R$ 100,000.00. This payment agreement would include both principal (R$ 2,502,567.34) and Interest (R$ 204,693.57). We have, via the enforcement collection claim received BRL 29k from the clients account via judicial decison. Upcoming Actions: we´ve not received feedback and are still assessing the viability of an agreed payment plan proposal. AFT is continuing to follow up on a payment schedule definition. AFT continues to follow on enforcement of any assets available from the client.
B31: CASA DAS SEMENTES | D31: Fertilizers | E31: 1702848.7 | F31: 0 | G31: =SUM(E31:F31) -> 1702848.7 | I31: 1702848.7 | L31: =I31 -> 1702848.7 | M31: =E31-I31 -> 0 | P31: Current Status: In Litigation via Collection enforcement claim. The process is ongoing, and we have successfully notified the debtor via judicial court. Upcoming Actions: AFT is seeking to seize assets from the debtor via the judicial claim which is ongoing.
B32: CBM FERTILIZANTES | D32: Fertilizers | E32: 876011.75 | F32: 0 | G32: =SUM(E32:F32) -> 876011.75 | I32: 0 | L32: =I32 -> 0 | M32: =E32-I32 -> 876011.75 | P32: Judicial settlement has been signed, under the following terms: (i) Total settlement amount: R$ 1,179,964.76, to be paid under the following conditions; (ii) Agreed payment in Two installments of R$ 100,000.00 each, due on April 24, 2025, and September 30th, 2025; Client has paid BRL 100k of the 1st installment and 2nd to be paid on the 30th of Sept. (iii) Three annual installments of R$ 326,654.92 , due on September 30, 2026, September 30, 2027, and September 30, 2028; Upcoming Actions: AFT awaiting for the payment plan agreed ofr September (another BRL 100k payment).
B33: GRUPO TRIANGULO AGRO | D33: Fertilizers | E33: 237309.12 | F33: 0 | G33: =SUM(E33:F33) -> 237309.12 | I33: 237309.12 | L33: =I33 -> 237309.12 | M33: =E33-I33 -> 0 | P33: Current Status: Client has issue a Judicial Recovery claim. The judicial process is still in the initial phase, and AFT has been notified. Upcoming Actions: AFT awaiting for the next steps to be set by court.
B34: TERRA FERTILIZANTES LTDA - ARAXÁ | D34: Additives | E34: 226233.6 | F34: 0 | G34: =SUM(E34:F34) -> 226233.6 | I34: 226233.6 | L34: =I34 -> 226233.6 | M34: =E34-I34 -> 0 | P34: May - 2024. In Litigation via collection enforcement. We don´t expect to have the collection. Client has been operation with a different Tax Id and we´re investigating how to link both companies to this claim.
B35: FAZENDA ARCOS SÃO JOÃO | D35: Fertilizers | E35: 988506.24 | F35: 0 | G35: =SUM(E35:F35) -> 988506.24 | I35: 539667.84 | L35: =I35 -> 539667.84 | M35: =E35-I35 -> 448838.4 | P35: Aug- 2025 Payment plan negotiation ongoing.
B36: ITERUM - RONDONOPOLIS | D36: Additives | E36: 213750 | F36: 0 | G36: =SUM(E36:F36) -> 213750 | I36: 213750 | L36: =I36 -> 213750 | M36: =E36-I36 -> 0 | P36: Dec- 2024 - Client facing fanancial difficulties and offered to return non-used final products. AFT is validating samples collected for quality assurance.
B37: GLINFERTIL - SAO FRANCISCO DO SUL | D37: Additives | E37: 20940 | F37: 0 | G37: =SUM(E37:F37) -> 20940 | I37: 20940 | L37: =I37 -> 20940 | M37: =E37-I37 -> 0 | P37: Nov 2023 Overdue. We don´t expect to receive collection from this client. The current status is that the client awaits for a court decision to accept the Judicial recovery process.
B39: Total Over Due in Litigation (TOP 12) | E39: =SUM(E26:E37) -> 22315752 | F39: =SUM(F26:F37) -> 0 | G39: =SUM(G26:G37) -> 22315752 | I39: =SUM(I26:I37) -> 10937332 | J39: =SUM(J26:J37) -> 0 | L39: =SUM(L26:L37) -> 10937332 | M39: =SUM(M26:M37) -> 11378420 | N39: =SUM(N26:N37) -> 0
B40: KLEYTON DUARTE SOARES | D40: Additives | E40: 100 | F40: 0 | G40: =SUM(E40:F40) -> 100 | I40: 100 | L40: =I40 -> 100 | M40: =E40-L40 -> 0 | P40: Jul - 2024 - Sale of old fixed assets to employees (chairs, desks etc) and it was not duly debited in employees payroll. Employee has left the company.
B41: MARIA JOSE DA SILVA | D41: Additives | E41: 50 | F41: 0 | G41: =SUM(E41:F41) -> 50 | I41: 50 | L41: =I41 -> 50 | M41: =E41-L41 -> 0 | P41: Aug - 2024 - Sale of old fixed assets to employees (chairs, desks etc) and it was not duly debited in employees payroll. Employee has left the company.
B42: GRUPO YARA | D42: Additives | E42: 5626.32 | F42: 0 | G42: =SUM(E42:F42) -> 5626.32 | I42: 5626.32 | L42: =I42 -> 5626.32 | M42: =E42-L42 -> 0 | P42: June 2024 - invoice underpayment due client claim of weight divergence
B43: SEU LIXO | D43: Additives | E43: 300 | F43: 0 | G43: =SUM(E43:F43) -> 300 | I43: 300 | L43: =I43 -> 300 | M43: =E43-L43 -> 0 | P43: Nov 2024 - sale of scrap materials.
B45: Total Over Due with Probable Loss | E45: =SUM(E40:E44) -> 6076.32 | F45: =SUM(F40:F44) -> 0 | G45: =SUM(G40:G44) -> 6076.32 | I45: =SUM(I40:I44) -> 6076.32 | J45: =SUM(J40:J44) -> 0 | L45: =SUM(L40:L44) -> 6076.32 | M45: =SUM(M40:M44) -> 0 | N45: =SUM(N40:N44) -> 0
B46: Low Risk - Expect to Receive soon | E46: =SUM(E47:E54) -> 693205.56 | F46: =F55+F56+F57 -> 0 | G46: =SUM(G47:G54) -> 693205.56 | I46: =SUM(I47:I54) -> 163972.03 | J46: =SUM(J47:J54) -> 0 | L46: =SUM(L47:L54) -> 0 | M46: =SUM(M47:M54) -> 0 | N46: =SUM(N47:N54) -> 693205.56 | P46: Provision as per corporate policy
B47: FAZENDA FERRADURA | D47: Fertilizers | E47: 329327.91 | G47: 329327.91 | I47: 0 | N47: =E47 -> 329327.91
B48: FERTIBAL - EQUADOR | D48: Additive Intl. | E48: 14548.35 | G48: =SUM(E48:F48) -> 14548.35 | I48: 436.4505 | N48: =E48 -> 14548.35
...

Sheet freight debit notes
D1: =SUBTOTAL(9,D3:D999) -> 154983.12 | Q1: 46197
A2: CODPARC | B2: NOMEPARC | C2: CNPJ | D2: Valor | E2: NUFIN | F2: DTVENC | G2: DHBAIXA | H2: AD_BU | I2: NOME_BU | J2: NUMNOTA | K2: DTENTSAI | L2: CODNAT | M2: DESCRNAT | N2: CODTIPOPER | O2: OPERACAO | P2: Grupo | Q2: Dias vencidos
A3: 1787 | B3: MOSAIC - UBERABA (CIU1) | C3: 33.931.486/0014-55 | D3: 3600 | E3: 1246031589 | F3: 44784 | H3: 1 | I3: Adtives | J3: 1246031589 | K3: 44769 | L3: 3041000 | M3: FRETES DIVERSOS | N3: 46 | O3: FINANCEIRO GERAL | P3: GRUPO MOSAIC FERTILIZANTES P K LTDA | Q3: =$Q$1-F3 -> 1413
A4: 1787 | B4: MOSAIC - UBERABA (CIU1) | C4: 33.931.486/0014-55 | D4: 2700 | E4: 1246055596 | F4: 44889 | H4: 1 | I4: Adtives | J4: 1246055596 | K4: 44889 | L4: 3041000 | M4: FRETES DIVERSOS | N4: 46 | O4: FINANCEIRO GERAL | P4: GRUPO MOSAIC FERTILIZANTES P K LTDA | Q4: =$Q$1-F4 -> 1308
A5: 1788 | B5: MOSAIC - UBERABA (CIU2) | C5: 33.931.486/0021-84 | D5: 5400 | E5: 1246055599 | F5: 44889 | H5: 1 | I5: Adtives | J5: 1246055599 | K5: 44889 | L5: 3041000 | M5: FRETES DIVERSOS | N5: 46 | O5: FINANCEIRO GERAL | P5: GRUPO MOSAIC FERTILIZANTES P K LTDA | Q5: =$Q$1-F5 -> 1308
A6: 1788 | B6: MOSAIC - UBERABA (CIU2) | C6: 33.931.486/0021-84 | D6: 1200 | E6: 1246190701 | F6: 45674 | H6: 1 | I6: Adtives | J6: 1246190701 | K6: 45659 | L6: 3041000 | M6: FRETES DIVERSOS | N6: 46 | O6: FINANCEIRO GERAL | P6: GRUPO MOSAIC FERTILIZANTES P K LTDA | Q6: =$Q$1-F6 -> 523
A7: 1789 | B7: MOSAIC - ARAXA (CMA) | C7: 33.931.486/0019-60 | D7: 2700 | E7: 1246120461 | F7: 45294 | H7: 1 | I7: Adtives | J7: 191223 | K7: 45279 | L7: 3041000 | M7: FRETES DIVERSOS | N7: 46 | O7: FINANCEIRO GERAL | P7: GRUPO MOSAIC FERTILIZANTES P K LTDA | Q7: =$Q$1-F7 -> 903
A8: 1789 | B8: MOSAIC - ARAXA (CMA) | C8: 33.931.486/0019-60 | D8: 900 | E8: 1246146095 | F8: 45428 | H8: 1 | I8: Adtives | J8: 1246120461 | K8: 45428 | L8: 3041000 | M8: FRETES DIVERSOS | N8: 46 | O8: FINANCEIRO GERAL | P8: GRUPO MOSAIC FERTILIZANTES P K LTDA | Q8: =$Q$1-F8 -> 769
A9: 43 | B9: CIBRA - CAMACARI | C9: 00.117.842/0001-28 | D9: 2400 | E9: 1246271921 | F9: 46147 | H9: 1 | I9: Adtives | J9: 1246271921 | K9: 46132 | L9: 3042200 | M9: DIÁRIAS E ESTADIA DE MOTORISTAS | N9: 46 | O9: FINANCEIRO GERAL | P9: GRUPO CIBRA | Q9: =$Q$1-F9 -> 50
A10: 1159 | B10: YARA - RIO GRANDE | C10: 92.660.604/0013-16 | D10: 1800 | E10: 1246087936 | F10: 45112 | H10: 1 | I10: Adtives | J10: 1246087936 | K10: 45097 | L10: 3041000 | M10: FRETES DIVERSOS | N10: 46 | O10: FINANCEIRO GERAL | P10: GRUPO YARA | Q10: =$Q$1-F10 -> 1085
A11: 1159 | B11: YARA - RIO GRANDE | C11: 92.660.604/0013-16 | D11: 2700 | E11: 1246087941 | F11: 45112 | H11: 1 | I11: Adtives | J11: 1246087941 | K11: 45097 | L11: 3041000 | M11: FRETES DIVERSOS | N11: 46 | O11: FINANCEIRO GERAL | P11: GRUPO YARA | Q11: =$Q$1-F11 -> 1085
A12: 1159 | B12: YARA - RIO GRANDE | C12: 92.660.604/0013-16 | D12: 1800 | E12: 1246087939 | F12: 45112 | H12: 1 | I12: Adtives | J12: 1246087939 | K12: 45097 | L12: 3041000 | M12: FRETES DIVERSOS | N12: 46 | O12: FINANCEIRO GERAL | P12: GRUPO YARA | Q12: =$Q$1-F12 -> 1085
A13: 1159 | B13: YARA - RIO GRANDE | C13: 92.660.604/0013-16 | D13: 1800 | E13: 1246087937 | F13: 45112 | H13: 1 | I13: Adtives | J13: 1246087937 | K13: 45097 | L13: 3041000 | M13: FRETES DIVERSOS | N13: 46 | O13: FINANCEIRO GERAL | P13: GRUPO YARA | Q13: =$Q$1-F13 -> 1085
A14: 1159 | B14: YARA - RIO GRANDE | C14: 92.660.604/0013-16 | D14: 1800 | E14: 1246087943 | F14: 45112 | H14: 1 | I14: Adtives | J14: 1246087943 | K14: 45097 | L14: 3041000 | M14: FRETES DIVERSOS | N14: 46 | O14: FINANCEIRO GERAL | P14: GRUPO YARA | Q14: =$Q$1-F14 -> 1085
... A49: 7022 | B49: STRATOS - ROSARIO DO CATETE | C49: 31.009.644/0001-74 | D49: 1800 | E49: 1246054442 | F49: 44897 | H49: 1 | I49: Adtives | J49: 1246054442 | K49: 44882 | L49: 3041000 | M49: FRETES DIVERSOS | N49: 46 | O49: FINANCEIRO GERAL | P49: STRATOS - ROSARIO DO CATETE | Q49: =$Q$1-F49 -> 1300
Q50: =$Q$1-F50 -> 46197
Q51: =$Q$1-F51 -> 46197
Q52: =$Q$1-F52 -> 46197
Q53: =$Q$1-F53 -> 46197
Q54: =$Q$1-F54 -> 46197

Sheet Data total
D1: =SUBTOTAL(9,D3:D1079) -> 64126237 | E1: ='Data Additive'!D1+'Data Fertilizers'!D1+'Data International'!D1 -> 63971254 | F1: ='Data Additive'!D1+'Data Fertilizers'!D1+'Data International'!D1+'freight debit notes'!D1 -> 64126237 | G1: =D1-F1 -> 0 | R1: 46197
A2: CODPARC | B2: NOMEPARC | C2: CNPJ | D2: Valor | E2: NUFIN | F2: DTVENC | G2: DHBAIXA | H2: AD_BU | I2: NOME_BU | J2: NUMNOTA | K2: DTENTSAI | L2: CODNAT | M2: DESCRNAT | N2: CODTIPOPER | O2: OPERACAO | P2: Grupo | Q2: Dias vencidos
A3: 1787 | B3: MOSAIC - UBERABA (CIU1) | C3: 33.931.486/0014-55 | D3: 3600 | E3: 1246031589 | F3: 44784 | H3: 1 | I3: Adtives | J3: 1246031589 | K3: 44769 | L3: 3041000 | M3: FRETES DIVERSOS | N3: 46 | O3: FINANCEIRO GERAL | P3: GRUPO MOSAIC FERTILIZANTES P K LTDA | Q3: =$R$1-F3 -> 1413 | R3: =_xlfn.XLOOKUP(E3,'Data Additive'!E:E,'Data Additive'!E:E,0) -> 0
A4: 1787 | B4: MOSAIC - UBERABA (CIU1) | C4: 33.931.486/0014-55 | D4: 2700 | E4: 1246055596 | F4: 44889 | H4: 1 | I4: Adtives | J4: 1246055596 | K4: 44889 | L4: 3041000 | M4: FRETES DIVERSOS | N4: 46 | O4: FINANCEIRO GERAL | P4: GRUPO MOSAIC FERTILIZANTES P K LTDA | Q4: =$R$1-F4 -> 1308 | R4: =_xlfn.XLOOKUP(E4,'Data Additive'!E:E,'Data Additive'!E:E,0) -> 0
A5: 1788 | B5: MOSAIC - UBERABA (CIU2) | C5: 33.931.486/0021-84 | D5: 5400 | E5: 1246055599 | F5: 44889 | H5: 1 | I5: Adtives | J5: 1246055599 | K5: 44889 | L5: 3041000 | M5: FRETES DIVERSOS | N5: 46 | O5: FINANCEIRO GERAL | P5: GRUPO MOSAIC FERTILIZANTES P K LTDA | Q5: =$R$1-F5 -> 1308 | R5: =_xlfn.XLOOKUP(E5,'Data Additive'!E:E,'Data Additive'!E:E,0) -> 0
A6: 1788 | B6: MOSAIC - UBERABA (CIU2) | C6: 33.931.486/0021-84 | D6: 1200 | E6: 1246190701 | F6: 45674 | H6: 1 | I6: Adtives | J6: 1246190701 | K6: 45659 | L6: 3041000 | M6: FRETES DIVERSOS | N6: 46 | O6: FINANCEIRO GERAL | P6: GRUPO MOSAIC FERTILIZANTES P K LTDA | Q6: =$R$1-F6 -> 523 | R6: =_xlfn.XLOOKUP(E6,'Data Additive'!E:E,'Data Additive'!E:E,0) -> 0
A7: 1789 | B7: MOSAIC - ARAXA (CMA) | C7: 33.931.486/0019-60 | D7: 2700 | E7: 1246120461 | F7: 45294 | H7: 1 | I7: Adtives | J7: 191223 | K7: 45279 | L7: 3041000 | M7: FRETES DIVERSOS | N7: 46 | O7: FINANCEIRO GERAL | P7: GRUPO MOSAIC FERTILIZANTES P K LTDA | Q7: =$R$1-F7 -> 903 | R7: =_xlfn.XLOOKUP(E7,'Data Additive'!E:E,'Data Additive'!E:E,0) -> 0
A8: 1789 | B8: MOSAIC - ARAXA (CMA) | C8: 33.931.486/0019-60 | D8: 900 | E8: 1246146095 | F8: 45428 | H8: 1 | I8: Adtives | J8: 1246120461 | K8: 45428 | L8: 3041000 | M8: FRETES DIVERSOS | N8: 46 | O8: FINANCEIRO GERAL | P8: GRUPO MOSAIC FERTILIZANTES P K LTDA | Q8: =$R$1-F8 -> 769 | R8: =_xlfn.XLOOKUP(E8,'Data Additive'!E:E,'Data Additive'!E:E,0) -> 0
A9: 43 | B9: CIBRA - CAMACARI | C9: 00.117.842/0001-28 | D9: 2400 | E9: 1246271921 | F9: 46147 | H9: 1 | I9: Adtives | J9: 1246271921 | K9: 46132 | L9: 3042200 | M9: DIÁRIAS E ESTADIA DE MOTORISTAS | N9: 46 | O9: FINANCEIRO GERAL | P9: GRUPO CIBRA | Q9: =$R$1-F9 -> 50 | R9: =_xlfn.XLOOKUP(E9,'Data Additive'!E:E,'Data Additive'!E:E,0) -> 0
A10: 1159 | B10: YARA - RIO GRANDE | C10: 92.660.604/0013-16 | D10: 1800 | E10: 1246087936 | F10: 45112 | H10: 1 | I10: Adtives | J10: 1246087936 | K10: 45097 | L10: 3041000 | M10: FRETES DIVERSOS | N10: 46 | O10: FINANCEIRO GERAL | P10: GRUPO YARA | Q10: =$R$1-F10 -> 1085 | R10: =_xlfn.XLOOKUP(E10,'Data Additive'!E:E,'Data Additive'!E:E,0) -> 0
A11: 1159 | B11: YARA - RIO GRANDE | C11: 92.660.604/0013-16 | D11: 2700 | E11: 1246087941 | F11: 45112 | H11: 1 | I11: Adtives | J11: 1246087941 | K11: 45097 | L11: 3041000 | M11: FRETES DIVERSOS | N11: 46 | O11: FINANCEIRO GERAL | P11: GRUPO YARA | Q11: =$R$1-F11 -> 1085 | R11: =_xlfn.XLOOKUP(E11,'Data Additive'!E:E,'Data Additive'!E:E,0) -> 0
A12: 1159 | B12: YARA - RIO GRANDE | C12: 92.660.604/0013-16 | D12: 1800 | E12: 1246087939 | F12: 45112 | H12: 1 | I12: Adtives | J12: 1246087939 | K12: 45097 | L12: 3041000 | M12: FRETES DIVERSOS | N12: 46 | O12: FINANCEIRO GERAL | P12: GRUPO YARA | Q12: =$R$1-F12 -> 1085 | R12: =_xlfn.XLOOKUP(E12,'Data Additive'!E:E,'Data Additive'!E:E,0) -> 0
A13: 1159 | B13: YARA - RIO GRANDE | C13: 92.660.604/0013-16 | D13: 1800 | E13: 1246087937 | F13: 45112 | H13: 1 | I13: Adtives | J13: 1246087937 | K13: 45097 | L13: 3041000 | M13: FRETES DIVERSOS | N13: 46 | O13: FINANCEIRO GERAL | P13: GRUPO YARA | Q13: =$R$1-F13 -> 1085 | R13: =_xlfn.XLOOKUP(E13,'Data Additive'!E:E,'Data Additive'!E:E,0) -> 0
A14: 1159 | B14: YARA - RIO GRANDE | C14: 92.660.604/0013-16 | D14: 1800 | E14: 1246087943 | F14: 45112 | H14: 1 | I14: Adtives | J14: 1246087943 | K14: 45097 | L14: 3041000 | M14: FRETES DIVERSOS | N14: 46 | O14: FINANCEIRO GERAL | P14: GRUPO YARA | Q14: =$R$1-F14 -> 1085 | R14: =_xlfn.XLOOKUP(E14,'Data Additive'!E:E,'Data Additive'!E:E,0) -> 0
... A327: 7022 | B327: STRATOS - ROSARIO DO CATETE | C327: 31.009.644/0001-74 | D327: 1800 | E327: 1246054442 | F327: 44897 | H327: 1 | I327: Adtives | J327: 1246054442 | K327: 44882 | L327: 3041000 | M327: FRETES DIVERSOS | N327: 46 | O327: FINANCEIRO GERAL | P327: STRATOS - ROSARIO DO CATETE | Q327: =$R$1-F327 -> 1300 | R327: =_xlfn.XLOOKUP(E327,'Data Additive'!E:E,'Data Additive'!E:E,0) -> 0
A328: 16189 | B328: ARSLOG SOLUCOES EM TRANSPORTE | C328: 05.765.626/0001-02 | D328: 49440 | E328: 1246261824 | F328: 46087 | I328: Não encontrado | J328: 1246261824 | K328: 46055 | L328: 7240000 | M328: PERDA DE MERCADORIA COM SINISTRO | N328: 46 | O328: FINANCEIRO GERAL | P328: ARSLOG SOLUCOES EM TRANSPORTE | Q328: =$R$1-F328 -> 110 | R328: =_xlfn.XLOOKUP(E328,'Data Additive'!E:E,'Data Additive'!E:E,0) -> 1246261824
A329: 7 | B329: START QUIMICA - 22.685.341/0006-95 | C329: 22.685.341/0006-95 | D329: 861.6 | E329: 1246278022 | F329: 46211 | H329: 2 | I329: Fertilizers | J329: 2996 | K329: 46176 | L329: 1010100 | M329: VENDAS MERCADO INTERNO | N329: 39 | O329: REVENDA - NFE | P329: START QUIMICA - 22.685.341/0006-95 | Q329: =$R$1-F329 -> -14 | R329: =_xlfn.XLOOKUP(E329,'Data Additive'!E:E,'Data Additive'!E:E,0) -> 0
A330: 3297 | B330: MACROSOURCE PERU S.R.L. | C330: ..- | D330: 49956.68 | E330: 1246271355 | F330: 46200 | H330: 1 | I330: Adtives | J330: 11123 | K330: 46126 | L330: 1010200 | M330: VENDAS MERCADO EXTERNO | N330: 40 | O330: VENDA - NFE (EXPORTAÇÃO) | P330: MACROSOURCE PERU S.R.L. | Q330: =$R$1-F330 -> -3 | R330: =_xlfn.XLOOKUP(E330,'Data Additive'!E:E,'Data Additive'!E:E,0) -> 0
A331: 2680 | B331: FERMAGRI S.A - EQUADOR | C331: ..- | D331: 175275.24 | E331: 1246272069 | F331: 46194 | H331: 1 | I331: Adtives | J331: 11191 | K331: 46134 | L331: 1010200 | M331: VENDAS MERCADO EXTERNO | N331: 40 | O331: VENDA - NFE (EXPORTAÇÃO) | P331: FERMAGRI S.A - EQUADOR | Q331: =$R$1-F331 -> 3 | R331: =_xlfn.XLOOKUP(E331,'Data Additive'!E:E,'Data Additive'!E:E,0) -> 0
A332: 2696 | B332: MOSAIC FERTILIZANTES PARAGUAY S.R.L. | C332: ..- | D332: 94148.95 | E332: 1246279520 | F332: 46278 | H332: 1 | I332: Adtives | J332: 11712 | K332: 46188 | L332: 1010200 | M332: VENDAS MERCADO EXTERNO | N332: 40 | O332: VENDA - NFE (EXPORTAÇÃO) | P332: MOSAIC FERTILIZANTES PARAGUAY S.R.L. | Q332: =$R$1-F332 -> -81 | R332: =_xlfn.XLOOKUP(E332,'Data Additive'!E:E,'Data Additive'!E:E,0) -> 0
A333: 2696 | B333: MOSAIC FERTILIZANTES PARAGUAY S.R.L. | C333: ..- | D333: 91784.41 | E333: 1246274791 | F333: 46245 | H333: 1 | I333: Adtives | J333: 11378 | K333: 46155 | L333: 1010200 | M333: VENDAS MERCADO EXTERNO | N333: 40 | O333: VENDA - NFE (EXPORTAÇÃO) | P333: MOSAIC FERTILIZANTES PARAGUAY S.R.L. | Q333: =$R$1-F333 -> -48 | R333: =_xlfn.XLOOKUP(E333,'Data Additive'!E:E,'Data Additive'!E:E,0) -> 0
A334: 2696 | B334: MOSAIC FERTILIZANTES PARAGUAY S.R.L. | C334: ..- | D334: 118833.22 | E334: 1246278569 | F334: 46271 | H334: 1 | I334: Adtives | J334: 11641 | K334: 46181 | L334: 1010200 | M334: VENDAS MERCADO EXTERNO | N334: 40 | O334: VENDA - NFE (EXPORTAÇÃO) | P334: MOSAIC FERTILIZANTES PARAGUAY S.R.L. | Q334: =$R$1-F334 -> -74 | R334: =_xlfn.XLOOKUP(E334,'Data Additive'!E:E,'Data Additive'!E:E,0) -> 0
A335: 2696 | B335: MOSAIC FERTILIZANTES PARAGUAY S.R.L. | C335: ..- | D335: 116719.31 | E335: 1246277374 | F335: 46261 | H335: 1 | I335: Adtives | J335: 11551 | K335: 46171 | L335: 1010200 | M335: VENDAS MERCADO EXTERNO | N335: 40 | O335: VENDA - NFE (EXPORTAÇÃO) | P335: MOSAIC FERTILIZANTES PARAGUAY S.R.L. | Q335: =$R$1-F335 -> -64 | R335: =_xlfn.XLOOKUP(E335,'Data Additive'!E:E,'Data Additive'!E:E,0) -> 0
A336: 2696 | B336: MOSAIC FERTILIZANTES PARAGUAY S.R.L. | C336: ..- | D336: 116211.91 | E336: 1246278291 | F336: 46268 | H336: 1 | I336: Adtives | J336: 11599 | K336: 46178 | L336: 1010200 | M336: VENDAS MERCADO EXTERNO | N336: 40 | O336: VENDA - NFE (EXPORTAÇÃO) | P336: MOSAIC FERTILIZANTES PARAGUAY S.R.L. | Q336: =$R$1-F336 -> -71 | R336: =_xlfn.XLOOKUP(E336,'Data Additive'!E:E,'Data Additive'!E:E,0) -> 0
A337: 2645 | B337: ANAGRA - CHILE | C337: ..- | D337: 143222.74 | E337: 1246277225 | F337: 46200 | H337: 1 | I337: Adtives | J337: 11529 | K337: 46170 | L337: 1010200 | M337: VENDAS MERCADO EXTERNO | N337: 40 | O337: VENDA - NFE (EXPORTAÇÃO) | P337: ANAGRA - CHILE | Q337: =$R$1-F337 -> -3 | R337: =_xlfn.XLOOKUP(E337,'Data Additive'!E:E,'Data Additive'!E:E,0) -> 0
A338: 2651 | B338: AGROBROKERS - COLÔMBIA | C338: ..- | D338: 132309.33 | E338: 1246278533 | F338: 46241 | H338: 1 | I338: Adtives | J338: 3002 | K338: 46181 | L338: 1010200 | M338: VENDAS MERCADO EXTERNO | N338: 40 | O338: VENDA - NFE (EXPORTAÇÃO) | P338: AGROBROKERS - COLÔMBIA | Q338: =$R$1-F338 -> -44 | R338: =_xlfn.XLOOKUP(E338,'Data Additive'!E:E,'Data Additive'!E:E,0) -> 0
A339: 2652 | B339: FERTIMAX PARAGUAY | C339: ..- | D339: 166161.39 | E339: 1246279339 | F339: 46215 | H339: 1 | I339: Adtives | J339: 11691 | K339: 46185 | L339: 1010200 | M339: VENDAS MERCADO EXTERNO | N339: 40 | O339: VENDA - NFE (EXPORTAÇÃO) | P339: FERTIMAX PARAGUAY | Q339: =$R$1-F339 -> -18 | R339: =_xlfn.XLOOKUP(E339,'Data Additive'!E:E,'Data Additive'!E:E,0) -> 0
A340: 2287 | B340: BUNGE PARAGUAY S.A | C340: 99.999.999/9999-99 | D340: 152321.99 | E340: 1246279865 | F340: 46220 | H340: 1 | I340: Adtives | J340: 11738 | K340: 46190 | L340: 1010200 | M340: VENDAS MERCADO EXTERNO | N340: 40 | O340: VENDA - NFE (EXPORTAÇÃO) | P340: BUNGE PARAGUAY S.A | Q340: =$R$1-F340 -> -23 | R340: =_xlfn.XLOOKUP(E340,'Data Additive'!E:E,'Data Additive'!E:E,0) -> 0
... A359: 12031 | B359: EVOAGRO NUTRICION S.A.S - COLOMBIA | C359: ..- | D359: 164297.05 | E359: 1246275610 | F359: 46220 | H359: 1 | I359: Adtives | J359: 2948 | K359: 46160 | L359: 1010200 | M359: VENDAS MERCADO EXTERNO | N359: 40 | O359: VENDA - NFE (EXPORTAÇÃO) | P359: EVOAGRO NUTRICION S.A.S - COLOMBIA | Q359: =$R$1-F359 -> -23 | R359: =_xlfn.XLOOKUP(E359,'Data Additive'!E:E,'Data Additive'!E:E,0) -> 0
A360: 13330 | B360: ORGANITEC - PARAGUAY | C360: 800.909.976- | D360: 853.24 | E360: 1246272264 | F360: 46148 | I360: Não encontrado | J360: 11057 | K360: 46118 | L360: 1010200 | M360: VENDAS MERCADO EXTERNO | N360: 40 | O360: VENDA - NFE (EXPORTAÇÃO) | P360: ORGANITEC - PARAGUAY | Q360: =$R$1-F360 -> 49 | R360: =_xlfn.XLOOKUP(E360,'Data Additive'!E:E,'Data Additive'!E:E,0) -> 0
A361: 13330 | B361: ORGANITEC - PARAGUAY | C361: 800.909.976- | D361: 527.28 | E361: 1246238356 | F361: 45927 | I361: Não encontrado | J361: 9092 | K361: 45897 | L361: 1010200 | M361: VENDAS MERCADO EXTERNO | N361: 40 | O361: VENDA - NFE (EXPORTAÇÃO) | P361: ORGANITEC - PARAGUAY | Q361: =$R$1-F361 -> 270 | R361: =_xlfn.XLOOKUP(E361,'Data Additive'!E:E,'Data Additive'!E:E,0) -> 0
A362: 15543 | B362: GOTLAND EQUADOR (SOLINAG) | C362: 19.512.950/9001- | D362: 45718.46 | E362: 1246264533 | F362: 46181 | H362: 1 | I362: Adtives | J362: 10745 | K362: 46076 | L362: 1010200 | M362: VENDAS MERCADO EXTERNO | N362: 40 | O362: VENDA - NFE (EXPORTAÇÃO) | P362: GOTLAND EQUADOR (SOLINAG) | Q362: =$R$1-F362 -> 16 | R362: =_xlfn.XLOOKUP(E362,'Data Additive'!E:E,'Data Additive'!E:E,0) -> 0
A363: 15543 | B363: GOTLAND EQUADOR (SOLINAG) | C363: 19.512.950/9001- | D363: 133756.12 | E363: 1246277124 | F363: 46259 | H363: 1 | I363: Adtives | J363: 11522 | K363: 46169 | L363: 1010200 | M363: VENDAS MERCADO EXTERNO | N363: 40 | O363: VENDA - NFE (EXPORTAÇÃO) | P363: GOTLAND EQUADOR (SOLINAG) | Q363: =$R$1-F363 -> -62 | R363: =_xlfn.XLOOKUP(E363,'Data Additive'!E:E,'Data Additive'!E:E,0) -> 0
A364: 7060 | B364: AGROVIVA | C364: 19.195.655/0001-90 | D364: 202489.44 | E364: 1246233024 | F364: 46264 | H364: 2 | I364: Fertilizers | J364: 9046 | K364: 45895 | L364: 1010100 | M364: VENDAS MERCADO INTERNO | N364: 56 | O364: VENDA A ORDEM | P364: AGROVIVA | Q364: =$R$1-F364 -> -67 | R364: =_xlfn.XLOOKUP(E364,'Data Additive'!E:E,'Data Additive'!E:E,0) -> 0
A365: 7060 | B365: AGROVIVA | C365: 19.195.655/0001-90 | D365: 210926.5 | E365: 1246232491 | F365: 46264 | H365: 2 | I365: Fertilizers | J365: 9006 | K365: 45891 | L365: 1010100 | M365: VENDAS MERCADO INTERNO | N365: 56 | O365: VENDA A ORDEM | P365: AGROVIVA | Q365: =$R$1-F365 -> -67 | R365: =_xlfn.XLOOKUP(E365,'Data Additive'!E:E,'Data Additive'!E:E,0) -> 0
A366: 7060 | B366: AGROVIVA | C366: 19.195.655/0001-90 | D366: 135891.48 | E366: 1246233319 | F366: 46266 | H366: 2 | I366: Fertilizers | J366: 9076 | K366: 45896 | L366: 1010100 | M366: VENDAS MERCADO INTERNO | N366: 56 | O366: VENDA A ORDEM | P366: AGROVIVA | Q366: =$R$1-F366 -> -69 | R366: =_xlfn.XLOOKUP(E366,'Data Additive'!E:E,'Data Additive'!E:E,0) -> 0
A367: 7060 | B367: AGROVIVA | C367: 19.195.655/0001-90 | D367: 160304.14 | E367: 1246232724 | F367: 46264 | H367: 2 | I367: Fertilizers | J367: 9023 | K367: 45894 | L367: 1010100 | M367: VENDAS MERCADO INTERNO | N367: 56 | O367: VENDA A ORDEM | P367: AGROVIVA | Q367: =$R$1-F367 -> -67 | R367: =_xlfn.XLOOKUP(E367,'Data Additive'!E:E,'Data Additive'!E:E,0) -> 0
A368: 7060 | B368: AGROVIVA | C368: 19.195.655/0001-90 | D368: 134992.96 | E368: 1246233318 | F368: 46265 | H368: 2 | I368: Fertilizers | J368: 9075 | K368: 45896 | L368: 1010100 | M368: VENDAS MERCADO INTERNO | N368: 56 | O368: VENDA A ORDEM | P368: AGROVIVA | Q368: =$R$1-F368 -> -68 | R368: =_xlfn.XLOOKUP(E368,'Data Additive'!E:E,'Data Additive'!E:E,0) -> 0
A369: 10413 | B369: BUNGE - SANTOS | C369: 84.046.101/0542-85 | D369: 78993 | E369: 1246279827 | F369: 46218 | H369: 1 | I369: Adtives | J369: 11733 | K369: 46189 | L369: 1010100 | M369: VENDAS MERCADO INTERNO | N369: 56 | O369: VENDA A ORDEM | P369: BUNGE - SANTOS | Q369: =$R$1-F369 -> -21 | R369: =_xlfn.XLOOKUP(E369,'Data Additive'!E:E,'Data Additive'!E:E,0) -> 1246279827
A370: 10413 | B370: BUNGE - SANTOS | C370: 84.046.101/0542-85 | D370: 79019.2 | E370: 1246278424 | F370: 46218 | H370: 1 | I370: Adtives | J370: 11626 | K370: 46178 | L370: 1010100 | M370: VENDAS MERCADO INTERNO | N370: 56 | O370: VENDA A ORDEM | P370: BUNGE - SANTOS | Q370: =$R$1-F370 -> -21 | R370: =_xlfn.XLOOKUP(E370,'Data Additive'!E:E,'Data Additive'!E:E,0) -> 1246278424
...

Sheet Data Additive
D1: =SUBTOTAL(9,$D$3:$D$863) -> 31818331 | R1: 46197
A2: CODPARC | B2: NOMEPARC | C2: CNPJ | D2: Valor | E2: NUFIN | F2: DTVENC | G2: DHBAIXA | H2: AD_BU | I2: NOME_BU | J2: NUMNOTA | K2: DTENTSAI | L2: CODNAT | M2: DESCRNAT | N2: CODTIPOPER | O2: OPERACAO | P2: Grupo | Q2: Dias vencidos
A3: 1257 | B3: MOSAIC - CAMPO GRANDE | C3: 61.156.501/0081-30 | D3: 1980.8 | E3: 1246032946 | F3: 44774 | H3: 1 | I3: Adtives | J3: 17935 | K3: 44714 | L3: 1010100 | M3: VENDAS MERCADO INTERNO | N3: 56 | O3: VENDA A ORDEM | P3: GRUPO MOSAIC FERTILIZANTES DO BRASIL | Q3: =$R$1-F3 -> 1423 | R3: =_xlfn.XLOOKUP(P3,'Painel Additive'!$B:$B,'Painel Additive'!$B:$B,0) -> GRUPO MOSAIC FERTILIZANTES DO BRASIL | S3: =F3-K3 -> 60
A4: 1936 | B4: CIBRA - PARANAGUÁ II | C4: 95.865.572/0024-36 | D4: 40300 | E4: 1246280425 | F4: 46223 | H4: 1 | I4: Adtives | J4: 11779 | K4: 46195 | L4: 1010100 | M4: VENDAS MERCADO INTERNO | N4: 56 | O4: VENDA A ORDEM | P4: GRUPO AGRO INDUSTRIAL SAO LUIZ LTDA | Q4: =$R$1-F4 -> -26 | R4: =_xlfn.XLOOKUP(P4,'Painel Additive'!$B:$B,'Painel Additive'!$B:$B,0) -> GRUPO AGRO INDUSTRIAL SAO LUIZ LTDA | S4: =F4-K4 -> 28
A5: 1936 | B5: CIBRA - PARANAGUÁ II | C5: 95.865.572/0024-36 | D5: 40300 | E5: 1246278386 | F5: 46206 | H5: 1 | I5: Adtives | J5: 11615 | K5: 46178 | L5: 1010100 | M5: VENDAS MERCADO INTERNO | N5: 56 | O5: VENDA A ORDEM | P5: GRUPO AGRO INDUSTRIAL SAO LUIZ LTDA | Q5: =$R$1-F5 -> -9 | R5: =_xlfn.XLOOKUP(P5,'Painel Additive'!$B:$B,'Painel Additive'!$B:$B,0) -> GRUPO AGRO INDUSTRIAL SAO LUIZ LTDA | S5: =F5-K5 -> 28
A6: 2603 | B6: MOSAIC - SÃO LUIS | C6: 61.156.501/0100-38 | D6: 4522.16 | E6: 1246097965 | F6: 45152 | H6: 1 | I6: Adtives | J6: 21713 | K6: 45092 | L6: 1010100 | M6: VENDAS MERCADO INTERNO | N6: 56 | O6: VENDA A ORDEM | P6: GRUPO MOSAIC FERTILIZANTES DO BRASIL | Q6: =$R$1-F6 -> 1045 | R6: =_xlfn.XLOOKUP(P6,'Painel Additive'!$B:$B,'Painel Additive'!$B:$B,0) -> GRUPO MOSAIC FERTILIZANTES DO BRASIL | S6: =F6-K6 -> 60
A7: 2603 | B7: MOSAIC - SÃO LUIS | C7: 61.156.501/0100-38 | D7: 241850 | E7: 1246273467 | F7: 46236 | H7: 1 | I7: Adtives | J7: 2903 | K7: 46146 | L7: 1010100 | M7: VENDAS MERCADO INTERNO | N7: 56 | O7: VENDA A ORDEM | P7: GRUPO MOSAIC FERTILIZANTES DO BRASIL | Q7: =$R$1-F7 -> -39 | R7: =_xlfn.XLOOKUP(P7,'Painel Additive'!$B:$B,'Painel Additive'!$B:$B,0) -> GRUPO MOSAIC FERTILIZANTES DO BRASIL | S7: =F7-K7 -> 90
A8: 6124 | B8: MOSAIC - UBERABA (UBA III) | C8: 61.156.501/0110-00 | D8: 384000 | E8: 1246277044 | F8: 46259 | H8: 1 | I8: Adtives | J8: 2971 | K8: 46169 | L8: 1010100 | M8: VENDAS MERCADO INTERNO | N8: 56 | O8: VENDA A ORDEM | P8: GRUPO MOSAIC FERTILIZANTES DO BRASIL | Q8: =$R$1-F8 -> -62 | R8: =_xlfn.XLOOKUP(P8,'Painel Additive'!$B:$B,'Painel Additive'!$B:$B,0) -> GRUPO MOSAIC FERTILIZANTES DO BRASIL | S8: =F8-K8 -> 90
A9: 6124 | B9: MOSAIC - UBERABA (UBA III) | C9: 61.156.501/0110-00 | D9: 384000 | E9: 1246279317 | F9: 46275 | H9: 1 | I9: Adtives | J9: 3012 | K9: 46185 | L9: 1010100 | M9: VENDAS MERCADO INTERNO | N9: 56 | O9: VENDA A ORDEM | P9: GRUPO MOSAIC FERTILIZANTES DO BRASIL | Q9: =$R$1-F9 -> -78 | R9: =_xlfn.XLOOKUP(P9,'Painel Additive'!$B:$B,'Painel Additive'!$B:$B,0) -> GRUPO MOSAIC FERTILIZANTES DO BRASIL | S9: =F9-K9 -> 90
A10: 7479 | B10: MOSAIC - CUBATÃO | C10: 61.156.501/0099-60 | D10: 167211.9 | E10: 1246274162 | F10: 46240 | H10: 1 | I10: Adtives | J10: 11335 | K10: 46150 | L10: 1010100 | M10: VENDAS MERCADO INTERNO | N10: 56 | O10: VENDA A ORDEM | P10: GRUPO MOSAIC FERTILIZANTES DO BRASIL | Q10: =$R$1-F10 -> -43 | R10: =_xlfn.XLOOKUP(P10,'Painel Additive'!$B:$B,'Painel Additive'!$B:$B,0) -> GRUPO MOSAIC FERTILIZANTES DO BRASIL | S10: =F10-K10 -> 90
A11: 7479 | B11: MOSAIC - CUBATÃO | C11: 61.156.501/0099-60 | D11: 768000 | E11: 1246280565 | F11: 46286 | H11: 1 | I11: Adtives | J11: 3029 | K11: 46196 | L11: 1010100 | M11: VENDAS MERCADO INTERNO | N11: 56 | O11: VENDA A ORDEM | P11: GRUPO MOSAIC FERTILIZANTES DO BRASIL | Q11: =$R$1-F11 -> -89 | R11: =_xlfn.XLOOKUP(P11,'Painel Additive'!$B:$B,'Painel Additive'!$B:$B,0) -> GRUPO MOSAIC FERTILIZANTES DO BRASIL | S11: =F11-K11 -> 90
A12: 7479 | B12: MOSAIC - CUBATÃO | C12: 61.156.501/0099-60 | D12: 64239.64 | E12: 1246275302 | F12: 46247 | H12: 1 | I12: Adtives | J12: 11401 | K12: 46157 | L12: 1010100 | M12: VENDAS MERCADO INTERNO | N12: 56 | O12: VENDA A ORDEM | P12: GRUPO MOSAIC FERTILIZANTES DO BRASIL | Q12: =$R$1-F12 -> -50 | R12: =_xlfn.XLOOKUP(P12,'Painel Additive'!$B:$B,'Painel Additive'!$B:$B,0) -> GRUPO MOSAIC FERTILIZANTES DO BRASIL | S12: =F12-K12 -> 90
A13: 7479 | B13: MOSAIC - CUBATÃO | C13: 61.156.501/0099-60 | D13: 384000 | E13: 1246277126 | F13: 46259 | H13: 1 | I13: Adtives | J13: 2974 | K13: 46169 | L13: 1010100 | M13: VENDAS MERCADO INTERNO | N13: 56 | O13: VENDA A ORDEM | P13: GRUPO MOSAIC FERTILIZANTES DO BRASIL | Q13: =$R$1-F13 -> -62 | R13: =_xlfn.XLOOKUP(P13,'Painel Additive'!$B:$B,'Painel Additive'!$B:$B,0) -> GRUPO MOSAIC FERTILIZANTES DO BRASIL | S13: =F13-K13 -> 90
A14: 7302 | B14: MOSAIC - PARANAGUA I | C14: 61.156.501/0080-50 | D14: 61000 | E14: 1246278404 | F14: 46268 | H14: 1 | I14: Adtives | J14: 11618 | K14: 46178 | L14: 1010100 | M14: VENDAS MERCADO INTERNO | N14: 56 | O14: VENDA A ORDEM | P14: GRUPO MOSAIC FERTILIZANTES DO BRASIL | Q14: =$R$1-F14 -> -71 | R14: =_xlfn.XLOOKUP(P14,'Painel Additive'!$B:$B,'Painel Additive'!$B:$B,0) -> GRUPO MOSAIC FERTILIZANTES DO BRASIL | S14: =F14-K14 -> 90
... A190: 6477 | B190: MOSAIC - PARANAGUA II | C190: 61.156.501/0109-76 | D190: 184525 | E190: 1246275783 | F190: 46251 | H190: 1 | I190: Adtives | J190: 11440 | K190: 46161 | L190: 1010100 | M190: VENDAS MERCADO INTERNO | N190: 161 | O190: VENDA PROD. INDUSTRIALIZADO - NFE | P190: GRUPO MOSAIC FERTILIZANTES DO BRASIL | Q190: =$R$1-F190 -> -54 | R190: =_xlfn.XLOOKUP(P190,'Painel Additive'!$B:$B,'Painel Additive'!$B:$B,0) -> GRUPO MOSAIC FERTILIZANTES DO BRASIL | S190: =F190-K190 -> 90
A191: 6477 | B191: MOSAIC - PARANAGUA II | C191: 61.156.501/0109-76 | D191: 185135 | E191: 1246276345 | F191: 46254 | H191: 1 | I191: Adtives | J191: 11476 | K191: 46164 | L191: 1010100 | M191: VENDAS MERCADO INTERNO | N191: 161 | O191: VENDA PROD. INDUSTRIALIZADO - NFE | P191: GRUPO MOSAIC FERTILIZANTES DO BRASIL | Q191: =$R$1-F191 -> -57 | R191: =_xlfn.XLOOKUP(P191,'Painel Additive'!$B:$B,'Painel Additive'!$B:$B,0) -> GRUPO MOSAIC FERTILIZANTES DO BRASIL | S191: =F191-K191 -> 90 | T191: =F191-$R$1 -> 57
A192: 6477 | B192: MOSAIC - PARANAGUA II | C192: 61.156.501/0109-76 | D192: 122000 | E192: 1246280250 | F192: 46282 | H192: 1 | I192: Adtives | J192: 11762 | K192: 46192 | L192: 1010100 | M192: VENDAS MERCADO INTERNO | N192: 161 | O192: VENDA PROD. INDUSTRIALIZADO - NFE | P192: GRUPO MOSAIC FERTILIZANTES DO BRASIL | Q192: =$R$1-F192 -> -85 | R192: =_xlfn.XLOOKUP(P192,'Painel Additive'!$B:$B,'Painel Additive'!$B:$B,0) -> GRUPO MOSAIC FERTILIZANTES DO BRASIL | S192: =F192-K192 -> 90 | T192: =F192-$R$1 -> 85
A193: 6477 | B193: MOSAIC - PARANAGUA II | C193: 61.156.501/0109-76 | D193: 35057.43 | E193: 1246277377 | F193: 46261 | H193: 1 | I193: Adtives | J193: 11552 | K193: 46171 | L193: 1010100 | M193: VENDAS MERCADO INTERNO | N193: 161 | O193: VENDA PROD. INDUSTRIALIZADO - NFE | P193: GRUPO MOSAIC FERTILIZANTES DO BRASIL | Q193: =$R$1-F193 -> -64 | R193: =_xlfn.XLOOKUP(P193,'Painel Additive'!$B:$B,'Painel Additive'!$B:$B,0) -> GRUPO MOSAIC FERTILIZANTES DO BRASIL | S193: =F193-K193 -> 90 | T193: =F193-$R$1 -> 64
A194: 6477 | B194: MOSAIC - PARANAGUA II | C194: 61.156.501/0109-76 | D194: 34213.5 | E194: 1246274569 | F194: 46244 | H194: 1 | I194: Adtives | J194: 11361 | K194: 46154 | L194: 1010100 | M194: VENDAS MERCADO INTERNO | N194: 161 | O194: VENDA PROD. INDUSTRIALIZADO - NFE | P194: GRUPO MOSAIC FERTILIZANTES DO BRASIL | Q194: =$R$1-F194 -> -47 | R194: =_xlfn.XLOOKUP(P194,'Painel Additive'!$B:$B,'Painel Additive'!$B:$B,0) -> GRUPO MOSAIC FERTILIZANTES DO BRASIL | S194: =F194-K194 -> 90
A195: 6477 | B195: MOSAIC - PARANAGUA II | C195: 61.156.501/0109-76 | D195: 121878 | E195: 1246278399 | F195: 46268 | H195: 1 | I195: Adtives | J195: 11617 | K195: 46178 | L195: 1010100 | M195: VENDAS MERCADO INTERNO | N195: 161 | O195: VENDA PROD. INDUSTRIALIZADO - NFE | P195: GRUPO MOSAIC FERTILIZANTES DO BRASIL | Q195: =$R$1-F195 -> -71 | R195: =_xlfn.XLOOKUP(P195,'Painel Additive'!$B:$B,'Painel Additive'!$B:$B,0) -> GRUPO MOSAIC FERTILIZANTES DO BRASIL | S195: =F195-K195 -> 90
A196: 6477 | B196: MOSAIC - PARANAGUA II | C196: 61.156.501/0109-76 | D196: 68404.19 | E196: 1246280278 | F196: 46282 | H196: 1 | I196: Adtives | J196: 11769 | K196: 46192 | L196: 1010100 | M196: VENDAS MERCADO INTERNO | N196: 161 | O196: VENDA PROD. INDUSTRIALIZADO - NFE | P196: GRUPO MOSAIC FERTILIZANTES DO BRASIL | Q196: =$R$1-F196 -> -85 | R196: =_xlfn.XLOOKUP(P196,'Painel Additive'!$B:$B,'Painel Additive'!$B:$B,0) -> GRUPO MOSAIC FERTILIZANTES DO BRASIL | S196: =F196-K196 -> 90
A197: 6477 | B197: MOSAIC - PARANAGUA II | C197: 61.156.501/0109-76 | D197: 64184.53 | E197: 1246278952 | F197: 46273 | H197: 1 | I197: Adtives | J197: 11666 | K197: 46183 | L197: 1010100 | M197: VENDAS MERCADO INTERNO | N197: 161 | O197: VENDA PROD. INDUSTRIALIZADO - NFE | P197: GRUPO MOSAIC FERTILIZANTES DO BRASIL | Q197: =$R$1-F197 -> -76 | R197: =_xlfn.XLOOKUP(P197,'Painel Additive'!$B:$B,'Painel Additive'!$B:$B,0) -> GRUPO MOSAIC FERTILIZANTES DO BRASIL | S197: =F197-K197 -> 90
A198: 6477 | B198: MOSAIC - PARANAGUA II | C198: 61.156.501/0109-76 | D198: 183427 | E198: 1246273826 | F198: 46238 | H198: 1 | I198: Adtives | J198: 11314 | K198: 46148 | L198: 1010100 | M198: VENDAS MERCADO INTERNO | N198: 161 | O198: VENDA PROD. INDUSTRIALIZADO - NFE | P198: GRUPO MOSAIC FERTILIZANTES DO BRASIL | Q198: =$R$1-F198 -> -41 | R198: =_xlfn.XLOOKUP(P198,'Painel Additive'!$B:$B,'Painel Additive'!$B:$B,0) -> GRUPO MOSAIC FERTILIZANTES DO BRASIL | S198: =F198-K198 -> 90
A199: 6477 | B199: MOSAIC - PARANAGUA II | C199: 61.156.501/0109-76 | D199: 6302.6 | E199: 1246212732 | F199: 45682 | H199: 1 | I199: Adtives | J199: 6197 | K199: 45622 | L199: 1010100 | M199: VENDAS MERCADO INTERNO | N199: 161 | O199: VENDA PROD. INDUSTRIALIZADO - NFE | P199: GRUPO MOSAIC FERTILIZANTES DO BRASIL | Q199: =$R$1-F199 -> 515 | R199: =_xlfn.XLOOKUP(P199,'Painel Additive'!$B:$B,'Painel Additive'!$B:$B,0) -> GRUPO MOSAIC FERTILIZANTES DO BRASIL | S199: =F199-K199 -> 60
A200: 7097 | B200: MOSAIC - SÃO FRANCISCO SUL | C200: 61.156.501/0125-96 | D200: 174501 | E200: 1246279050 | F200: 46273 | H200: 1 | I200: Adtives | J200: 11673 | K200: 46183 | L200: 1010100 | M200: VENDAS MERCADO INTERNO | N200: 161 | O200: VENDA PROD. INDUSTRIALIZADO - NFE | P200: GRUPO MOSAIC FERTILIZANTES DO BRASIL | Q200: =$R$1-F200 -> -76 | R200: =_xlfn.XLOOKUP(P200,'Painel Additive'!$B:$B,'Painel Additive'!$B:$B,0) -> GRUPO MOSAIC FERTILIZANTES DO BRASIL | S200: =F200-K200 -> 90
A201: 7648 | B201: LOUIS DREYFUS - PARANAGUÁ | C201: 47.067.525/0221-87 | D201: 69092.1 | E201: 1246279181 | F201: 46219 | H201: 1 | I201: Adtives | J201: 11678 | K201: 46184 | L201: 1010100 | M201: VENDAS MERCADO INTERNO | N201: 161 | O201: VENDA PROD. INDUSTRIALIZADO - NFE | P201: GRUPO LOUIS DREYFUS | Q201: =$R$1-F201 -> -22 | R201: =_xlfn.XLOOKUP(P201,'Painel Additive'!$B:$B,'Painel Additive'!$B:$B,0) -> GRUPO LOUIS DREYFUS | S201: =F201-K201 -> 35
A202: 7024 | B202: MOSAIC - SORRISO | C202: 61.156.501/0092-93 | D202: 70855.2 | E202: 1246269662 | F202: 46201 | H202: 1 | I202: Adtives | J202: 11011 | K202: 46111 | L202: 1010100 | M202: VENDAS MERCADO INTERNO | N202: 161 | O202: VENDA PROD. INDUSTRIALIZADO - NFE | P202: GRUPO MOSAIC FERTILIZANTES DO BRASIL | Q202: =$R$1-F202 -> -4 | R202: =_xlfn.XLOOKUP(P202,'Painel Additive'!$B:$B,'Painel Additive'!$B:$B,0) -> GRUPO MOSAIC FERTILIZANTES DO BRASIL | S202: =F202-K202 -> 90
A203: 7024 | B203: MOSAIC - SORRISO | C203: 61.156.501/0092-93 | D203: 70849.5 | E203: 1246278281 | F203: 46268 | H203: 1 | I203: Adtives | J203: 11597 | K203: 46178 | L203: 1010100 | M203: VENDAS MERCADO INTERNO | N203: 161 | O203: VENDA PROD. INDUSTRIALIZADO - NFE | P203: GRUPO MOSAIC FERTILIZANTES DO BRASIL | Q203: =$R$1-F203 -> -71 | R203: =_xlfn.XLOOKUP(P203,'Painel Additive'!$B:$B,'Painel Additive'!$B:$B,0) -> GRUPO MOSAIC FERTILIZANTES DO BRASIL | S203: =F203-K203 -> 90
A204: 7024 | B204: MOSAIC - SORRISO | C204: 61.156.501/0092-93 | D204: 71323.2 | E204: 1246270943 | F204: 46212 | H204: 1 | I204: Adtives | J204: 11084 | K204: 46122 | L204: 1010100 | M204: VENDAS MERCADO INTERNO | N204: 161 | O204: VENDA PROD. INDUSTRIALIZADO - NFE | P204: GRUPO MOSAIC FERTILIZANTES DO BRASIL | Q204: =$R$1-F204 -> -15 | R204: =_xlfn.XLOOKUP(P204,'Painel Additive'!$B:$B,'Painel Additive'!$B:$B,0) -> GRUPO MOSAIC FERTILIZANTES DO BRASIL | S204: =F204-K204 -> 90
A205: 7024 | B205: MOSAIC - SORRISO | C205: 61.156.501/0092-93 | D205: 71038.43 | E205: 1246279215 | F205: 46274 | H205: 1 | I205: Adtives | J205: 11682 | K205: 46184 | L205: 1010100 | M205: VENDAS MERCADO INTERNO | N205: 161 | O205: VENDA PROD. INDUSTRIALIZADO - NFE | P205: GRUPO MOSAIC FERTILIZANTES DO BRASIL | Q205: =$R$1-F205 -> -77 | R205: =_xlfn.XLOOKUP(P205,'Painel Additive'!$B:$B,'Painel Additive'!$B:$B,0) -> GRUPO MOSAIC FERTILIZANTES DO BRASIL | S205: =F205-K205 -> 90
... A241: 16099 | B241: MOSAIC - PALMEIRANTE | C241: 61.156.501/0208-58 | D241: 88185.43 | E241: 1246280413 | F241: 46285 | H241: 1 | I241: Adtives | J241: 11775 | K241: 46195 | L241: 1010100 | M241: VENDAS MERCADO INTERNO | N241: 161 | O241: VENDA PROD. INDUSTRIALIZADO - NFE | P241: GRUPO MOSAIC FERTILIZANTES DO BRASIL | Q241: =$R$1-F241 -> -88 | R241: =_xlfn.XLOOKUP(P241,'Painel Additive'!$B:$B,'Painel Additive'!$B:$B,0) -> GRUPO MOSAIC FERTILIZANTES DO BRASIL | S241: =F241-K241 -> 90
A242: 16189 | B242: ARSLOG SOLUCOES EM TRANSPORTE | C242: 05.765.626/0001-02 | D242: 49440 | E242: 1246261824 | F242: 46087 | I242: Não encontrado | J242: 1246261824 | K242: 46055 | L242: 7240000 | M242: PERDA DE MERCADORIA COM SINISTRO | N242: 46 | O242: FINANCEIRO GERAL | P242: ARSLOG SOLUCOES EM TRANSPORTE | Q242: =$R$1-F242 -> 110 | R242: =_xlfn.XLOOKUP(P242,'Painel Additive'!$B:$B,'Painel Additive'!$B:$B,0) -> ARSLOG SOLUCOES EM TRANSPORTE | S242: =F242-K242 -> 32
A243: 10413 | B243: BUNGE - SANTOS | C243: 84.046.101/0542-85 | D243: 78993 | E243: 1246279827 | F243: 46218 | H243: 1 | I243: Adtives | J243: 11733 | K243: 46189 | L243: 1010100 | M243: VENDAS MERCADO INTERNO | N243: 56 | O243: VENDA A ORDEM | P243: BUNGE - SANTOS | Q243: =$R$1-F243 -> -21 | R243: =_xlfn.XLOOKUP(P243,'Painel Additive'!$B:$B,'Painel Additive'!$B:$B,0) -> BUNGE - SANTOS | S243: =F243-K243 -> 29
A244: 10413 | B244: BUNGE - SANTOS | C244: 84.046.101/0542-85 | D244: 79019.2 | E244: 1246278424 | F244: 46218 | H244: 1 | I244: Adtives | J244: 11626 | K244: 46178 | L244: 1010100 | M244: VENDAS MERCADO INTERNO | N244: 56 | O244: VENDA A ORDEM | P244: BUNGE - SANTOS | Q244: =$R$1-F244 -> -21 | R244: =_xlfn.XLOOKUP(P244,'Painel Additive'!$B:$B,'Painel Additive'!$B:$B,0) -> BUNGE - SANTOS | S244: =F244-K244 -> 40
A245: 10677 | B245: MARCELO HONORIO DE CARVALHO RAMOS | C245: 007.511.136-54 | D245: 581 | E245: 1246272911 | F245: 46175 | I245: Não encontrado | J245: 11244 | K245: 46140 | L245: 4011600 | M245: APARELHOS DE INFORMÁTICA | N245: 244 | O245: VENDA DE IMOBILIZADO SEM ICMS | P245: MARCELO HONORIO DE CARVALHO RAMOS | Q245: =$R$1-F245 -> 22 | R245: =_xlfn.XLOOKUP(P245,'Painel Additive'!$B:$B,'Painel Additive'!$B:$B,0) -> MARCELO HONORIO DE CARVALHO RAMOS | S245: =F245-K245 -> 35
A246: 10677 | B246: MARCELO HONORIO DE CARVALHO RAMOS | C246: 007.511.136-54 | D246: 581 | E246: 1246272912 | F246: 46200 | I246: Não encontrado | J246: 11244 | K246: 46140 | L246: 4011600 | M246: APARELHOS DE INFORMÁTICA | N246: 244 | O246: VENDA DE IMOBILIZADO SEM ICMS | P246: MARCELO HONORIO DE CARVALHO RAMOS | Q246: =$R$1-F246 -> -3 | R246: =_xlfn.XLOOKUP(P246,'Painel Additive'!$B:$B,'Painel Additive'!$B:$B,0) -> MARCELO HONORIO DE CARVALHO RAMOS | S246: =F246-K246 -> 60
A247: 10677 | B247: MARCELO HONORIO DE CARVALHO RAMOS | C247: 007.511.136-54 | D247: 581 | E247: 1246272913 | F247: 46230 | I247: Não encontrado | J247: 11244 | K247: 46140 | L247: 4011600 | M247: APARELHOS DE INFORMÁTICA | N247: 244 | O247: VENDA DE IMOBILIZADO SEM ICMS | P247: MARCELO HONORIO DE CARVALHO RAMOS | Q247: =$R$1-F247 -> -33 | R247: =_xlfn.XLOOKUP(P247,'Painel Additive'!$B:$B,'Painel Additive'!$B:$B,0) -> MARCELO HONORIO DE CARVALHO RAMOS | S247: =F247-K247 -> 90
A248: 14094 | B248: KLEYTON DUARTE SOARES | C248: 014.415.101-41 | D248: 100 | E248: 1246154530 | F248: 45474 | I248: Não encontrado | J248: 4088 | K248: 45474 | L248: 4010300 | M248: MÓVEIS E UTENSÍLIOS | N248: 244 | O248: VENDA DE IMOBILIZADO SEM ICMS | P248: KLEYTON DUARTE SOARES | Q248: =$R$1-F248 -> 723 | R248: =_xlfn.XLOOKUP(P248,'Painel Additive'!$B:$B,'Painel Additive'!$B:$B,0) -> KLEYTON DUARTE SOARES | S248: =F248-K248 -> 0
A249: 13873 | B249: MARIA JOSE DA SILVA | C249: 844.462.855-72 | D249: 50 | E249: 1246166396 | F249: 45525 | I249: Não encontrado | J249: 4854 | K249: 45525 | L249: 4010300 | M249: MÓVEIS E UTENSÍLIOS | N249: 244 | O249: VENDA DE IMOBILIZADO SEM ICMS | P249: MARIA JOSE DA SILVA | Q249: =$R$1-F249 -> 672 | R249: =_xlfn.XLOOKUP(P249,'Painel Additive'!$B:$B,'Painel Additive'!$B:$B,0) -> MARIA JOSE DA SILVA | S249: =F249-K249 -> 0
A250: 14106 | B250: SEU LIXO | C250: 50.454.037/0001-68 | D250: 300 | E250: 1246182736 | F250: 45625 | I250: Não encontrado | J250: 6092 | K250: 45610 | L250: 1020400 | M250: VENDA DE SUCATAS | N250: 136 | O250: VENDA DE SUCATAS | P250: SEU LIXO | Q250: =$R$1-F250 -> 572 | R250: =_xlfn.XLOOKUP(P250,'Painel Additive'!$B:$B,'Painel Additive'!$B:$B,0) -> SEU LIXO | S250: =F250-K250 -> 15
...

Sheet Data International
D1: =SUBTOTAL(9,D3:D994) -> 7575530 | R1: 46197
A2: CODPARC | B2: NOMEPARC | C2: CNPJ | D2: Valor | E2: NUFIN | F2: DTVENC | G2: DHBAIXA | H2: AD_BU | I2: NOME_BU | J2: NUMNOTA | K2: DTENTSAI | L2: CODNAT | M2: DESCRNAT | N2: CODTIPOPER | O2: OPERACAO | P2: Grupo | Q2: Dias vencidos
A3: 3297 | B3: MACROSOURCE PERU S.R.L. | C3: ..- | D3: 49956.68 | E3: 1246271355 | F3: 46200 | H3: 1 | I3: Adtives | J3: 11123 | K3: 46126 | L3: 1010200 | M3: VENDAS MERCADO EXTERNO | N3: 40 | O3: VENDA - NFE (EXPORTAÇÃO) | P3: MACROSOURCE PERU S.R.L. | Q3: =$R$1-F3 -> -3 | R3: =_xlfn.XLOOKUP(P3,'Painel International'!$B:$B,'Painel International'!$B:$B,0) -> MACROSOURCE PERU S.R.L.
A4: 2680 | B4: FERMAGRI S.A - EQUADOR | C4: ..- | D4: 175275.24 | E4: 1246272069 | F4: 46194 | H4: 1 | I4: Adtives | J4: 11191 | K4: 46134 | L4: 1010200 | M4: VENDAS MERCADO EXTERNO | N4: 40 | O4: VENDA - NFE (EXPORTAÇÃO) | P4: FERMAGRI S.A - EQUADOR | Q4: =$R$1-F4 -> 3 | R4: =_xlfn.XLOOKUP(P4,'Painel International'!$B:$B,'Painel International'!$B:$B,0) -> FERMAGRI S.A - EQUADOR
A5: 2696 | B5: MOSAIC FERTILIZANTES PARAGUAY S.R.L. | C5: ..- | D5: 94148.95 | E5: 1246279520 | F5: 46278 | H5: 1 | I5: Adtives | J5: 11712 | K5: 46188 | L5: 1010200 | M5: VENDAS MERCADO EXTERNO | N5: 40 | O5: VENDA - NFE (EXPORTAÇÃO) | P5: MOSAIC FERTILIZANTES PARAGUAY S.R.L. | Q5: =$R$1-F5 -> -81 | R5: =_xlfn.XLOOKUP(P5,'Painel International'!$B:$B,'Painel International'!$B:$B,0) -> MOSAIC FERTILIZANTES PARAGUAY S.R.L.
A6: 2696 | B6: MOSAIC FERTILIZANTES PARAGUAY S.R.L. | C6: ..- | D6: 91784.41 | E6: 1246274791 | F6: 46245 | H6: 1 | I6: Adtives | J6: 11378 | K6: 46155 | L6: 1010200 | M6: VENDAS MERCADO EXTERNO | N6: 40 | O6: VENDA - NFE (EXPORTAÇÃO) | P6: MOSAIC FERTILIZANTES PARAGUAY S.R.L. | Q6: =$R$1-F6 -> -48 | R6: =_xlfn.XLOOKUP(P6,'Painel International'!$B:$B,'Painel International'!$B:$B,0) -> MOSAIC FERTILIZANTES PARAGUAY S.R.L.
A7: 2696 | B7: MOSAIC FERTILIZANTES PARAGUAY S.R.L. | C7: ..- | D7: 118833.22 | E7: 1246278569 | F7: 46271 | H7: 1 | I7: Adtives | J7: 11641 | K7: 46181 | L7: 1010200 | M7: VENDAS MERCADO EXTERNO | N7: 40 | O7: VENDA - NFE (EXPORTAÇÃO) | P7: MOSAIC FERTILIZANTES PARAGUAY S.R.L. | Q7: =$R$1-F7 -> -74 | R7: =_xlfn.XLOOKUP(P7,'Painel International'!$B:$B,'Painel International'!$B:$B,0) -> MOSAIC FERTILIZANTES PARAGUAY S.R.L.
A8: 2696 | B8: MOSAIC FERTILIZANTES PARAGUAY S.R.L. | C8: ..- | D8: 116719.31 | E8: 1246277374 | F8: 46261 | H8: 1 | I8: Adtives | J8: 11551 | K8: 46171 | L8: 1010200 | M8: VENDAS MERCADO EXTERNO | N8: 40 | O8: VENDA - NFE (EXPORTAÇÃO) | P8: MOSAIC FERTILIZANTES PARAGUAY S.R.L. | Q8: =$R$1-F8 -> -64 | R8: =_xlfn.XLOOKUP(P8,'Painel International'!$B:$B,'Painel International'!$B:$B,0) -> MOSAIC FERTILIZANTES PARAGUAY S.R.L.
A9: 2696 | B9: MOSAIC FERTILIZANTES PARAGUAY S.R.L. | C9: ..- | D9: 116211.91 | E9: 1246278291 | F9: 46268 | H9: 1 | I9: Adtives | J9: 11599 | K9: 46178 | L9: 1010200 | M9: VENDAS MERCADO EXTERNO | N9: 40 | O9: VENDA - NFE (EXPORTAÇÃO) | P9: MOSAIC FERTILIZANTES PARAGUAY S.R.L. | Q9: =$R$1-F9 -> -71 | R9: =_xlfn.XLOOKUP(P9,'Painel International'!$B:$B,'Painel International'!$B:$B,0) -> MOSAIC FERTILIZANTES PARAGUAY S.R.L.
A10: 2645 | B10: ANAGRA - CHILE | C10: ..- | D10: 143222.74 | E10: 1246277225 | F10: 46200 | H10: 1 | I10: Adtives | J10: 11529 | K10: 46170 | L10: 1010200 | M10: VENDAS MERCADO EXTERNO | N10: 40 | O10: VENDA - NFE (EXPORTAÇÃO) | P10: ANAGRA - CHILE | Q10: =$R$1-F10 -> -3 | R10: =_xlfn.XLOOKUP(P10,'Painel International'!$B:$B,'Painel International'!$B:$B,0) -> ANAGRA - CHILE
A11: 2651 | B11: AGROBROKERS - COLÔMBIA | C11: ..- | D11: 132309.33 | E11: 1246278533 | F11: 46241 | H11: 1 | I11: Adtives | J11: 3002 | K11: 46181 | L11: 1010200 | M11: VENDAS MERCADO EXTERNO | N11: 40 | O11: VENDA - NFE (EXPORTAÇÃO) | P11: AGROBROKERS - COLÔMBIA | Q11: =$R$1-F11 -> -44 | R11: =_xlfn.XLOOKUP(P11,'Painel International'!$B:$B,'Painel International'!$B:$B,0) -> AGROBROKERS - COLÔMBIA
A12: 2652 | B12: FERTIMAX PARAGUAY | C12: ..- | D12: 166161.39 | E12: 1246279339 | F12: 46215 | H12: 1 | I12: Adtives | J12: 11691 | K12: 46185 | L12: 1010200 | M12: VENDAS MERCADO EXTERNO | N12: 40 | O12: VENDA - NFE (EXPORTAÇÃO) | P12: FERTIMAX PARAGUAY | Q12: =$R$1-F12 -> -18 | R12: =_xlfn.XLOOKUP(P12,'Painel International'!$B:$B,'Painel International'!$B:$B,0) -> FERTIMAX PARAGUAY
A13: 2287 | B13: BUNGE PARAGUAY S.A | C13: 99.999.999/9999-99 | D13: 152321.99 | E13: 1246279865 | F13: 46220 | H13: 1 | I13: Adtives | J13: 11738 | K13: 46190 | L13: 1010200 | M13: VENDAS MERCADO EXTERNO | N13: 40 | O13: VENDA - NFE (EXPORTAÇÃO) | P13: BUNGE PARAGUAY S.A | Q13: =$R$1-F13 -> -23 | R13: =_xlfn.XLOOKUP(P13,'Painel International'!$B:$B,'Painel International'!$B:$B,0) -> BUNGE PARAGUAY S.A
A14: 2287 | B14: BUNGE PARAGUAY S.A | C14: 99.999.999/9999-99 | D14: 155118.66 | E14: 1246278696 | F14: 46212 | H14: 1 | I14: Adtives | J14: 11655 | K14: 46182 | L14: 1010200 | M14: VENDAS MERCADO EXTERNO | N14: 40 | O14: VENDA - NFE (EXPORTAÇÃO) | P14: BUNGE PARAGUAY S.A | Q14: =$R$1-F14 -> -15 | R14: =_xlfn.XLOOKUP(P14,'Painel International'!$B:$B,'Painel International'!$B:$B,0) -> BUNGE PARAGUAY S.A
... A32: 12031 | B32: EVOAGRO NUTRICION S.A.S - COLOMBIA | C32: ..- | D32: 164297.05 | E32: 1246275610 | F32: 46220 | H32: 1 | I32: Adtives | J32: 2948 | K32: 46160 | L32: 1010200 | M32: VENDAS MERCADO EXTERNO | N32: 40 | O32: VENDA - NFE (EXPORTAÇÃO) | P32: EVOAGRO NUTRICION S.A.S - COLOMBIA | Q32: =$R$1-F32 -> -23 | R32: =_xlfn.XLOOKUP(P32,'Painel International'!$B:$B,'Painel International'!$B:$B,0) -> EVOAGRO NUTRICION S.A.S - COLOMBIA
A33: 13330 | B33: ORGANITEC - PARAGUAY | C33: 800.909.976- | D33: 853.24 | E33: 1246272264 | F33: 46148 | I33: Não encontrado | J33: 11057 | K33: 46118 | L33: 1010200 | M33: VENDAS MERCADO EXTERNO | N33: 40 | O33: VENDA - NFE (EXPORTAÇÃO) | P33: ORGANITEC - PARAGUAY | Q33: =$R$1-F33 -> 49 | R33: =_xlfn.XLOOKUP(P33,'Painel International'!$B:$B,'Painel International'!$B:$B,0) -> ORGANITEC - PARAGUAY
A34: 13330 | B34: ORGANITEC - PARAGUAY | C34: 800.909.976- | D34: 527.28 | E34: 1246238356 | F34: 45927 | I34: Não encontrado | J34: 9092 | K34: 45897 | L34: 1010200 | M34: VENDAS MERCADO EXTERNO | N34: 40 | O34: VENDA - NFE (EXPORTAÇÃO) | P34: ORGANITEC - PARAGUAY | Q34: =$R$1-F34 -> 270 | R34: =_xlfn.XLOOKUP(P34,'Painel International'!$B:$B,'Painel International'!$B:$B,0) -> ORGANITEC - PARAGUAY
A35: 15543 | B35: GOTLAND EQUADOR (SOLINAG) | C35: 19.512.950/9001- | D35: 45718.46 | E35: 1246264533 | F35: 46181 | H35: 1 | I35: Adtives | J35: 10745 | K35: 46076 | L35: 1010200 | M35: VENDAS MERCADO EXTERNO | N35: 40 | O35: VENDA - NFE (EXPORTAÇÃO) | P35: GOTLAND EQUADOR (SOLINAG) | Q35: =$R$1-F35 -> 16 | R35: =_xlfn.XLOOKUP(P35,'Painel International'!$B:$B,'Painel International'!$B:$B,0) -> GOTLAND EQUADOR (SOLINAG)
A36: 15543 | B36: GOTLAND EQUADOR (SOLINAG) | C36: 19.512.950/9001- | D36: 133756.12 | E36: 1246277124 | F36: 46259 | H36: 1 | I36: Adtives | J36: 11522 | K36: 46169 | L36: 1010200 | M36: VENDAS MERCADO EXTERNO | N36: 40 | O36: VENDA - NFE (EXPORTAÇÃO) | P36: GOTLAND EQUADOR (SOLINAG) | Q36: =$R$1-F36 -> -62 | R36: =_xlfn.XLOOKUP(P36,'Painel International'!$B:$B,'Painel International'!$B:$B,0) -> GOTLAND EQUADOR (SOLINAG)
Q37: =$R$1-F37 -> 46197 | R37: =_xlfn.XLOOKUP(P37,'Painel International'!$B:$B,'Painel International'!$B:$B,0) -> 0
Q38: =$R$1-F38 -> 46197 | R38: =_xlfn.XLOOKUP(P38,'Painel International'!$B:$B,'Painel International'!$B:$B,0) -> 0
Q39: =$R$1-F39 -> 46197 | R39: =_xlfn.XLOOKUP(P39,'Painel International'!$B:$B,'Painel International'!$B:$B,0) -> 0
Q40: =$R$1-F40 -> 46197 | R40: =_xlfn.XLOOKUP(P40,'Painel International'!$B:$B,'Painel International'!$B:$B,0) -> 0
Q41: =$R$1-F41 -> 46197 | R41: =_xlfn.XLOOKUP(P41,'Painel International'!$B:$B,'Painel International'!$B:$B,0) -> 0
Q42: =$R$1-F42 -> 46197 | R42: =_xlfn.XLOOKUP(P42,'Painel International'!$B:$B,'Painel International'!$B:$B,0) -> 0
Q43: =$R$1-F43 -> 46197 | R43: =_xlfn.XLOOKUP(P43,'Painel International'!$B:$B,'Painel International'!$B:$B,0) -> 0
Q44: =$R$1-F44 -> 46197 | R44: =_xlfn.XLOOKUP(P44,'Painel International'!$B:$B,'Painel International'!$B:$B,0) -> 0
Q45: =$R$1-F45 -> 46197 | R45: =_xlfn.XLOOKUP(P45,'Painel International'!$B:$B,'Painel International'!$B:$B,0) -> 0
Q46: =$R$1-F46 -> 46197 | R46: =_xlfn.XLOOKUP(P46,'Painel International'!$B:$B,'Painel International'!$B:$B,0) -> 0
Q47: =$R$1-F47 -> 46197 | R47: =_xlfn.XLOOKUP(P47,'Painel International'!$B:$B,'Painel International'!$B:$B,0) -> 0

Sheet Data Fertilizers
D1: =SUBTOTAL(9,D3:D995) -> 24577393 | R1: 46197
A2: CODPARC | B2: NOMEPARC | C2: CNPJ | D2: Valor | E2: NUFIN | F2: DTVENC | G2: DHBAIXA | H2: AD_BU | I2: NOME_BU | J2: NUMNOTA | K2: DTENTSAI | L2: CODNAT | M2: DESCRNAT | N2: CODTIPOPER | O2: OPERACAO | P2: GRUPO | Q2: Dias vencidos
A3: 9824 | B3: TRIANGULO AGRO CONSULTORIA C/PRESCISAO | C3: 11.827.200/0001-39 | D3: 69971.2 | E3: 1246154720 | F3: 45738 | H3: 2 | I3: Fertilizers | J3: 4113 | K3: 45475 | L3: 1010100 | M3: VENDAS MERCADO INTERNO | N3: 161 | O3: VENDA PROD. INDUSTRIALIZADO - NFE | P3: GRUPO TRIANGULO AGRO | Q3: =$R$1-F3 -> 459 | R3: =_xlfn.XLOOKUP(P3,'Painel Fertilizers'!$B:$B,'Painel Fertilizers'!$B:$B,0) -> GRUPO TRIANGULO AGRO
